Workbook

Sheet 说明
A2: 数据源来源及数据处理步骤
A3: 1、下载数据源（4.business report和Advertised report），时间选择维度需统一
A4: 2、处理(2.SKU透视表-右键刷新）
A22: 3、把sku透视表筛选好的数据贴进（3.SKU处理-排名表）中，步骤如下
A23: 步骤1:筛选SKU透视表相应的SKU-复制粘贴数值A-D列
A24: 步骤2：把“#DIV/0!”全部替换成“0”
A25: 步骤3：下拉E-F列公式
A27: 4、在（4.businessReport ）表中筛选要分析的SKU数据-复制到（5.业务报告&AD报告分析）表格中，操作步骤如下：
A29: 步骤1：给business报告中的第N列（即Ordered Product Sales）排序-降序
A30: 步骤2：从business报告中复制已经筛选的SKU数据把A-Q列直接贴进来，对应的A-Q列，R-Y列均为公式不能动

Sheet 跟进备注
A2: 1、 | B2: YDF11\B全部缺货严重
A3: 2、 | B3: YDF2、YDF1 可以加大推广，以及其他头部转化好的SKU，已单独创建TOP系列跟进
A4: 3、 | B4: 无SP-M-广泛广告，目前开启一个只跑头部低流量的SKU+转化好的SKU

Sheet 7.颜色分析（排名）
A1: 步骤1:复制粘贴颜色分析A-I列
A2: 步骤2：把“#DIV/0!”全部替换成“0”
A3: 步骤3：下拉J-P列公式
A4: 颜色 | B4: Sessions | C4: Units Ordered | D4: 转化率 | E4: 广告Impressions | F4: 广告Clicks | G4: 广告orders | H4: CTR | I4: CR | J4: 总流量排名 | K4: 总销量排名 | L4: 总转化率排名 | M4: 广告点击排名 | N4: 广告转化率CTR排名 | O4: 广告转化率CR排名 | P4: 广告订单贡献占比 | Q4: 备注 | R4: 在库周转天数
A5: AMXX0001_YDF11 | B5: 6789 | C5: 142 | D5: 0.020916188 | E5: 234948 | F5: 551 | G5: 53 | H5: 0.0023451998 | I5: 0.096188748 | J5: =RANK(B5,B:B,0) -> 1 | K5: =RANK(C5,C:C,0) -> 1 | L5: =RANK(D5,D:D,0) -> 10 | M5: =RANK(F5,F:F,0) -> 2 | N5: =RANK(G5,G:G,0) -> 2 | O5: =RANK(H5,H:H,0) -> 3 | P5: =G5/C5 -> 0.37323944 | R5: 83.388033
A6: AMXX0001_B | B6: 2435 | C6: 135 | D6: 0.055441478 | E6: 36446 | F6: 74 | G6: 25 | H6: 0.0020304011 | I6: 0.33783784 | J6: =RANK(B6,B:B,0) -> 5 | K6: =RANK(C6,C:C,0) -> 2 | L6: =RANK(D6,D:D,0) -> 1 | M6: =RANK(F6,F:F,0) -> 5 | N6: =RANK(G6,G:G,0) -> 3 | O6: =RANK(H6,H:H,0) -> 6 | P6: =G6/C6 -> 0.18518519 | R6: 17.777778
A7: AMXX0001_YDF1 | B7: 4073 | C7: 112 | D7: 0.027498159 | E7: 133485 | F7: 174 | G7: 14 | H7: 0.0013035172 | I7: 0.08045977 | J7: =RANK(B7,B:B,0) -> 3 | K7: =RANK(C7,C:C,0) -> 3 | L7: =RANK(D7,D:D,0) -> 6 | M7: =RANK(F7,F:F,0) -> 3 | N7: =RANK(G7,G:G,0) -> 4 | O7: =RANK(H7,H:H,0) -> 10 | P7: =G7/C7 -> 0.125 | R7: 54.21278
A8: AMXX0001_YDF2 | B8: 4350 | C8: 88 | D8: 0.020229885 | E8: 369517 | F8: 711 | G8: 76 | H8: 0.0019241334 | I8: 0.1068917 | J8: =RANK(B8,B:B,0) -> 2 | K8: =RANK(C8,C:C,0) -> 4 | L8: =RANK(D8,D:D,0) -> 11 | M8: =RANK(F8,F:F,0) -> 1 | N8: =RANK(G8,G:G,0) -> 1 | O8: =RANK(H8,H:H,0) -> 7 | P8: =G8/C8 -> 0.86363636 | R8: 169.05657
A9: AMXX0001_MGT | B9: 3437 | C9: 86 | D9: 0.025021821 | E9: 13644 | F9: 18 | G9: 2 | H9: 0.0013192612 | I9: 0.11111111 | J9: =RANK(B9,B:B,0) -> 4 | K9: =RANK(C9,C:C,0) -> 5 | L9: =RANK(D9,D:D,0) -> 8 | M9: =RANK(F9,F:F,0) -> 12 | N9: =RANK(G9,G:G,0) -> 10 | O9: =RANK(H9,H:H,0) -> 9 | P9: =G9/C9 -> 0.023255814 | R9: 57.79816
A10: AMXX0001_YDF5 | B10: 2184 | C10: 86 | D10: 0.039377289 | E10: 41933 | F10: 23 | G10: 6 | H10: 0.00054849403 | I10: 0.26086957 | J10: =RANK(B10,B:B,0) -> 7 | K10: =RANK(C10,C:C,0) -> 5 | L10: =RANK(D10,D:D,0) -> 2 | M10: =RANK(F10,F:F,0) -> 10 | N10: =RANK(G10,G:G,0) -> 5 | O10: =RANK(H10,H:H,0) -> 17 | P10: =G10/C10 -> 0.069767442 | R10: 45.454545
A11: AMXX0001_NB | B11: 2279 | C11: 83 | D11: 0.036419482 | E11: 12229 | F11: 35 | G11: 3 | H11: 0.0028620492 | I11: 0.085714286 | J11: =RANK(B11,B:B,0) -> 6 | K11: =RANK(C11,C:C,0) -> 7 | L11: =RANK(D11,D:D,0) -> 3 | M11: =RANK(F11,F:F,0) -> 6 | N11: =RANK(G11,G:G,0) -> 7 | O11: =RANK(H11,H:H,0) -> 2 | P11: =G11/C11 -> 0.036144578 | R11: 40.645174
A12: AMXX0001_WR | B12: 1869 | C12: 57 | D12: 0.030497592 | E12: 19464 | F12: 19 | G12: 1 | H12: 0.00097616112 | I12: 0.052631579 | J12: =RANK(B12,B:B,0) -> 10 | K12: =RANK(C12,C:C,0) -> 8 | L12: =RANK(D12,D:D,0) -> 5 | M12: =RANK(F12,F:F,0) -> 11 | N12: =RANK(G12,G:G,0) -> 12 | O12: =RANK(H12,H:H,0) -> 11 | P12: =G12/C12 -> 0.01754386 | R12: 110.83331
A13: AMXX0001_PEB | B13: 1898 | C13: 43 | D13: 0.022655427 | E13: 24617 | F13: 14 | G13: 0 | H13: 0.00056871268 | I13: 0 | J13: =RANK(B13,B:B,0) -> 9 | K13: =RANK(C13,C:C,0) -> 9 | L13: =RANK(D13,D:D,0) -> 9 | M13: =RANK(F13,F:F,0) -> 14 | N13: =RANK(G13,G:G,0) -> 17 | O13: =RANK(H13,H:H,0) -> 16 | P13: =G13/C13 -> 0 | R13: 90.12509
A14: AMXX0001_YDF9 | B14: 1603 | C14: 42 | D14: 0.026200873 | E14: 30691 | F14: 29 | G14: 3 | H14: 0.00094490241 | I14: 0.10344828 | J14: =RANK(B14,B:B,0) -> 11 | K14: =RANK(C14,C:C,0) -> 10 | L14: =RANK(D14,D:D,0) -> 7 | M14: =RANK(F14,F:F,0) -> 8 | N14: =RANK(G14,G:G,0) -> 7 | O14: =RANK(H14,H:H,0) -> 12 | P14: =G14/C14 -> 0.071428571 | R14: 120.39995
A15: AMXX0001_YDF10 | B15: 1303 | C15: 42 | D15: 0.032233308 | E15: 39775 | F15: 32 | G15: 3 | H15: 0.00080452546 | I15: 0.09375 | J15: =RANK(B15,B:B,0) -> 15 | K15: =RANK(C15,C:C,0) -> 10 | L15: =RANK(D15,D:D,0) -> 4 | M15: =RANK(F15,F:F,0) -> 7 | N15: =RANK(G15,G:G,0) -> 7 | O15: =RANK(H15,H:H,0) -> 14 | P15: =G15/C15 -> 0.071428571 | R15: 75.957398
A16: AMXX0001_PAT9 | B16: 1965 | C16: 38 | D16: 0.019338422 | E16: 55162 | F16: 114 | G16: 6 | H16: 0.0020666401 | I16: 0.052631579 | J16: =RANK(B16,B:B,0) -> 8 | K16: =RANK(C16,C:C,0) -> 12 | L16: =RANK(D16,D:D,0) -> 13 | M16: =RANK(F16,F:F,0) -> 4 | N16: =RANK(G16,G:G,0) -> 5 | O16: =RANK(H16,H:H,0) -> 5 | P16: =G16/C16 -> 0.15789474 | R16: 126.21214
... A21: AMXX0001_YDF4 | B21: 1077 | C21: 17 | D21: 0.015784587 | E21: 29555 | F21: 26 | G21: 1 | H21: 0.00087971578 | I21: 0.038461538 | J21: =RANK(B21,B:B,0) -> 17 | K21: =RANK(C21,C:C,0) -> 17 | L21: =RANK(D21,D:D,0) -> 17 | M21: =RANK(F21,F:F,0) -> 9 | N21: =RANK(G21,G:G,0) -> 12 | O21: =RANK(H21,H:H,0) -> 13 | P21: =G21/C21 -> 0.058823529 | R21: 262.5
A22: AMXX0001_PU | B22: 674 | C22: 11 | D22: 0.016320475 | E22: 8690 | F22: 4 | G22: 1 | H22: 0.00046029919 | I22: 0.25 | J22: =RANK(B22,B:B,0) -> 19 | K22: =RANK(C22,C:C,0) -> 18 | L22: =RANK(D22,D:D,0) -> 16 | M22: =RANK(F22,F:F,0) -> 17 | N22: =RANK(G22,G:G,0) -> 12 | O22: =RANK(H22,H:H,0) -> 18 | P22: =G22/C22 -> 0.090909091 | R22: #N/A
A23: AMXX0001_YDF12 | B23: 640 | C23: 6 | D23: 0.009375 | E23: 74 | F23: 0 | G23: 0 | H23: 0 | I23: 0 | J23: =RANK(B23,B:B,0) -> 20 | K23: =RANK(C23,C:C,0) -> 19 | L23: =RANK(D23,D:D,0) -> 19 | M23: =RANK(F23,F:F,0) -> 19 | N23: =RANK(G23,G:G,0) -> 17 | O23: =RANK(H23,H:H,0) -> 19 | P23: =G23/C23 -> 0 | R23: 107.69247
A24: AMXX0001_PAT3 | B24: 742 | C24: 5 | D24: 0.0067385445 | E24: 0 | F24: 0 | G24: 0 | H24: 0 | I24: 0 | J24: =RANK(B24,B:B,0) -> 18 | K24: =RANK(C24,C:C,0) -> 20 | L24: =RANK(D24,D:D,0) -> 20 | M24: =RANK(F24,F:F,0) -> 19 | N24: =RANK(G24,G:G,0) -> 17 | O24: =RANK(H24,H:H,0) -> 19 | P24: =G24/C24 -> 0 | R24: 402.49899

Sheet 6.颜色分析
A3: 行标签 | B3: 求和项:Sessions | C3: 求和项:Units Ordered | D3: 求和项:转化率 | E3: 求和项:广告Impressions | F3: 求和项:广告Clicks | G3: 求和项:广告orders | H3: 求和项:CTR | I3: 求和项:CR
A4: AMXX0001_YDF11 | B4: 6789 | C4: 142 | D4: 0.020916188 | E4: 234948 | F4: 551 | G4: 53 | H4: 0.0023451998 | I4: 0.096188748
A5: AMXX0001_YDF2 | B5: 4350 | C5: 88 | D5: 0.020229885 | E5: 369517 | F5: 711 | G5: 76 | H5: 0.0019241334 | I5: 0.1068917
A6: AMXX0001_YDF1 | B6: 4073 | C6: 112 | D6: 0.027498159 | E6: 133485 | F6: 174 | G6: 14 | H6: 0.0013035172 | I6: 0.08045977
A7: AMXX0001_MGT | B7: 3437 | C7: 86 | D7: 0.025021821 | E7: 13644 | F7: 18 | G7: 2 | H7: 0.0013192612 | I7: 0.11111111
A8: AMXX0001_B | B8: 2435 | C8: 135 | D8: 0.055441478 | E8: 36446 | F8: 74 | G8: 25 | H8: 0.0020304011 | I8: 0.33783784
A9: AMXX0001_NB | B9: 2279 | C9: 83 | D9: 0.036419482 | E9: 12229 | F9: 35 | G9: 3 | H9: 0.0028620492 | I9: 0.085714286
A10: AMXX0001_YDF5 | B10: 2184 | C10: 86 | D10: 0.039377289 | E10: 41933 | F10: 23 | G10: 6 | H10: 0.00054849403 | I10: 0.26086957
A11: AMXX0001_PAT9 | B11: 1965 | C11: 38 | D11: 0.019338422 | E11: 55162 | F11: 114 | G11: 6 | H11: 0.0020666401 | I11: 0.052631579
A12: AMXX0001_PEB | B12: 1898 | C12: 43 | D12: 0.022655427 | E12: 24617 | F12: 14 | G12: 0 | H12: 0.00056871268 | I12: 0
A13: AMXX0001_WR | B13: 1869 | C13: 57 | D13: 0.030497592 | E13: 19464 | F13: 19 | G13: 1 | H13: 0.00097616112 | I13: 0.052631579
A14: AMXX0001_YDF9 | B14: 1603 | C14: 42 | D14: 0.026200873 | E14: 30691 | F14: 29 | G14: 3 | H14: 0.00094490241 | I14: 0.10344828
A15: AMXX0001_PAT1 | B15: 1572 | C15: 31 | D15: 0.019720102 | E15: 11545 | F15: 18 | G15: 1 | H15: 0.0015591165 | I15: 0.055555556
... A20: AMXX0001_YDF4 | B20: 1077 | C20: 17 | D20: 0.015784587 | E20: 29555 | F20: 26 | G20: 1 | H20: 0.00087971578 | I20: 0.038461538
A21: AMXX0001_PAT3 | B21: 742 | C21: 5 | D21: 0.0067385445 | E21: 0 | F21: 0 | G21: 0 | H21: #DIV/0! | I21: #DIV/0!
A22: AMXX0001_PU | B22: 674 | C22: 11 | D22: 0.016320475 | E22: 8690 | F22: 4 | G22: 1 | H22: 0.00046029919 | I22: 0.25
A23: AMXX0001_YDF12 | B23: 640 | C23: 6 | D23: 0.009375 | E23: 74 | F23: 0 | G23: 0 | H23: 0 | I23: #DIV/0!
A24: (空白) | D24: #DIV/0! | H24: #DIV/0! | I24: #DIV/0!
A25: 总计 | B25: 42822 | C25: 1089 | D25: 0.025430853 | E25: 1073401 | F25: 1855 | G25: 198 | H25: 0.0017281519 | I25: 0.10673854

Sheet 5.业务报告&AD报告分析
B1: 步骤1：给business报告中的第N列（即Ordered Product Sales）排序-降序
B2: 步骤2：从business报告中复制已经筛选的SKU数据把A-Q列直接贴进来，对应的A-Q列，R-Y列均为公式不能动
A3: 颜色 | B3: (Parent) ASIN | C3: (Child) ASIN | D3: Title | E3: SKU | F3: Sessions | G3: Session Percentage | H3: Page Views | I3: Page Views Percentage | J3: Buy Box Percentage | K3: Units Ordered | L3: Units Ordered - B2B | M3: Unit Session Percentage | N3: Unit Session Percentage - B2B | O3: Ordered Product Sales | P3: Ordered Product Sales - B2B | Q3: Total Order Items | R3: Total Order Items - B2B | S3: 总流量排名 | T3: 总销售额排名 | U3: 总转化率排名 | V3: 广告Impressions | W3: 广告Clicks | X3: 广告CTR | Y3: 广告CR | Z3: 广告ROI | AA3: 广告orders | AB3: 广告点击排名 | AC3: 广告点击率CTR排名 | AD3: 广告转化率CR排名 | AE3: 备注(调整建议及问题）
A4: =LEFT(E4,FIND("_",E4,11)-1) -> #VALUE! | B4: B0CPHL55Y1 | C4: B0CM9F3CXY | D4: Puzzomix 3D Wooden Puzzles Christmas Village Houses Music Box - Colorful Wood Model Building Kits for Kids Unique Gift for Kids & Adults, Desk Decor for Birthday/Christmas Day | E4: PZM-US-YYH-V1-1 | F4: 1003 | G4: 0.297 | H4: 1298 | I4: 0.3119 | J4: 1 | K4: 44 | L4: 1 | M4: 0.0439 | N4: 0.0588 | O4: 1289.57 | P4: 29.99 | Q4: 43 | R4: 1 | S4: =RANK(F4,F:F,0) -> 2 | T4: =RANK(O4,O:O,0) -> 1 | U4: =RANK(M4,M:M,0) -> 1 | V4: =IFERROR(VLOOKUP(E4,'3.SKU处理-排名'!A:B,2,0),0) -> 284886 | W4: =IFERROR(VLOOKUP(E4,'3.SKU处理-排名'!A:J,3,0),0) -> 542 | X4: =IFERROR(VLOOKUP(E4,'3.SKU处理-排名'!A:D,4,0),0) -> 0.0019025154 | Y4: =IFERROR(VLOOKUP(E4,'3.SKU处理-排名'!A:J,5,0),0) -> 0.064575646 | Z4: =IFERROR(VLOOKUP(E4,'3.SKU处理-排名'!A:J,6,0),0) -> 1.8906815 | AA4: =IFERROR(VLOOKUP(E4,'3.SKU处理-排名'!A:G,7,0),0) -> 36 | AB4: =IFERROR(VLOOKUP(E4,'3.SKU处理-排名'!A:J,8,0),0) -> 1 | AC4: =IFERROR(VLOOKUP(E4,'3.SKU处理-排名'!A:I,9,0),0) -> 3 | AD4: =IFERROR(VLOOKUP(E4,'3.SKU处理-排名'!A:J,9,0),0) -> 3 | AE4: 广告点击率低，转化相对其他SKU高一些，可做广泛投放+精准投放
A5: =LEFT(E5,FIND("_",E5,11)-1) -> #VALUE! | B5: B0CPHL55Y1 | C5: B0CMJ85RH6 | D5: Puzzomix 3D Wooden Puzzles for Kids - DIY Building Kit with LED Night Light, Unique Idea for Kids & Adults Hobbies Handmade Christmas Crafts and Home Decor (Christmas Luminous Box) | E5: PZM-US-YGH-V1-1 | F5: 1473 | G5: 0.4362 | H5: 1797 | I5: 0.4319 | J5: 1 | K5: 35 | L5: 0 | M5: 0.0238 | N5: 0 | O5: 883.65 | P5: 0 | Q5: 34 | R5: 0 | S5: =RANK(F5,F:F,0) -> 1 | T5: =RANK(O5,O:O,0) -> 2 | U5: =RANK(M5,M:M,0) -> 3 | V5: =IFERROR(VLOOKUP(E5,'3.SKU处理-排名'!A:B,2,0),0) -> 64123 | W5: =IFERROR(VLOOKUP(E5,'3.SKU处理-排名'!A:J,3,0),0) -> 278 | X5: =IFERROR(VLOOKUP(E5,'3.SKU处理-排名'!A:D,4,0),0) -> 0.0043354179 | Y5: =IFERROR(VLOOKUP(E5,'3.SKU处理-排名'!A:J,5,0),0) -> 0.021582734 | Z5: =IFERROR(VLOOKUP(E5,'3.SKU处理-排名'!A:J,6,0),0) -> 0.54720849 | AA5: =IFERROR(VLOOKUP(E5,'3.SKU处理-排名'!A:G,7,0),0) -> 6 | AB5: =IFERROR(VLOOKUP(E5,'3.SKU处理-排名'!A:J,8,0),0) -> 3 | AC5: =IFERROR(VLOOKUP(E5,'3.SKU处理-排名'!A:I,9,0),0) -> 1 | AD5: =IFERROR(VLOOKUP(E5,'3.SKU处理-排名'!A:J,9,0),0) -> 1 | AE5: 广告点击率高，但转化率差
A6: =LEFT(E6,FIND("_",E6,11)-1) -> #VALUE! | B6: B0CPHL55Y1 | C6: B0CMHNDQT8 | D6: Puzzomix 3D Wooden Puzzles Christmas Ornament - DIY Mechanical Model Building Kit, Fun and Creative DIY 3D Puzzles for Kids, Unique for Adult Hobbies | E6: PZM-US-XBJ-V1-1 | F6: 611 | G6: 0.1809 | H6: 747 | I6: 0.1795 | J6: 1 | K6: 23 | L6: 0 | M6: 0.0376 | N6: 0 | O6: 301.77 | P6: 0 | Q6: 18 | R6: 0 | S6: =RANK(F6,F:F,0) -> 3 | T6: =RANK(O6,O:O,0) -> 3 | U6: =RANK(M6,M:M,0) -> 2 | V6: =IFERROR(VLOOKUP(E6,'3.SKU处理-排名'!A:B,2,0),0) -> 94170 | W6: =IFERROR(VLOOKUP(E6,'3.SKU处理-排名'!A:J,3,0),0) -> 333 | X6: =IFERROR(VLOOKUP(E6,'3.SKU处理-排名'!A:D,4,0),0) -> 0.003536158 | Y6: =IFERROR(VLOOKUP(E6,'3.SKU处理-排名'!A:J,5,0),0) -> 0.045045045 | Z6: =IFERROR(VLOOKUP(E6,'3.SKU处理-排名'!A:J,6,0),0) -> 1.0893752 | AA6: =IFERROR(VLOOKUP(E6,'3.SKU处理-排名'!A:G,7,0),0) -> 21 | AB6: =IFERROR(VLOOKUP(E6,'3.SKU处理-排名'!A:J,8,0),0) -> 2 | AC6: =IFERROR(VLOOKUP(E6,'3.SKU处理-排名'!A:I,9,0),0) -> 2 | AD6: =IFERROR(VLOOKUP(E6,'3.SKU处理-排名'!A:J,9,0),0) -> 2 | AE6: 做主要拓流量SKU ，区分转化差的词，其他可加大推广

Sheet 4.BusinessReport-1201-1214
A1: (Parent) ASIN | B1: (Child) ASIN | C1: Title | D1: SKU | E1: Sessions | F1: Session Percentage | G1: Page Views | H1: Page Views Percentage | I1: Buy Box Percentage | J1: Units Ordered | K1: Units Ordered - B2B | L1: Unit Session Percentage | M1: Unit Session Percentage - B2B | N1: Ordered Product Sales | O1: Ordered Product Sales - B2B | P1: Total Order Items | Q1: Total Order Items - B2B
A2: B0CPHL55Y1 | B2: B0CM9F3CXY | C2: Puzzomix 3D Wooden Puzzles Christmas Village Houses Music Box - Colorful Wood Model Building Kits for Kids Unique Gift for Kids & Adults, Desk Decor for Birthday/Christmas Day | D2: PZM-US-YYH-V1-1 | E2: 1003 | F2: 0.297 | G2: 1298 | H2: 0.3119 | I2: 1 | J2: 44 | K2: 1 | L2: 0.0439 | M2: 0.0588 | N2: 1289.57 | O2: 29.99 | P2: 43 | Q2: 1
A3: B0CPHL55Y1 | B3: B0CMJ85RH6 | C3: Puzzomix 3D Wooden Puzzles for Kids - DIY Building Kit with LED Night Light, Unique Idea for Kids & Adults Hobbies Handmade Christmas Crafts and Home Decor (Christmas Luminous Box) | D3: PZM-US-YGH-V1-1 | E3: 1473 | F3: 0.4362 | G3: 1797 | H3: 0.4319 | I3: 1 | J3: 35 | K3: 0 | L3: 0.0238 | M3: 0 | N3: 883.65 | O3: 0 | P3: 34 | Q3: 0
A4: B0CPHL55Y1 | B4: B0CMHNDQT8 | C4: Puzzomix 3D Wooden Puzzles Christmas Ornament - DIY Mechanical Model Building Kit, Fun and Creative DIY 3D Puzzles for Kids, Unique for Adult Hobbies | D4: PZM-US-XBJ-V1-1 | E4: 611 | F4: 0.1809 | G4: 747 | H4: 0.1795 | I4: 1 | J4: 23 | K4: 0 | L4: 0.0376 | M4: 0 | N4: 301.77 | O4: 0 | P4: 18 | Q4: 0
A5: B0CMHX59TC | B5: B0CMHX59TC | C5: Puzzomix Booknook Kit Book Nook Miniature Kit for Adults DIY Bookshelf Insert-Wood 3D Puzzle, Bookshelf Miniature Scenes - Christmas Birthday Gifts for Kids and Adults Hobbies | D5: PZM-US-XXSL-V1-0 | E5: 181 | F5: 0.0536 | G5: 197 | H5: 0.0473 | I5: 0.9492 | J5: 9 | K5: 0 | L5: 0.0497 | M5: 0 | N5: 0 | O5: 0 | P5: 9 | Q5: 0
A6: B0CMH891WR | B6: B0CMH891WR | C6: Puzzomix 3D Puzzles for Kids, Models for Adults to Build - Wood Model Kit, Ferris Wheel Wood Building Kits - Ideal Birthday for Puzzle Lovers and Teens | D6: PZM-US-MTL-V1-0 | E6: 61 | F6: 0.0181 | G6: 66 | H6: 0.0159 | I6: 0.9545 | J6: 8 | K6: 0 | L6: 0.1311 | M6: 0 | N6: 0 | O6: 0 | P6: 8 | Q6: 0
A7: B0CMHNDQT8 | B7: B0CMHNDQT8 | C7: Puzzomix 3D Wooden Puzzles Christmas Ornament - DIY Mechanical Model Building Kit, Fun and Creative DIY 3D Puzzles for Kids, Unique for Adult Hobbies | D7: PZM-US-XBJ-V1-1 | E7: 48 | F7: 0.0142 | G7: 56 | H7: 0.0135 | I7: 1 | J7: 8 | K7: 0 | L7: 0.1667 | M7: 0 | N7: 0 | O7: 0 | P7: 8 | Q7: 0

Sheet 3.SKU处理-排名
A1: 步骤1:筛选SKU透视表相应的SKU-复制粘贴数值A-D列
A2: 步骤2：把“0”全部替换成“0”
A3: 步骤3：下拉E-F列公式
A4: SKU-需筛选 | B4: 求和项:Impressions | C4: 求和项:Clicks | D4: 求和项:CTR | E4: 求和项:CR | F4: 求和项:ROI | G4: 求和项:7 Day Total Units | H4: 广告点击排名 | I4: 广告点击率CTR排名 | J4: 广告转化率CR排名
A5: PZM-US-YYH-V1-1 | B5: 284886 | C5: 542 | D5: 0.0019025154 | E5: 0.064575646 | F5: 1.8906815 | G5: 36 | H5: =RANK(C5,C:C,0) -> 1 | I5: =RANK(D5,D:D,0) -> 3 | J5: =RANK(E5,E:E,0) -> 1
A6: PZM-US-XBJ-V1-1 | B6: 94170 | C6: 333 | D6: 0.003536158 | E6: 0.045045045 | F6: 1.0893752 | G6: 21 | H6: =RANK(C6,C:C,0) -> 2 | I6: =RANK(D6,D:D,0) -> 2 | J6: =RANK(E6,E:E,0) -> 2
A7: PZM-US-YGH-V1-1 | B7: 64123 | C7: 278 | D7: 0.0043354179 | E7: 0.021582734 | F7: 0.54720849 | G7: 6 | H7: =RANK(C7,C:C,0) -> 3 | I7: =RANK(D7,D:D,0) -> 1 | J7: =RANK(E7,E:E,0) -> 3

Sheet 2.SKU透视表
A1: SKU-需筛选 | B1: 求和项:Impressions | C1: 求和项:Clicks | D1: 求和项:CTR | E1: 求和项:CR | F1: 求和项:ROI | G1: 求和项:7 Day Total Units
A2: PZM-US-YYH-V1-1 | B2: 284886 | C2: 542 | D2: 0.0019025154 | E2: 0.064575646 | F2: 1.8906815 | G2: 36
A3: PZM-US-XBJ-V1-1 | B3: 94170 | C3: 333 | D3: 0.003536158 | E3: 0.045045045 | F3: 1.0893752 | G3: 21
A4: PZM-US-YGH-V1-1 | B4: 64123 | C4: 278 | D4: 0.0043354179 | E4: 0.021582734 | F4: 0.54720849 | G4: 6
A5: (空白) | D5: #DIV/0! | E5: #DIV/0! | F5: #DIV/0!
A6: 总计 | B6: 443179 | C6: 1153 | D6: 0.0026016576 | E6: 0.048568951 | F6: 1.3587293 | G6: 63

Sheet  1.Advertised report  （SKU报告）
A1: 月份 | B1: Date | C1: Portfolio name | D1: Currency | E1: Campaign Name | F1: Ad Group Name | G1: Advertised SKU | H1: Advertised ASIN | I1: Impressions | J1: Clicks | K1: Click-Thru Rate (CTR) | L1: Cost Per Click (CPC) | M1: Spend | N1: 7 Day Total Sales | O1: Total Advertising Cost of Sales (ACOS) | P1: Total Return on Advertising Spend (ROAS) | Q1: 7 Day Total Orders (#) | R1: 7 Day Total Units (#) | S1: 7 Day Conversion Rate | T1: 7 Day Advertised SKU Units (#) | U1: 7 Day Other SKU Units (#) | V1: 7 Day Advertised SKU Sales | W1: 7 Day Other SKU Sales
A2: =IF(MONTH(B2)<10,"0"&MONTH(B2)&"月",MONTH(B2)&"月") -> 12月 | B2: 45262 | C2: No Portfolio | D2: USD | E2: PP6-1-WZX-YYH-V1-SP-A-12.9重启-12.12取消ROS+top10% | F2: YYH-V1-SP-A-12.11F | G2: PZM-US-YYH-V1-1 | H2: B0CM9F3CXY | I2: 4778 | J2: 12 | K2: 0.0025115111 | L2: 0.69166667 | M2: 8.3 | N2: 0 | P2: 0 | Q2: 0 | R2: 0 | S2: 0 | T2: 0 | U2: 0 | V2: 0 | W2: 0
A3: =IF(MONTH(B3)<10,"0"&MONTH(B3)&"月",MONTH(B3)&"月") -> 12月 | B3: 45263 | C3: No Portfolio | D3: USD | E3: PP6-1-WZX-YYH-V1-SP-A-12.9重启-12.12取消ROS+top10% | F3: YYH-V1-SP-A-12.11F | G3: PZM-US-YYH-V1-1 | H3: B0CM9F3CXY | I3: 1993 | J3: 4 | K3: 0.0020070246 | L3: 0.535 | M3: 2.14 | N3: 0 | P3: 0 | Q3: 0 | R3: 0 | S3: 0 | T3: 0 | U3: 0 | V3: 0 | W3: 0
A4: =IF(MONTH(B4)<10,"0"&MONTH(B4)&"月",MONTH(B4)&"月") -> 12月 | B4: 45264 | C4: No Portfolio | D4: USD | E4: PP6-1-WZX-YYH-V1-SP-A-12.9重启-12.12取消ROS+top10% | F4: YYH-V1-SP-A-12.11F | G4: PZM-US-YYH-V1-1 | H4: B0CM9F3CXY | I4: 4 | J4: 0 | K4: 0 | M4: 0 | N4: 0 | Q4: 0 | R4: 0 | T4: 0 | U4: 0 | V4: 0 | W4: 0
A5: =IF(MONTH(B5)<10,"0"&MONTH(B5)&"月",MONTH(B5)&"月") -> 12月 | B5: 45269 | C5: No Portfolio | D5: USD | E5: PP6-1-WZX-YYH-V1-SP-A-12.9重启-12.12取消ROS+top10% | F5: YYH-V1-SP-A-12.11F | G5: PZM-US-YYH-V1-1 | H5: B0CM9F3CXY | I5: 6089 | J5: 22 | K5: 0.0036130728 | L5: 0.68636364 | M5: 15.1 | N5: 29.99 | O5: 0.50350117 | P5: 1.9860927 | Q5: 1 | R5: 1 | S5: 0.045454545 | T5: 1 | U5: 0 | V5: 29.99 | W5: 0
A6: =IF(MONTH(B6)<10,"0"&MONTH(B6)&"月",MONTH(B6)&"月") -> 12月 | B6: 45270 | C6: No Portfolio | D6: USD | E6: PP6-1-WZX-YYH-V1-SP-A-12.9重启-12.12取消ROS+top10% | F6: YYH-V1-SP-A-12.11F | G6: PZM-US-YYH-V1-1 | H6: B0CM9F3CXY | I6: 17820 | J6: 45 | K6: 0.0025252525 | L6: 0.74177778 | M6: 33.38 | N6: 119.96 | O6: 0.27825942 | P6: 3.5937687 | Q6: 5 | R6: 5 | S6: 0.11111111 | T6: 5 | U6: 0 | V6: 119.96 | W6: 0
A7: =IF(MONTH(B7)<10,"0"&MONTH(B7)&"月",MONTH(B7)&"月") -> 12月 | B7: 45271 | C7: No Portfolio | D7: USD | E7: PP6-1-WZX-YYH-V1-SP-A-12.9重启-12.12取消ROS+top10% | F7: YYH-V1-SP-A-12.11F | G7: PZM-US-YYH-V1-1 | H7: B0CM9F3CXY | I7: 40808 | J7: 52 | K7: 0.0012742599 | L7: 0.88019231 | M7: 45.77 | N7: 145.95 | O7: 0.31360055 | P7: 3.1887699 | Q7: 5 | R7: 5 | S7: 0.096153846 | T7: 4 | U7: 1 | V7: 119.96 | W7: 25.99
A8: =IF(MONTH(B8)<10,"0"&MONTH(B8)&"月",MONTH(B8)&"月") -> 12月 | B8: 45272 | C8: No Portfolio | D8: USD | E8: PP6-1-WZX-YYH-V1-SP-A-12.9重启-12.12取消ROS+top10% | F8: YYH-V1-SP-A-12.11F | G8: PZM-US-YYH-V1-1 | H8: B0CM9F3CXY | I8: 55114 | J8: 62 | K8: 0.001124941 | L8: 0.87548387 | M8: 54.28 | N8: 59.98 | O8: 0.90496832 | P8: 1.1050111 | Q8: 2 | R8: 2 | S8: 0.032258065 | T8: 2 | U8: 0 | V8: 59.98 | W8: 0
A9: =IF(MONTH(B9)<10,"0"&MONTH(B9)&"月",MONTH(B9)&"月") -> 12月 | B9: 45273 | C9: No Portfolio | D9: USD | E9: PP6-1-WZX-YYH-V1-SP-A-12.9重启-12.12取消ROS+top10% | F9: YYH-V1-SP-A-12.11F | G9: PZM-US-YYH-V1-1 | H9: B0CM9F3CXY | I9: 6865 | J9: 23 | K9: 0.0033503277 | L9: 0.82217391 | M9: 18.91 | N9: 0 | P9: 0 | Q9: 0 | R9: 0 | S9: 0 | T9: 0 | U9: 0 | V9: 0 | W9: 0
A10: =IF(MONTH(B10)<10,"0"&MONTH(B10)&"月",MONTH(B10)&"月") -> 12月 | B10: 45274 | C10: No Portfolio | D10: USD | E10: PP6-1-WZX-YYH-V1-SP-A-12.9重启-12.12取消ROS+top10% | F10: YYH-V1-SP-A-12.11F | G10: PZM-US-YYH-V1-1 | H10: B0CM9F3CXY | I10: 15258 | J10: 41 | K10: 0.002687115 | L10: 0.85317073 | M10: 34.98 | N10: 89.97 | O10: 0.38879627 | P10: 2.5720412 | Q10: 3 | R10: 3 | S10: 0.073170732 | T10: 3 | U10: 0 | V10: 89.97 | W10: 0
A11: =IF(MONTH(B11)<10,"0"&MONTH(B11)&"月",MONTH(B11)&"月") -> 12月 | B11: 45262 | C11: No Portfolio | D11: USD | E11: PP6-1-WZX-YYH-V1-SP-M-B-12.11重启+词 | F11: YYH-V1-SP-M-B-12.11f | G11: PZM-US-YYH-V1-1 | H11: B0CM9F3CXY | I11: 3601 | J11: 10 | K11: 0.0027770064 | L11: 1.254 | M11: 12.54 | N11: 0 | P11: 0 | Q11: 0 | R11: 0 | S11: 0 | T11: 0 | U11: 0 | V11: 0 | W11: 0
A12: =IF(MONTH(B12)<10,"0"&MONTH(B12)&"月",MONTH(B12)&"月") -> 12月 | B12: 45263 | C12: No Portfolio | D12: USD | E12: PP6-1-WZX-YYH-V1-SP-M-B-12.11重启+词 | F12: YYH-V1-SP-M-B-12.11f | G12: PZM-US-YYH-V1-1 | H12: B0CM9F3CXY | I12: 5307 | J12: 5 | K12: 0.00094215187 | L12: 1.018 | M12: 5.09 | N12: 0 | P12: 0 | Q12: 0 | R12: 0 | S12: 0 | T12: 0 | U12: 0 | V12: 0 | W12: 0
A13: =IF(MONTH(B13)<10,"0"&MONTH(B13)&"月",MONTH(B13)&"月") -> 12月 | B13: 45271 | C13: No Portfolio | D13: USD | E13: PP6-1-WZX-YYH-V1-SP-M-B-12.11重启+词 | F13: YYH-V1-SP-M-B-12.11f | G13: PZM-US-YYH-V1-1 | H13: B0CM9F3CXY | I13: 8747 | J13: 26 | K13: 0.0029724477 | L13: 0.77038462 | M13: 20.03 | N13: 42.98 | O13: 0.46603071 | P13: 2.1457813 | Q13: 2 | R13: 2 | S13: 0.076923077 | T13: 1 | U13: 1 | V13: 29.99 | W13: 12.99
A14: =IF(MONTH(B14)<10,"0"&MONTH(B14)&"月",MONTH(B14)&"月") -> 12月 | B14: 45272 | C14: No Portfolio | D14: USD | E14: PP6-1-WZX-YYH-V1-SP-M-B-12.11重启+词 | F14: YYH-V1-SP-M-B-12.11f | G14: PZM-US-YYH-V1-1 | H14: B0CM9F3CXY | I14: 61 | J14: 0 | K14: 0 | M14: 0 | N14: 0 | Q14: 0 | R14: 0 | T14: 0 | U14: 0 | V14: 0 | W14: 0
A15: =IF(MONTH(B15)<10,"0"&MONTH(B15)&"月",MONTH(B15)&"月") -> 12月 | B15: 45273 | C15: No Portfolio | D15: USD | E15: PP6-1-WZX-YYH-V1-SP-M-B-12.11重启+词 | F15: YYH-V1-SP-M-B-12.11f | G15: PZM-US-YYH-V1-1 | H15: B0CM9F3CXY | I15: 0 | J15: 0 | M15: 0 | N15: 0 | Q15: 0 | R15: 0 | T15: 0 | U15: 0 | V15: 0 | W15: 0
A16: =IF(MONTH(B16)<10,"0"&MONTH(B16)&"月",MONTH(B16)&"月") -> 12月 | B16: 45274 | C16: No Portfolio | D16: USD | E16: PP6-1-WZX-YYH-V1-SP-M-B-12.11重启+词 | F16: YYH-V1-SP-M-B-12.11f | G16: PZM-US-YYH-V1-1 | H16: B0CM9F3CXY | I16: 2710 | J16: 17 | K16: 0.0062730627 | L16: 0.92176471 | M16: 15.67 | N16: 29.99 | O16: 0.5225075 | P16: 1.9138481 | Q16: 1 | R16: 1 | S16: 0.058823529 | T16: 1 | U16: 0 | V16: 29.99 | W16: 0
A17: =IF(MONTH(B17)<10,"0"&MONTH(B17)&"月",MONTH(B17)&"月") -> 12月 | B17: 45265 | C17: No Portfolio | D17: USD | E17: PP6-1-WZX-YGH-V1-SP-M-广泛 | F17: YGH-V1-SP-B-kids+0.1+0.1 | G17: PZM-US-YGH-V1-1 | H17: B0CMJ85RH6 | I17: 3621 | J17: 10 | K17: 0.002761668 | L17: 1.131 | M17: 11.31 | N17: 0 | P17: 0 | Q17: 0 | R17: 0 | S17: 0 | T17: 0 | U17: 0 | V17: 0 | W17: 0
A18: =IF(MONTH(B18)<10,"0"&MONTH(B18)&"月",MONTH(B18)&"月") -> 12月 | B18: 45266 | C18: No Portfolio | D18: USD | E18: PP6-1-WZX-YGH-V1-SP-M-广泛 | F18: YGH-V1-SP-B-kids+0.1+0.1 | G18: PZM-US-YGH-V1-1 | H18: B0CMJ85RH6 | I18: 1926 | J18: 5 | K18: 0.002596054 | L18: 1.13 | M18: 5.65 | N18: 0 | P18: 0 | Q18: 0 | R18: 0 | S18: 0 | T18: 0 | U18: 0 | V18: 0 | W18: 0
A19: =IF(MONTH(B19)<10,"0"&MONTH(B19)&"月",MONTH(B19)&"月") -> 12月 | B19: 45265 | C19: No Portfolio | D19: USD | E19: PP6-1-WZX-YGH-V1-SP-M-广泛 | F19: YGH-V1-SP-B-大词 wood &wooden puzzle | G19: PZM-US-YGH-V1-1 | H19: B0CMJ85RH6 | I19: 4016 | J19: 12 | K19: 0.0029880478 | L19: 1.1666667 | M19: 14 | N19: 0 | P19: 0 | Q19: 0 | R19: 0 | S19: 0 | T19: 0 | U19: 0 | V19: 0 | W19: 0
A20: =IF(MONTH(B20)<10,"0"&MONTH(B20)&"月",MONTH(B20)&"月") -> 12月 | B20: 45266 | C20: No Portfolio | D20: USD | E20: PP6-1-WZX-YGH-V1-SP-M-广泛 | F20: YGH-V1-SP-B-大词 wood &wooden puzzle | G20: PZM-US-YGH-V1-1 | H20: B0CMJ85RH6 | I20: 5879 | J20: 11 | K20: 0.0018710665 | L20: 0.82636364 | M20: 9.09 | N20: 0 | P20: 0 | Q20: 0 | R20: 0 | S20: 0 | T20: 0 | U20: 0 | V20: 0 | W20: 0
A21: =IF(MONTH(B21)<10,"0"&MONTH(B21)&"月",MONTH(B21)&"月") -> 12月 | B21: 45266 | C21: No Portfolio | D21: USD | E21: PP6-1-WZX-YGH-SP-PT-CA | F21: SP-PT-12.6+0.1+01 | G21: PZM-US-YGH-V1-1 | H21: B0CMJ85RH6 | I21: 867 | J21: 5 | K21: 0.0057670127 | L21: 1.15 | M21: 5.75 | N21: 0 | P21: 0 | Q21: 0 | R21: 0 | S21: 0 | T21: 0 | U21: 0 | V21: 0 | W21: 0
A22: =IF(MONTH(B22)<10,"0"&MONTH(B22)&"月",MONTH(B22)&"月") -> 12月 | B22: 45265 | C22: No Portfolio | D22: USD | E22: PP6-1-WZX-YGH-V1-SP-A-观ROS-0.75 PP 0.5 -12.12关闭（流量偏向Adult | F22: YGH-V1-SP-A | G22: PZM-US-YGH-V1-1 | H22: B0CMJ85RH6 | I22: 2894 | J22: 16 | K22: 0.00552868 | L22: 0.7575 | M22: 12.12 | N22: 0 | P22: 0 | Q22: 0 | R22: 0 | S22: 0 | T22: 0 | U22: 0 | V22: 0 | W22: 0
A23: =IF(MONTH(B23)<10,"0"&MONTH(B23)&"月",MONTH(B23)&"月") -> 12月 | B23: 45266 | C23: No Portfolio | D23: USD | E23: PP6-1-WZX-YGH-V1-SP-A-观ROS-0.75 PP 0.5 -12.12关闭（流量偏向Adult | F23: YGH-V1-SP-A | G23: PZM-US-YGH-V1-1 | H23: B0CMJ85RH6 | I23: 10519 | J23: 20 | K23: 0.0019013214 | L23: 0.75 | M23: 15 | N23: 25.99 | O23: 0.57714506 | P23: 1.7326667 | Q23: 1 | R23: 1 | S23: 0.05 | T23: 1 | U23: 0 | V23: 25.99 | W23: 0
A24: =IF(MONTH(B24)<10,"0"&MONTH(B24)&"月",MONTH(B24)&"月") -> 12月 | B24: 45269 | C24: No Portfolio | D24: USD | E24: PP6-1-WZX-YGH-V1-SP-A-观ROS-0.75 PP 0.5 -12.12关闭（流量偏向Adult | F24: YGH-V1-SP-A | G24: PZM-US-YGH-V1-1 | H24: B0CMJ85RH6 | I24: 408 | J24: 8 | K24: 0.019607843 | L24: 0.67625 | M24: 5.41 | N24: 0 | P24: 0 | Q24: 0 | R24: 0 | S24: 0 | T24: 0 | U24: 0 | V24: 0 | W24: 0
A25: =IF(MONTH(B25)<10,"0"&MONTH(B25)&"月",MONTH(B25)&"月") -> 12月 | B25: 45270 | C25: No Portfolio | D25: USD | E25: PP6-1-WZX-YGH-V1-SP-A-观ROS-0.75 PP 0.5 -12.12关闭（流量偏向Adult | F25: YGH-V1-SP-A | G25: PZM-US-YGH-V1-1 | H25: B0CMJ85RH6 | I25: 1449 | J25: 9 | K25: 0.0062111801 | L25: 0.66111111 | M25: 5.95 | N25: 0 | P25: 0 | Q25: 0 | R25: 0 | S25: 0 | T25: 0 | U25: 0 | V25: 0 | W25: 0
A26: =IF(MONTH(B26)<10,"0"&MONTH(B26)&"月",MONTH(B26)&"月") -> 12月 | B26: 45271 | C26: No Portfolio | D26: USD | E26: PP6-1-WZX-YGH-V1-SP-A-观ROS-0.75 PP 0.5 -12.12关闭（流量偏向Adult | F26: YGH-V1-SP-A | G26: PZM-US-YGH-V1-1 | H26: B0CMJ85RH6 | I26: 4452 | J26: 19 | K26: 0.0042677448 | L26: 0.55 | M26: 10.45 | N26: 0 | P26: 0 | Q26: 0 | R26: 0 | S26: 0 | T26: 0 | U26: 0 | V26: 0 | W26: 0
A27: =IF(MONTH(B27)<10,"0"&MONTH(B27)&"月",MONTH(B27)&"月") -> 12月 | B27: 45268 | C27: No Portfolio | D27: USD | E27: PP6-1-WZX-XBJ-V1-SP-M-E-长尾词kid 12.11加词 | F27: YYH-V1-12月12日启动-精推词3d puzzles for kids ages 12-14（XBJ-V1-12.8建，12.11-YGH-close）-3d puzzles for kids ages 观察出单词流量变化 | G27: PZM-US-XBJ-V1-1 | H27: B0CMHNDQT8 | I27: 3775 | J27: 4 | K27: 0.0010596026 | L27: 0.88 | M27: 3.52 | N27: 25.98 | O27: 0.13548884 | P27: 7.3806818 | Q27: 1 | R27: 2 | S27: 0.25 | T27: 2 | U27: 0 | V27: 25.98 | W27: 0
A28: =IF(MONTH(B28)<10,"0"&MONTH(B28)&"月",MONTH(B28)&"月") -> 12月 | B28: 45269 | C28: No Portfolio | D28: USD | E28: PP6-1-WZX-XBJ-V1-SP-M-E-长尾词kid 12.11加词 | F28: YYH-V1-12月12日启动-精推词3d puzzles for kids ages 12-14（XBJ-V1-12.8建，12.11-YGH-close）-3d puzzles for kids ages 观察出单词流量变化 | G28: PZM-US-XBJ-V1-1 | H28: B0CMHNDQT8 | I28: 6592 | J28: 9 | K28: 0.0013652913 | L28: 1.0844444 | M28: 9.76 | N28: 0 | P28: 0 | Q28: 0 | R28: 0 | S28: 0 | T28: 0 | U28: 0 | V28: 0 | W28: 0
A29: =IF(MONTH(B29)<10,"0"&MONTH(B29)&"月",MONTH(B29)&"月") -> 12月 | B29: 45270 | C29: No Portfolio | D29: USD | E29: PP6-1-WZX-XBJ-V1-SP-M-E-长尾词kid 12.11加词 | F29: YYH-V1-12月12日启动-精推词3d puzzles for kids ages 12-14（XBJ-V1-12.8建，12.11-YGH-close）-3d puzzles for kids ages 观察出单词流量变化 | G29: PZM-US-XBJ-V1-1 | H29: B0CMHNDQT8 | I29: 2386 | J29: 0 | K29: 0 | M29: 0 | N29: 0 | Q29: 0 | R29: 0 | T29: 0 | U29: 0 | V29: 0 | W29: 0
A30: =IF(MONTH(B30)<10,"0"&MONTH(B30)&"月",MONTH(B30)&"月") -> 12月 | B30: 45271 | C30: No Portfolio | D30: USD | E30: PP6-1-WZX-XBJ-V1-SP-M-E-长尾词kid 12.11加词 | F30: YYH-V1-12月12日启动-精推词3d puzzles for kids ages 12-14（XBJ-V1-12.8建，12.11-YGH-close）-3d puzzles for kids ages 观察出单词流量变化 | G30: PZM-US-XBJ-V1-1 | H30: B0CMHNDQT8 | I30: 9975 | J30: 16 | K30: 0.00160401 | L30: 0.94125 | M30: 15.06 | N30: 0 | P30: 0 | Q30: 0 | R30: 0 | S30: 0 | T30: 0 | U30: 0 | V30: 0 | W30: 0
A31: =IF(MONTH(B31)<10,"0"&MONTH(B31)&"月",MONTH(B31)&"月") -> 12月 | B31: 45272 | C31: No Portfolio | D31: USD | E31: PP6-1-WZX-XBJ-V1-SP-M-E-长尾词kid 12.11加词 | F31: YYH-V1-12月12日启动-精推词3d puzzles for kids ages 12-14（XBJ-V1-12.8建，12.11-YGH-close）-3d puzzles for kids ages 观察出单词流量变化 | G31: PZM-US-XBJ-V1-1 | H31: B0CMHNDQT8 | I31: 5008 | J31: 12 | K31: 0.0023961661 | L31: 1.0341667 | M31: 12.41 | N31: 0 | P31: 0 | Q31: 0 | R31: 0 | S31: 0 | T31: 0 | U31: 0 | V31: 0 | W31: 0
A32: =IF(MONTH(B32)<10,"0"&MONTH(B32)&"月",MONTH(B32)&"月") -> 12月 | B32: 45269 | C32: No Portfolio | D32: USD | E32: PP6-1-WZX-XBJ-V1-SP-A-12-0.03+f/12.12-保持ROS0.91 | F32: XBJ-V1-12.12F-12.10 | G32: PZM-US-XBJ-V1-1 | H32: B0CMHNDQT8 | I32: 2346 | J32: 23 | K32: 0.0098039216 | L32: 1.0565217 | M32: 24.3 | N32: 12.99 | O32: 1.8706697 | P32: 0.5345679 | Q32: 1 | R32: 1 | S32: 0.043478261 | T32: 1 | U32: 0 | V32: 12.99 | W32: 0
A33: =IF(MONTH(B33)<10,"0"&MONTH(B33)&"月",MONTH(B33)&"月") -> 12月 | B33: 45270 | C33: No Portfolio | D33: USD | E33: PP6-1-WZX-XBJ-V1-SP-A-12-0.03+f/12.12-保持ROS0.91 | F33: XBJ-V1-12.12F-12.10 | G33: PZM-US-XBJ-V1-1 | H33: B0CMHNDQT8 | I33: 2347 | J33: 12 | K33: 0.0051129101 | L33: 0.8125 | M33: 9.75 | N33: 0 | P33: 0 | Q33: 0 | R33: 0 | S33: 0 | T33: 0 | U33: 0 | V33: 0 | W33: 0
A34: =IF(MONTH(B34)<10,"0"&MONTH(B34)&"月",MONTH(B34)&"月") -> 12月 | B34: 45271 | C34: No Portfolio | D34: USD | E34: PP6-1-WZX-XBJ-V1-SP-A-12-0.03+f/12.12-保持ROS0.91 | F34: XBJ-V1-12.12F-12.10 | G34: PZM-US-XBJ-V1-1 | H34: B0CMHNDQT8 | I34: 7312 | J34: 47 | K34: 0.0064277899 | L34: 0.85191489 | M34: 40.04 | N34: 51.96 | O34: 0.77059276 | P34: 1.2977023 | Q34: 4 | R34: 4 | S34: 0.085106383 | T34: 4 | U34: 0 | V34: 51.96 | W34: 0
A35: =IF(MONTH(B35)<10,"0"&MONTH(B35)&"月",MONTH(B35)&"月") -> 12月 | B35: 45272 | C35: No Portfolio | D35: USD | E35: PP6-1-WZX-XBJ-V1-SP-A-12-0.03+f/12.12-保持ROS0.91 | F35: XBJ-V1-12.12F-12.10 | G35: PZM-US-XBJ-V1-1 | H35: B0CMHNDQT8 | I35: 8718 | J35: 40 | K35: 0.0045882083 | L35: 0.8105 | M35: 32.42 | N35: 0 | P35: 0 | Q35: 0 | R35: 0 | S35: 0 | T35: 0 | U35: 0 | V35: 0 | W35: 0
A36: =IF(MONTH(B36)<10,"0"&MONTH(B36)&"月",MONTH(B36)&"月") -> 12月 | B36: 45273 | C36: No Portfolio | D36: USD | E36: PP6-1-WZX-XBJ-V1-SP-A-12-0.03+f/12.12-保持ROS0.91 | F36: XBJ-V1-12.12F-12.10 | G36: PZM-US-XBJ-V1-1 | H36: B0CMHNDQT8 | I36: 4216 | J36: 18 | K36: 0.0042694497 | L36: 0.74277778 | M36: 13.37 | N36: 0 | P36: 0 | Q36: 0 | R36: 0 | S36: 0 | T36: 0 | U36: 0 | V36: 0 | W36: 0
A37: =IF(MONTH(B37)<10,"0"&MONTH(B37)&"月",MONTH(B37)&"月") -> 12月 | B37: 45274 | C37: No Portfolio | D37: USD | E37: PP6-1-WZX-XBJ-V1-SP-A-12-0.03+f/12.12-保持ROS0.91 | F37: XBJ-V1-12.12F-12.10 | G37: PZM-US-XBJ-V1-1 | H37: B0CMHNDQT8 | I37: 5491 | J37: 10 | K37: 0.0018211619 | L37: 0.808 | M37: 8.08 | N37: 0 | P37: 0 | Q37: 0 | R37: 0 | S37: 0 | T37: 0 | U37: 0 | V37: 0 | W37: 0
A38: =IF(MONTH(B38)<10,"0"&MONTH(B38)&"月",MONTH(B38)&"月") -> 12月 | B38: 45269 | C38: No Portfolio | D38: USD | E38: PP6-1-WZX-XBJ-V1-SP-A-12-0.03+f/12.12-保持ROS0.91 | F38: YGH-V1-12.10关闭 | G38: PZM-US-YGH-V1-1 | H38: B0CMJ85RH6 | I38: 2921 | J38: 20 | K38: 0.0068469702 | L38: 0.791 | M38: 15.82 | N38: 0 | P38: 0 | Q38: 0 | R38: 0 | S38: 0 | T38: 0 | U38: 0 | V38: 0 | W38: 0
A39: =IF(MONTH(B39)<10,"0"&MONTH(B39)&"月",MONTH(B39)&"月") -> 12月 | B39: 45269 | C39: No Portfolio | D39: USD | E39: PP6-1-WZX-XBJ-V1-SP-M-E-长尾词kid 12.11加词 | F39: YYH-V1-12月12日启动-精推词3d puzzles for kids ages 12-14（XBJ-V1-12.8建，12.11-YGH-close）-3d puzzles for kids ages 观察出单词流量变化 | G39: PZM-US-YGH-V1-1 | H39: B0CMJ85RH6 | I39: 1963 | J39: 18 | K39: 0.0091696383 | L39: 1.1038889 | M39: 19.87 | N39: 25.99 | O39: 0.76452482 | P39: 1.308002 | Q39: 1 | R39: 1 | S39: 0.055555556 | T39: 1 | U39: 0 | V39: 25.99 | W39: 0
A40: =IF(MONTH(B40)<10,"0"&MONTH(B40)&"月",MONTH(B40)&"月") -> 12月 | B40: 45270 | C40: No Portfolio | D40: USD | E40: PP6-1-WZX-XBJ-V1-SP-M-E-长尾词kid 12.11加词 | F40: YYH-V1-12月12日启动-精推词3d puzzles for kids ages 12-14（XBJ-V1-12.8建，12.11-YGH-close）-3d puzzles for kids ages 观察出单词流量变化 | G40: PZM-US-YGH-V1-1 | H40: B0CMJ85RH6 | I40: 2160 | J40: 16 | K40: 0.0074074074 | L40: 1.241875 | M40: 19.87 | N40: 0 | P40: 0 | Q40: 0 | R40: 0 | S40: 0 | T40: 0 | U40: 0 | V40: 0 | W40: 0
...
