Workbook
Name BSR【站点】: 运营数据表!#REF!
Name 站点: 站点目录!$A$2:$A$11

Sheet 表格使用说明
A2: 1. 数据导入
A3: ① | B3: 业绩报告
B4: 下载路径：亚马逊卖家后台>Business Report>Child Asin Report (筛选当天数据)
A6: ② | B6: Base
B7: 将所在站点销售的产品信息（站点，品名，ASIN,SKU）登记到这个BASE表中
A9: ③ | B9: 站点目录（二级目录）
B10: 将所在站点销售的产品品名进行登记
A14: ④ | B14: 广告数据 | C14: 从广告报表直接导出全部复制到本栏

Sheet 运营数据表
A1: 2022 | B1: 年份 | C1: 10 | D1: 月份 | E1: 7 | F1: 日期
A3: 运营数据表 | C3: =DATE($A$1,$C$1,$E$1) -> 44841 | D3: =DATE(YEAR(C3),MONTH(C3),DAY(C3)+1) -> 44842 | E3: =DATE(YEAR(D3),MONTH(D3),DAY(D3)+1) -> 44843 | F3: =DATE(YEAR(E3),MONTH(E3),DAY(E3)+1) -> 44844 | G3: =DATE(YEAR(F3),MONTH(F3),DAY(F3)+1) -> 44845 | H3: =DATE(YEAR(G3),MONTH(G3),DAY(G3)+1) -> 44846 | I3: =DATE(YEAR(H3),MONTH(H3),DAY(H3)+1) -> 44847 | J3: =WEEKNUM(C3,2)&"周" -> 41周 | K3: =DATE(YEAR(C3),MONTH(C3),DAY(C3)-1) -> 44840 | L3: =DATE(YEAR(K3),MONTH(K3),DAY(K3)-1) -> 44839 | M3: =DATE(YEAR(L3),MONTH(L3),DAY(L3)-1) -> 44838 | N3: =DATE(YEAR(M3),MONTH(M3),DAY(M3)-1) -> 44837 | O3: =DATE(YEAR(N3),MONTH(N3),DAY(N3)-1) -> 44836 | P3: =DATE(YEAR(O3),MONTH(O3),DAY(O3)-1) -> 44835 | Q3: =DATE(YEAR(P3),MONTH(P3),DAY(P3)-1) -> 44834 | R3: =WEEKNUM(K3,2)-1&"周" -> 40周 | S3: 周环比
C4: ="星期"&WEEKDAY(C3,2) -> 星期5 | D4: ="星期"&WEEKDAY(D3,2) -> 星期6 | E4: ="星期"&WEEKDAY(E3,2) -> 星期7 | F4: ="星期"&WEEKDAY(F3,2) -> 星期1 | G4: ="星期"&WEEKDAY(G3,2) -> 星期2 | H4: ="星期"&WEEKDAY(H3,2) -> 星期3 | I4: ="星期"&WEEKDAY(I3,2) -> 星期4 | K4: ="星期"&WEEKDAY(K3,2) -> 星期4 | L4: ="星期"&WEEKDAY(L3,2) -> 星期3 | M4: ="星期"&WEEKDAY(M3,2) -> 星期2 | N4: ="星期"&WEEKDAY(N3,2) -> 星期1 | O4: ="星期"&WEEKDAY(O3,2) -> 星期7 | P4: ="星期"&WEEKDAY(P3,2) -> 星期6 | Q4: ="星期"&WEEKDAY(Q3,2) -> 星期5
A5: 销售站点 | B5: 总浏览量/PV | C5: {=IFERROR(VLOOKUP(C$3&$A6&$A9,IF({1,0},业绩报告!$A$2:$A$8229&业绩报告!$B$2:$B$8229&业绩报告!$C$2:$C$8229,业绩报告!$F$2:$F$8229),2,0),"")} -> 571 | D5: {=IFERROR(VLOOKUP(D$3&$A6&$A9,IF({1,0},业绩报告!$A$2:$A$8229&业绩报告!$B$2:$B$8229&业绩报告!$C$2:$C$8229,业绩报告!$F$2:$F$8229),2,0),"")} -> 534 | E5: {=IFERROR(VLOOKUP(E$3&$A6&$A9,IF({1,0},业绩报告!$A$2:$A$8229&业绩报告!$B$2:$B$8229&业绩报告!$C$2:$C$8229,业绩报告!$F$2:$F$8229),2,0),"")} -> 668 | F5: {=IFERROR(VLOOKUP(F$3&$A6&$A9,IF({1,0},业绩报告!$A$2:$A$8229&业绩报告!$B$2:$B$8229&业绩报告!$C$2:$C$8229,业绩报告!$F$2:$F$8229),2,0),"")} -> 506 | G5: {=IFERROR(VLOOKUP(G$3&$A6&$A9,IF({1,0},业绩报告!$A$2:$A$8229&业绩报告!$B$2:$B$8229&业绩报告!$C$2:$C$8229,业绩报告!$F$2:$F$8229),2,0),"")} -> 533 | H5: {=IFERROR(VLOOKUP(H$3&$A6&$A9,IF({1,0},业绩报告!$A$2:$A$8229&业绩报告!$B$2:$B$8229&业绩报告!$C$2:$C$8229,业绩报告!$F$2:$F$8229),2,0),"")} -> 0 | I5: {=IFERROR(VLOOKUP(I$3&$A6&$A9,IF({1,0},业绩报告!$A$2:$A$8229&业绩报告!$B$2:$B$8229&业绩报告!$C$2:$C$8229,业绩报告!$F$2:$F$8229),2,0),"")} -> 0 | J5: =SUM(C5:I5) -> 2812 | K5: {=IFERROR(VLOOKUP(K$3&$A6&$A9,IF({1,0},业绩报告!$A$2:$A$8229&业绩报告!$B$2:$B$8229&业绩报告!$C$2:$C$8229,业绩报告!$F$2:$F$8229),2,0),"")} -> 895 | L5: {=IFERROR(VLOOKUP(L$3&$A6&$A9,IF({1,0},业绩报告!$A$2:$A$8229&业绩报告!$B$2:$B$8229&业绩报告!$C$2:$C$8229,业绩报告!$F$2:$F$8229),2,0),"")} -> 827 | M5: {=IFERROR(VLOOKUP(M$3&$A6&$A9,IF({1,0},业绩报告!$A$2:$A$8229&业绩报告!$B$2:$B$8229&业绩报告!$C$2:$C$8229,业绩报告!$F$2:$F$8229),2,0),"")} -> 639 | N5: {=IFERROR(VLOOKUP(N$3&$A6&$A9,IF({1,0},业绩报告!$A$2:$A$8229&业绩报告!$B$2:$B$8229&业绩报告!$C$2:$C$8229,业绩报告!$F$2:$F$8229),2,0),"")} -> 812 | O5: {=IFERROR(VLOOKUP(O$3&$A6&$A9,IF({1,0},业绩报告!$A$2:$A$8229&业绩报告!$B$2:$B$8229&业绩报告!$C$2:$C$8229,业绩报告!$F$2:$F$8229),2,0),"")} -> 947 | P5: {=IFERROR(VLOOKUP(P$3&$A6&$A9,IF({1,0},业绩报告!$A$2:$A$8229&业绩报告!$B$2:$B$8229&业绩报告!$C$2:$C$8229,业绩报告!$F$2:$F$8229),2,0),"")} -> 555 | Q5: {=IFERROR(VLOOKUP(Q$3&$A6&$A9,IF({1,0},业绩报告!$A$2:$A$8229&业绩报告!$B$2:$B$8229&业绩报告!$C$2:$C$8229,业绩报告!$F$2:$F$8229),2,0),"")} -> 391 | R5: =SUM(K5:Q5) -> 5066
A6: US | B6: 访客数/UV | C6: {=IFERROR(VLOOKUP(C$3&$A6&$A9,IF({1,0},业绩报告!$A$2:$A$8229&业绩报告!$B$2:$B$8229&业绩报告!$C$2:$C$8229,业绩报告!$E$2:$E$8229),2,0),"")} -> 426 | D6: {=IFERROR(VLOOKUP(D$3&$A6&$A9,IF({1,0},业绩报告!$A$2:$A$8229&业绩报告!$B$2:$B$8229&业绩报告!$C$2:$C$8229,业绩报告!$E$2:$E$8229),2,0),"")} -> 404 | E6: {=IFERROR(VLOOKUP(E$3&$A6&$A9,IF({1,0},业绩报告!$A$2:$A$8229&业绩报告!$B$2:$B$8229&业绩报告!$C$2:$C$8229,业绩报告!$E$2:$E$8229),2,0),"")} -> 486 | F6: {=IFERROR(VLOOKUP(F$3&$A6&$A9,IF({1,0},业绩报告!$A$2:$A$8229&业绩报告!$B$2:$B$8229&业绩报告!$C$2:$C$8229,业绩报告!$E$2:$E$8229),2,0),"")} -> 385 | G6: {=IFERROR(VLOOKUP(G$3&$A6&$A9,IF({1,0},业绩报告!$A$2:$A$8229&业绩报告!$B$2:$B$8229&业绩报告!$C$2:$C$8229,业绩报告!$E$2:$E$8229),2,0),"")} -> 406 | H6: {=IFERROR(VLOOKUP(H$3&$A6&$A9,IF({1,0},业绩报告!$A$2:$A$8229&业绩报告!$B$2:$B$8229&业绩报告!$C$2:$C$8229,业绩报告!$E$2:$E$8229),2,0),"")} -> 0 | I6: {=IFERROR(VLOOKUP(I$3&$A6&$A9,IF({1,0},业绩报告!$A$2:$A$8229&业绩报告!$B$2:$B$8229&业绩报告!$C$2:$C$8229,业绩报告!$E$2:$E$8229),2,0),"")} -> 0 | J6: =SUM(C6:I6) -> 2107 | K6: {=IFERROR(VLOOKUP(K$3&$A6&$A9,IF({1,0},业绩报告!$A$2:$A$8229&业绩报告!$B$2:$B$8229&业绩报告!$C$2:$C$8229,业绩报告!$E$2:$E$8229),2,0),"")} -> 677 | L6: {=IFERROR(VLOOKUP(L$3&$A6&$A9,IF({1,0},业绩报告!$A$2:$A$8229&业绩报告!$B$2:$B$8229&业绩报告!$C$2:$C$8229,业绩报告!$E$2:$E$8229),2,0),"")} -> 632 | M6: {=IFERROR(VLOOKUP(M$3&$A6&$A9,IF({1,0},业绩报告!$A$2:$A$8229&业绩报告!$B$2:$B$8229&业绩报告!$C$2:$C$8229,业绩报告!$E$2:$E$8229),2,0),"")} -> 474 | N6: {=IFERROR(VLOOKUP(N$3&$A6&$A9,IF({1,0},业绩报告!$A$2:$A$8229&业绩报告!$B$2:$B$8229&业绩报告!$C$2:$C$8229,业绩报告!$E$2:$E$8229),2,0),"")} -> 631 | O6: {=IFERROR(VLOOKUP(O$3&$A6&$A9,IF({1,0},业绩报告!$A$2:$A$8229&业绩报告!$B$2:$B$8229&业绩报告!$C$2:$C$8229,业绩报告!$E$2:$E$8229),2,0),"")} -> 689 | P6: {=IFERROR(VLOOKUP(P$3&$A6&$A9,IF({1,0},业绩报告!$A$2:$A$8229&业绩报告!$B$2:$B$8229&业绩报告!$C$2:$C$8229,业绩报告!$E$2:$E$8229),2,0),"")} -> 386 | Q6: {=IFERROR(VLOOKUP(Q$3&$A6&$A9,IF({1,0},业绩报告!$A$2:$A$8229&业绩报告!$B$2:$B$8229&业绩报告!$C$2:$C$8229,业绩报告!$E$2:$E$8229),2,0),"")} -> 303 | R6: =SUM(K6:Q6) -> 3792
A7: US | B7: 自然浏览量/pv | C7: =C5-C81 -> 495 | D7: =D5-D81 -> 475 | E7: =E5-E81 -> 581 | F7: =F5-F81 -> 431 | G7: =G5-G81 -> 442 | H7: =H5-H81 -> -98 | I7: =I5-I81 -> 0 | J7: =J5-J81 -> 2326 | ... R7: =R5-R81 -> 4413
A8: 产品名 | B8: 总销量 | C8: {=IFERROR(VLOOKUP(C$3&$A6&$A9,IF({1,0},业绩报告!$A$2:$A$8229&业绩报告!$B$2:$B$8229&业绩报告!$C$2:$C$8229,业绩报告!$G$2:$G$8229),2,0),"")} -> 31 | D8: {=IFERROR(VLOOKUP(D$3&$A6&$A9,IF({1,0},业绩报告!$A$2:$A$8229&业绩报告!$B$2:$B$8229&业绩报告!$C$2:$C$8229,业绩报告!$G$2:$G$8229),2,0),"")} -> 27 | E8: {=IFERROR(VLOOKUP(E$3&$A6&$A9,IF({1,0},业绩报告!$A$2:$A$8229&业绩报告!$B$2:$B$8229&业绩报告!$C$2:$C$8229,业绩报告!$G$2:$G$8229),2,0),"")} -> 18 | F8: {=IFERROR(VLOOKUP(F$3&$A6&$A9,IF({1,0},业绩报告!$A$2:$A$8229&业绩报告!$B$2:$B$8229&业绩报告!$C$2:$C$8229,业绩报告!$G$2:$G$8229),2,0),"")} -> 27 | G8: {=IFERROR(VLOOKUP(G$3&$A6&$A9,IF({1,0},业绩报告!$A$2:$A$8229&业绩报告!$B$2:$B$8229&业绩报告!$C$2:$C$8229,业绩报告!$G$2:$G$8229),2,0),"")} -> 44 | H8: {=IFERROR(VLOOKUP(H$3&$A6&$A9,IF({1,0},业绩报告!$A$2:$A$8229&业绩报告!$B$2:$B$8229&业绩报告!$C$2:$C$8229,业绩报告!$G$2:$G$8229),2,0),"")} -> 55 | I8: {=IFERROR(VLOOKUP(I$3&$A6&$A9,IF({1,0},业绩报告!$A$2:$A$8229&业绩报告!$B$2:$B$8229&业绩报告!$C$2:$C$8229,业绩报告!$G$2:$G$8229),2,0),"")} -> 0 | J8: =SUM(C8:I8) -> 202 | K8: {=IFERROR(VLOOKUP(K$3&$A6&$A9,IF({1,0},业绩报告!$A$2:$A$8229&业绩报告!$B$2:$B$8229&业绩报告!$C$2:$C$8229,业绩报告!$G$2:$G$8229),2,0),"")} -> 31 | L8: {=IFERROR(VLOOKUP(L$3&$A6&$A9,IF({1,0},业绩报告!$A$2:$A$8229&业绩报告!$B$2:$B$8229&业绩报告!$C$2:$C$8229,业绩报告!$G$2:$G$8229),2,0),"")} -> 28 | M8: {=IFERROR(VLOOKUP(M$3&$A6&$A9,IF({1,0},业绩报告!$A$2:$A$8229&业绩报告!$B$2:$B$8229&业绩报告!$C$2:$C$8229,业绩报告!$G$2:$G$8229),2,0),"")} -> 36 | N8: {=IFERROR(VLOOKUP(N$3&$A6&$A9,IF({1,0},业绩报告!$A$2:$A$8229&业绩报告!$B$2:$B$8229&业绩报告!$C$2:$C$8229,业绩报告!$G$2:$G$8229),2,0),"")} -> 39 | O8: {=IFERROR(VLOOKUP(O$3&$A6&$A9,IF({1,0},业绩报告!$A$2:$A$8229&业绩报告!$B$2:$B$8229&业绩报告!$C$2:$C$8229,业绩报告!$G$2:$G$8229),2,0),"")} -> 38 | P8: {=IFERROR(VLOOKUP(P$3&$A6&$A9,IF({1,0},业绩报告!$A$2:$A$8229&业绩报告!$B$2:$B$8229&业绩报告!$C$2:$C$8229,业绩报告!$G$2:$G$8229),2,0),"")} -> 29 | Q8: {=IFERROR(VLOOKUP(Q$3&$A6&$A9,IF({1,0},业绩报告!$A$2:$A$8229&业绩报告!$B$2:$B$8229&业绩报告!$C$2:$C$8229,业绩报告!$G$2:$G$8229),2,0),"")} -> 23 | R8: =SUM(K8:Q8) -> 224
A9: 按压皂液器 | B9: 转化率 | C9: =IFERROR(C8/C6,"0") -> 0.072769953 | D9: =IFERROR(D8/D6,"0") -> 0.066831683 | E9: =IFERROR(E8/E6,"0") -> 0.037037037 | F9: =IFERROR(F8/F6,"0") -> 0.07012987 | G9: =IFERROR(G8/G6,"0") -> 0.10837438 | H9: =IFERROR(H8/H6,"0") -> 0 | I9: =IFERROR(I8/I6,"0") -> 0 | J9: =IFERROR(J8/J6,"0") -> 0.095870907 | ... R9: =IFERROR(R8/R6,"0") -> 0.05907173
A10: {=VLOOKUP($A$6&$A$9,IF({1,0},base!$C$2:$C$13&base!$D$2:$D$13,base!$F$2:$F$13),2,0)} -> B0B17717D3 | B10: 销售额 | C10: {=IFERROR(VLOOKUP(C$3&$A6&$A9,IF({1,0},业绩报告!$A$2:$A$8229&业绩报告!$B$2:$B$8229&业绩报告!$C$2:$C$8229,业绩报告!$H$2:$H$8229),2,0),"")} -> 371.69 | D10: {=IFERROR(VLOOKUP(D$3&$A6&$A9,IF({1,0},业绩报告!$A$2:$A$8229&业绩报告!$B$2:$B$8229&业绩报告!$C$2:$C$8229,业绩报告!$H$2:$H$8229),2,0),"")} -> 323.73 | E10: {=IFERROR(VLOOKUP(E$3&$A6&$A9,IF({1,0},业绩报告!$A$2:$A$8229&业绩报告!$B$2:$B$8229&业绩报告!$C$2:$C$8229,业绩报告!$H$2:$H$8229),2,0),"")} -> 215.82 | F10: {=IFERROR(VLOOKUP(F$3&$A6&$A9,IF({1,0},业绩报告!$A$2:$A$8229&业绩报告!$B$2:$B$8229&业绩报告!$C$2:$C$8229,业绩报告!$H$2:$H$8229),2,0),"")} -> 323.73 | G10: {=IFERROR(VLOOKUP(G$3&$A6&$A9,IF({1,0},业绩报告!$A$2:$A$8229&业绩报告!$B$2:$B$8229&业绩报告!$C$2:$C$8229,业绩报告!$H$2:$H$8229),2,0),"")} -> 429.16 | H10: {=IFERROR(VLOOKUP(H$3&$A6&$A9,IF({1,0},业绩报告!$A$2:$A$8229&业绩报告!$B$2:$B$8229&业绩报告!$C$2:$C$8229,业绩报告!$H$2:$H$8229),2,0),"")} -> 539.45 | I10: {=IFERROR(VLOOKUP(I$3&$A6&$A9,IF({1,0},业绩报告!$A$2:$A$8229&业绩报告!$B$2:$B$8229&业绩报告!$C$2:$C$8229,业绩报告!$H$2:$H$8229),2,0),"")} -> 0 | J10: =IFERROR(SUM(C10:I10),"0") -> 2203.58 | K10: {=IFERROR(VLOOKUP(K$3&$A6&$A9,IF({1,0},业绩报告!$A$2:$A$8229&业绩报告!$B$2:$B$8229&业绩报告!$C$2:$C$8229,业绩报告!$H$2:$H$8229),2,0),"")} -> 371.69 | L10: {=IFERROR(VLOOKUP(L$3&$A6&$A9,IF({1,0},业绩报告!$A$2:$A$8229&业绩报告!$B$2:$B$8229&业绩报告!$C$2:$C$8229,业绩报告!$H$2:$H$8229),2,0),"")} -> 335.72 | M10: {=IFERROR(VLOOKUP(M$3&$A6&$A9,IF({1,0},业绩报告!$A$2:$A$8229&业绩报告!$B$2:$B$8229&业绩报告!$C$2:$C$8229,业绩报告!$H$2:$H$8229),2,0),"")} -> 431.64 | N10: {=IFERROR(VLOOKUP(N$3&$A6&$A9,IF({1,0},业绩报告!$A$2:$A$8229&业绩报告!$B$2:$B$8229&业绩报告!$C$2:$C$8229,业绩报告!$H$2:$H$8229),2,0),"")} -> 467.61 | O10: {=IFERROR(VLOOKUP(O$3&$A6&$A9,IF({1,0},业绩报告!$A$2:$A$8229&业绩报告!$B$2:$B$8229&业绩报告!$C$2:$C$8229,业绩报告!$H$2:$H$8229),2,0),"")} -> 455.62 | P10: {=IFERROR(VLOOKUP(P$3&$A6&$A9,IF({1,0},业绩报告!$A$2:$A$8229&业绩报告!$B$2:$B$8229&业绩报告!$C$2:$C$8229,业绩报告!$H$2:$H$8229),2,0),"")} -> 347.71 | Q10: {=IFERROR(VLOOKUP(Q$3&$A6&$A9,IF({1,0},业绩报告!$A$2:$A$8229&业绩报告!$B$2:$B$8229&业绩报告!$C$2:$C$8229,业绩报告!$H$2:$H$8229),2,0),"")} -> 275.77 | R10: =K10+L10+M10+N10+O10+P10+Q10 -> 2685.76
B11: 自然单 | C11: =C8-C82 -> 28 | D11: =D8-D82 -> 27 | E11: =E8-E82 -> 12 | F11: =F8-F82 -> 22 | G11: =G8-G82 -> 40 | H11: =H8-H82 -> 48 | I11: =I8-I82 -> 0 | J11: =SUM(C11:I11) -> 177 | K11: =K8-K82 -> 30 | L11: =L8-L82 -> 21 | M11: =M8-M82 -> 26 | N11: =N8-N82 -> 28 | O11: =O8-O82 -> 28 | P11: =P8-P82 -> 20 | Q11: =Q8-Q82 -> 18
B12: 售价 | C12: {=IFERROR(VLOOKUP(C$3&$A6&$A9,IF({1,0},业绩报告!$A$2:$A$8229&业绩报告!$B$2:$B$8229&业绩报告!$C$2:$C$8229,业绩报告!$I$2:$I$8229),2,0),"")} -> 11.99 | D12: {=IFERROR(VLOOKUP(D$3&$A6&$A9,IF({1,0},业绩报告!$A$2:$A$8229&业绩报告!$B$2:$B$8229&业绩报告!$C$2:$C$8229,业绩报告!$I$2:$I$8229),2,0),"")} -> 11.99 | E12: {=IFERROR(VLOOKUP(E$3&$A6&$A9,IF({1,0},业绩报告!$A$2:$A$8229&业绩报告!$B$2:$B$8229&业绩报告!$C$2:$C$8229,业绩报告!$I$2:$I$8229),2,0),"")} -> 11.99 | F12: {=IFERROR(VLOOKUP(F$3&$A6&$A9,IF({1,0},业绩报告!$A$2:$A$8229&业绩报告!$B$2:$B$8229&业绩报告!$C$2:$C$8229,业绩报告!$I$2:$I$8229),2,0),"")} -> 11.99 | G12: {=IFERROR(VLOOKUP(G$3&$A6&$A9,IF({1,0},业绩报告!$A$2:$A$8229&业绩报告!$B$2:$B$8229&业绩报告!$C$2:$C$8229,业绩报告!$I$2:$I$8229),2,0),"")} -> 9.59 | H12: {=IFERROR(VLOOKUP(H$3&$A6&$A9,IF({1,0},业绩报告!$A$2:$A$8229&业绩报告!$B$2:$B$8229&业绩报告!$C$2:$C$8229,业绩报告!$I$2:$I$8229),2,0),"")} -> 9.59 | I12: {=IFERROR(VLOOKUP(I$3&$A6&$A9,IF({1,0},业绩报告!$A$2:$A$8229&业绩报告!$B$2:$B$8229&业绩报告!$C$2:$C$8229,业绩报告!$I$2:$I$8229),2,0),"")} -> 11.99 | J12: =AVERAGE(C12:I12) -> 11.304286 | K12: {=IFERROR(VLOOKUP(K$3&$A6&$A9,IF({1,0},业绩报告!$A$2:$A$8229&业绩报告!$B$2:$B$8229&业绩报告!$C$2:$C$8229,业绩报告!$I$2:$I$8229),2,0),"")} -> 11.99 | L12: {=IFERROR(VLOOKUP(L$3&$A6&$A9,IF({1,0},业绩报告!$A$2:$A$8229&业绩报告!$B$2:$B$8229&业绩报告!$C$2:$C$8229,业绩报告!$I$2:$I$8229),2,0),"")} -> 11.99 | M12: {=IFERROR(VLOOKUP(M$3&$A6&$A9,IF({1,0},业绩报告!$A$2:$A$8229&业绩报告!$B$2:$B$8229&业绩报告!$C$2:$C$8229,业绩报告!$I$2:$I$8229),2,0),"")} -> 11.99 | N12: {=IFERROR(VLOOKUP(N$3&$A6&$A9,IF({1,0},业绩报告!$A$2:$A$8229&业绩报告!$B$2:$B$8229&业绩报告!$C$2:$C$8229,业绩报告!$I$2:$I$8229),2,0),"")} -> 11.99 | O12: {=IFERROR(VLOOKUP(O$3&$A6&$A9,IF({1,0},业绩报告!$A$2:$A$8229&业绩报告!$B$2:$B$8229&业绩报告!$C$2:$C$8229,业绩报告!$I$2:$I$8229),2,0),"")} -> 11.99 | P12: {=IFERROR(VLOOKUP(P$3&$A6&$A9,IF({1,0},业绩报告!$A$2:$A$8229&业绩报告!$B$2:$B$8229&业绩报告!$C$2:$C$8229,业绩报告!$I$2:$I$8229),2,0),"")} -> 11.99 | Q12: {=IFERROR(VLOOKUP(Q$3&$A6&$A9,IF({1,0},业绩报告!$A$2:$A$8229&业绩报告!$B$2:$B$8229&业绩报告!$C$2:$C$8229,业绩报告!$I$2:$I$8229),2,0),"")} -> 11.99
B13: 评分 | C13: {=IFERROR(VLOOKUP(C$3&$A6&$A9,IF({1,0},业绩报告!$A$2:$A$8229&业绩报告!$B$2:$B$8229&业绩报告!$C$2:$C$8229,业绩报告!$J$2:$J$8229),2,0),"")} -> 4.4 | D13: {=IFERROR(VLOOKUP(D$3&$A6&$A9,IF({1,0},业绩报告!$A$2:$A$8229&业绩报告!$B$2:$B$8229&业绩报告!$C$2:$C$8229,业绩报告!$J$2:$J$8229),2,0),"")} -> 4.5 | E13: {=IFERROR(VLOOKUP(E$3&$A6&$A9,IF({1,0},业绩报告!$A$2:$A$8229&业绩报告!$B$2:$B$8229&业绩报告!$C$2:$C$8229,业绩报告!$J$2:$J$8229),2,0),"")} -> 4.5 | F13: {=IFERROR(VLOOKUP(F$3&$A6&$A9,IF({1,0},业绩报告!$A$2:$A$8229&业绩报告!$B$2:$B$8229&业绩报告!$C$2:$C$8229,业绩报告!$J$2:$J$8229),2,0),"")} -> 4.4 | G13: {=IFERROR(VLOOKUP(G$3&$A6&$A9,IF({1,0},业绩报告!$A$2:$A$8229&业绩报告!$B$2:$B$8229&业绩报告!$C$2:$C$8229,业绩报告!$J$2:$J$8229),2,0),"")} -> 4.5 | H13: {=IFERROR(VLOOKUP(H$3&$A6&$A9,IF({1,0},业绩报告!$A$2:$A$8229&业绩报告!$B$2:$B$8229&业绩报告!$C$2:$C$8229,业绩报告!$J$2:$J$8229),2,0),"")} -> 4.5 | I13: {=IFERROR(VLOOKUP(I$3&$A6&$A9,IF({1,0},业绩报告!$A$2:$A$8229&业绩报告!$B$2:$B$8229&业绩报告!$C$2:$C$8229,业绩报告!$J$2:$J$8229),2,0),"")} -> 4.5 | J13: =AVERAGE(C13:I13) -> 4.4714286 | K13: {=IFERROR(VLOOKUP(K$3&$A6&$A9,IF({1,0},业绩报告!$A$2:$A$8229&业绩报告!$B$2:$B$8229&业绩报告!$C$2:$C$8229,业绩报告!$J$2:$J$8229),2,0),"")} -> 4.5 | L13: {=IFERROR(VLOOKUP(L$3&$A6&$A9,IF({1,0},业绩报告!$A$2:$A$8229&业绩报告!$B$2:$B$8229&业绩报告!$C$2:$C$8229,业绩报告!$J$2:$J$8229),2,0),"")} -> 4.5 | M13: {=IFERROR(VLOOKUP(M$3&$A6&$A9,IF({1,0},业绩报告!$A$2:$A$8229&业绩报告!$B$2:$B$8229&业绩报告!$C$2:$C$8229,业绩报告!$J$2:$J$8229),2,0),"")} -> 4.5 | N13: {=IFERROR(VLOOKUP(N$3&$A6&$A9,IF({1,0},业绩报告!$A$2:$A$8229&业绩报告!$B$2:$B$8229&业绩报告!$C$2:$C$8229,业绩报告!$J$2:$J$8229),2,0),"")} -> 4.5 | O13: {=IFERROR(VLOOKUP(O$3&$A6&$A9,IF({1,0},业绩报告!$A$2:$A$8229&业绩报告!$B$2:$B$8229&业绩报告!$C$2:$C$8229,业绩报告!$J$2:$J$8229),2,0),"")} -> 4.5 | P13: {=IFERROR(VLOOKUP(P$3&$A6&$A9,IF({1,0},业绩报告!$A$2:$A$8229&业绩报告!$B$2:$B$8229&业绩报告!$C$2:$C$8229,业绩报告!$J$2:$J$8229),2,0),"")} -> 4.4 | Q13: {=IFERROR(VLOOKUP(Q$3&$A6&$A9,IF({1,0},业绩报告!$A$2:$A$8229&业绩报告!$B$2:$B$8229&业绩报告!$C$2:$C$8229,业绩报告!$J$2:$J$8229),2,0),"")} -> 4.5
B14: 评论数 | C14: {=IFERROR(VLOOKUP(C$3&$A6&$A9,IF({1,0},业绩报告!$A$2:$A$8229&业绩报告!$B$2:$B$8229&业绩报告!$C$2:$C$8229,业绩报告!$K$2:$K$8229),2,0),"")} -> 120 | D14: {=IFERROR(VLOOKUP(D$3&$A6&$A9,IF({1,0},业绩报告!$A$2:$A$8229&业绩报告!$B$2:$B$8229&业绩报告!$C$2:$C$8229,业绩报告!$K$2:$K$8229),2,0),"")} -> 122 | E14: {=IFERROR(VLOOKUP(E$3&$A6&$A9,IF({1,0},业绩报告!$A$2:$A$8229&业绩报告!$B$2:$B$8229&业绩报告!$C$2:$C$8229,业绩报告!$K$2:$K$8229),2,0),"")} -> 123 | F14: {=IFERROR(VLOOKUP(F$3&$A6&$A9,IF({1,0},业绩报告!$A$2:$A$8229&业绩报告!$B$2:$B$8229&业绩报告!$C$2:$C$8229,业绩报告!$K$2:$K$8229),2,0),"")} -> 126 | G14: {=IFERROR(VLOOKUP(G$3&$A6&$A9,IF({1,0},业绩报告!$A$2:$A$8229&业绩报告!$B$2:$B$8229&业绩报告!$C$2:$C$8229,业绩报告!$K$2:$K$8229),2,0),"")} -> 132 | H14: {=IFERROR(VLOOKUP(H$3&$A6&$A9,IF({1,0},业绩报告!$A$2:$A$8229&业绩报告!$B$2:$B$8229&业绩报告!$C$2:$C$8229,业绩报告!$K$2:$K$8229),2,0),"")} -> 137 | I14: {=IFERROR(VLOOKUP(I$3&$A6&$A9,IF({1,0},业绩报告!$A$2:$A$8229&业绩报告!$B$2:$B$8229&业绩报告!$C$2:$C$8229,业绩报告!$K$2:$K$8229),2,0),"")} -> 137 | J14: =AVERAGE(C14:I14) -> 128.14286 | K14: {=IFERROR(VLOOKUP(K$3&$A6&$A9,IF({1,0},业绩报告!$A$2:$A$8229&业绩报告!$B$2:$B$8229&业绩报告!$C$2:$C$8229,业绩报告!$K$2:$K$8229),2,0),"")} -> 119 | L14: {=IFERROR(VLOOKUP(L$3&$A6&$A9,IF({1,0},业绩报告!$A$2:$A$8229&业绩报告!$B$2:$B$8229&业绩报告!$C$2:$C$8229,业绩报告!$K$2:$K$8229),2,0),"")} -> 118 | M14: {=IFERROR(VLOOKUP(M$3&$A6&$A9,IF({1,0},业绩报告!$A$2:$A$8229&业绩报告!$B$2:$B$8229&业绩报告!$C$2:$C$8229,业绩报告!$K$2:$K$8229),2,0),"")} -> 118 | N14: {=IFERROR(VLOOKUP(N$3&$A6&$A9,IF({1,0},业绩报告!$A$2:$A$8229&业绩报告!$B$2:$B$8229&业绩报告!$C$2:$C$8229,业绩报告!$K$2:$K$8229),2,0),"")} -> 118 | O14: {=IFERROR(VLOOKUP(O$3&$A6&$A9,IF({1,0},业绩报告!$A$2:$A$8229&业绩报告!$B$2:$B$8229&业绩报告!$C$2:$C$8229,业绩报告!$K$2:$K$8229),2,0),"")} -> 115 | P14: {=IFERROR(VLOOKUP(P$3&$A6&$A9,IF({1,0},业绩报告!$A$2:$A$8229&业绩报告!$B$2:$B$8229&业绩报告!$C$2:$C$8229,业绩报告!$K$2:$K$8229),2,0),"")} -> 113 | Q14: {=IFERROR(VLOOKUP(Q$3&$A6&$A9,IF({1,0},业绩报告!$A$2:$A$8229&业绩报告!$B$2:$B$8229&业绩报告!$C$2:$C$8229,业绩报告!$K$2:$K$8229),2,0),"")} -> 111
B15: 大类 | C15: {=IFERROR(VLOOKUP(C$3&$A6&$A9,IF({1,0},业绩报告!$A$2:$A$8229&业绩报告!$B$2:$B$8229&业绩报告!$C$2:$C$8229,业绩报告!$L$2:$L$8229),2,0),"")} -> Home & Kitchen | D15: {=IFERROR(VLOOKUP(D$3&$A6&$A9,IF({1,0},业绩报告!$A$2:$A$8229&业绩报告!$B$2:$B$8229&业绩报告!$C$2:$C$8229,业绩报告!$L$2:$L$8229),2,0),"")} -> Home & Kitchen | E15: {=IFERROR(VLOOKUP(E$3&$A6&$A9,IF({1,0},业绩报告!$A$2:$A$8229&业绩报告!$B$2:$B$8229&业绩报告!$C$2:$C$8229,业绩报告!$L$2:$L$8229),2,0),"")} -> Home & Kitchen | F15: {=IFERROR(VLOOKUP(F$3&$A6&$A9,IF({1,0},业绩报告!$A$2:$A$8229&业绩报告!$B$2:$B$8229&业绩报告!$C$2:$C$8229,业绩报告!$L$2:$L$8229),2,0),"")} -> Home & Kitchen | G15: {=IFERROR(VLOOKUP(G$3&$A6&$A9,IF({1,0},业绩报告!$A$2:$A$8229&业绩报告!$B$2:$B$8229&业绩报告!$C$2:$C$8229,业绩报告!$L$2:$L$8229),2,0),"")} -> Home & Kitchen | H15: {=IFERROR(VLOOKUP(H$3&$A6&$A9,IF({1,0},业绩报告!$A$2:$A$8229&业绩报告!$B$2:$B$8229&业绩报告!$C$2:$C$8229,业绩报告!$L$2:$L$8229),2,0),"")} -> Home & Kitchen | I15: {=IFERROR(VLOOKUP(I$3&$A6&$A9,IF({1,0},业绩报告!$A$2:$A$8229&业绩报告!$B$2:$B$8229&业绩报告!$C$2:$C$8229,业绩报告!$L$2:$L$8229),2,0),"")} -> Home & Kitchen | K15: {=IFERROR(VLOOKUP(K$3&$A6&$A9,IF({1,0},业绩报告!$A$2:$A$8229&业绩报告!$B$2:$B$8229&业绩报告!$C$2:$C$8229,业绩报告!$L$2:$L$8229),2,0),"")} -> Home & Kitchen | L15: {=IFERROR(VLOOKUP(L$3&$A6&$A9,IF({1,0},业绩报告!$A$2:$A$8229&业绩报告!$B$2:$B$8229&业绩报告!$C$2:$C$8229,业绩报告!$L$2:$L$8229),2,0),"")} -> Home & Kitchen | M15: {=IFERROR(VLOOKUP(M$3&$A6&$A9,IF({1,0},业绩报告!$A$2:$A$8229&业绩报告!$B$2:$B$8229&业绩报告!$C$2:$C$8229,业绩报告!$L$2:$L$8229),2,0),"")} -> Home & Kitchen | N15: {=IFERROR(VLOOKUP(N$3&$A6&$A9,IF({1,0},业绩报告!$A$2:$A$8229&业绩报告!$B$2:$B$8229&业绩报告!$C$2:$C$8229,业绩报告!$L$2:$L$8229),2,0),"")} -> Home & Kitchen | O15: {=IFERROR(VLOOKUP(O$3&$A6&$A9,IF({1,0},业绩报告!$A$2:$A$8229&业绩报告!$B$2:$B$8229&业绩报告!$C$2:$C$8229,业绩报告!$L$2:$L$8229),2,0),"")} -> Home & Kitchen | P15: {=IFERROR(VLOOKUP(P$3&$A6&$A9,IF({1,0},业绩报告!$A$2:$A$8229&业绩报告!$B$2:$B$8229&业绩报告!$C$2:$C$8229,业绩报告!$L$2:$L$8229),2,0),"")} -> Home & Kitchen | Q15: {=IFERROR(VLOOKUP(Q$3&$A6&$A9,IF({1,0},业绩报告!$A$2:$A$8229&业绩报告!$B$2:$B$8229&业绩报告!$C$2:$C$8229,业绩报告!$L$2:$L$8229),2,0),"")} -> Home & Kitchen
B16: 大类排名 | C16: {=IFERROR(VLOOKUP(C$3&$A6&$A9,IF({1,0},业绩报告!$A$2:$A$8229&业绩报告!$B$2:$B$8229&业绩报告!$C$2:$C$8229,业绩报告!$M$2:$M$8229),2,0),"")} -> 24893 | D16: {=IFERROR(VLOOKUP(D$3&$A6&$A9,IF({1,0},业绩报告!$A$2:$A$8229&业绩报告!$B$2:$B$8229&业绩报告!$C$2:$C$8229,业绩报告!$M$2:$M$8229),2,0),"")} -> 28,871 | E16: {=IFERROR(VLOOKUP(E$3&$A6&$A9,IF({1,0},业绩报告!$A$2:$A$8229&业绩报告!$B$2:$B$8229&业绩报告!$C$2:$C$8229,业绩报告!$M$2:$M$8229),2,0),"")} -> 35,650 | F16: {=IFERROR(VLOOKUP(F$3&$A6&$A9,IF({1,0},业绩报告!$A$2:$A$8229&业绩报告!$B$2:$B$8229&业绩报告!$C$2:$C$8229,业绩报告!$M$2:$M$8229),2,0),"")} -> 37,224 | G16: {=IFERROR(VLOOKUP(G$3&$A6&$A9,IF({1,0},业绩报告!$A$2:$A$8229&业绩报告!$B$2:$B$8229&业绩报告!$C$2:$C$8229,业绩报告!$M$2:$M$8229),2,0),"")} -> 27283 | H16: {=IFERROR(VLOOKUP(H$3&$A6&$A9,IF({1,0},业绩报告!$A$2:$A$8229&业绩报告!$B$2:$B$8229&业绩报告!$C$2:$C$8229,业绩报告!$M$2:$M$8229),2,0),"")} -> 28347 | I16: {=IFERROR(VLOOKUP(I$3&$A6&$A9,IF({1,0},业绩报告!$A$2:$A$8229&业绩报告!$B$2:$B$8229&业绩报告!$C$2:$C$8229,业绩报告!$M$2:$M$8229),2,0),"")} -> 27877 | J16: =AVERAGE(C16:I16) -> #DIV/0! | K16: {=IFERROR(VLOOKUP(K$3&$A6&$A9,IF({1,0},业绩报告!$A$2:$A$8229&业绩报告!$B$2:$B$8229&业绩报告!$C$2:$C$8229,业绩报告!$M$2:$M$8229),2,0),"")} -> 25634 | L16: {=IFERROR(VLOOKUP(L$3&$A6&$A9,IF({1,0},业绩报告!$A$2:$A$8229&业绩报告!$B$2:$B$8229&业绩报告!$C$2:$C$8229,业绩报告!$M$2:$M$8229),2,0),"")} -> 29860 | M16: {=IFERROR(VLOOKUP(M$3&$A6&$A9,IF({1,0},业绩报告!$A$2:$A$8229&业绩报告!$B$2:$B$8229&业绩报告!$C$2:$C$8229,业绩报告!$M$2:$M$8229),2,0),"")} -> 25653 | N16: {=IFERROR(VLOOKUP(N$3&$A6&$A9,IF({1,0},业绩报告!$A$2:$A$8229&业绩报告!$B$2:$B$8229&业绩报告!$C$2:$C$8229,业绩报告!$M$2:$M$8229),2,0),"")} -> 30720 | O16: {=IFERROR(VLOOKUP(O$3&$A6&$A9,IF({1,0},业绩报告!$A$2:$A$8229&业绩报告!$B$2:$B$8229&业绩报告!$C$2:$C$8229,业绩报告!$M$2:$M$8229),2,0),"")} -> 36802 | P16: {=IFERROR(VLOOKUP(P$3&$A6&$A9,IF({1,0},业绩报告!$A$2:$A$8229&业绩报告!$B$2:$B$8229&业绩报告!$C$2:$C$8229,业绩报告!$M$2:$M$8229),2,0),"")} -> 36727 | Q16: {=IFERROR(VLOOKUP(Q$3&$A6&$A9,IF({1,0},业绩报告!$A$2:$A$8229&业绩报告!$B$2:$B$8229&业绩报告!$C$2:$C$8229,业绩报告!$M$2:$M$8229),2,0),"")} -> 37166 | R16: =AVERAGE(K16:Q16) -> 25643.5
B17: 小类 | C17: {=IFERROR(VLOOKUP(C$3&$A6&$A9,IF({1,0},业绩报告!$A$2:$A$8229&业绩报告!$B$2:$B$8229&业绩报告!$C$2:$C$8229,业绩报告!$N$2:$N$8229),2,0),"")} -> Bathroom Countertop Soap Dispensers | D17: {=IFERROR(VLOOKUP(D$3&$A6&$A9,IF({1,0},业绩报告!$A$2:$A$8229&业绩报告!$B$2:$B$8229&业绩报告!$C$2:$C$8229,业绩报告!$N$2:$N$8229),2,0),"")} -> Bathroom Countertop Soap Dispensers | E17: {=IFERROR(VLOOKUP(E$3&$A6&$A9,IF({1,0},业绩报告!$A$2:$A$8229&业绩报告!$B$2:$B$8229&业绩报告!$C$2:$C$8229,业绩报告!$N$2:$N$8229),2,0),"")} -> Bathroom Countertop Soap Dispensers | F17: {=IFERROR(VLOOKUP(F$3&$A6&$A9,IF({1,0},业绩报告!$A$2:$A$8229&业绩报告!$B$2:$B$8229&业绩报告!$C$2:$C$8229,业绩报告!$N$2:$N$8229),2,0),"")} -> Bathroom Countertop Soap Dispensers | G17: {=IFERROR(VLOOKUP(G$3&$A6&$A9,IF({1,0},业绩报告!$A$2:$A$8229&业绩报告!$B$2:$B$8229&业绩报告!$C$2:$C$8229,业绩报告!$N$2:$N$8229),2,0),"")} -> Bathroom Countertop Soap Dispensers | H17: {=IFERROR(VLOOKUP(H$3&$A6&$A9,IF({1,0},业绩报告!$A$2:$A$8229&业绩报告!$B$2:$B$8229&业绩报告!$C$2:$C$8229,业绩报告!$N$2:$N$8229),2,0),"")} -> Bathroom Countertop Soap Dispensers | I17: {=IFERROR(VLOOKUP(I$3&$A6&$A9,IF({1,0},业绩报告!$A$2:$A$8229&业绩报告!$B$2:$B$8229&业绩报告!$C$2:$C$8229,业绩报告!$N$2:$N$8229),2,0),"")} -> Bathroom Countertop Soap Dispensers | K17: {=IFERROR(VLOOKUP(K$3&$A6&$A9,IF({1,0},业绩报告!$A$2:$A$8229&业绩报告!$B$2:$B$8229&业绩报告!$C$2:$C$8229,业绩报告!$N$2:$N$8229),2,0),"")} -> Bathroom Countertop Soap Dispensers | L17: {=IFERROR(VLOOKUP(L$3&$A6&$A9,IF({1,0},业绩报告!$A$2:$A$8229&业绩报告!$B$2:$B$8229&业绩报告!$C$2:$C$8229,业绩报告!$N$2:$N$8229),2,0),"")} -> Bathroom Countertop Soap Dispensers | M17: {=IFERROR(VLOOKUP(M$3&$A6&$A9,IF({1,0},业绩报告!$A$2:$A$8229&业绩报告!$B$2:$B$8229&业绩报告!$C$2:$C$8229,业绩报告!$N$2:$N$8229),2,0),"")} -> Bathroom Countertop Soap Dispensers | N17: {=IFERROR(VLOOKUP(N$3&$A6&$A9,IF({1,0},业绩报告!$A$2:$A$8229&业绩报告!$B$2:$B$8229&业绩报告!$C$2:$C$8229,业绩报告!$N$2:$N$8229),2,0),"")} -> Bathroom Countertop Soap Dispensers | O17: {=IFERROR(VLOOKUP(O$3&$A6&$A9,IF({1,0},业绩报告!$A$2:$A$8229&业绩报告!$B$2:$B$8229&业绩报告!$C$2:$C$8229,业绩报告!$N$2:$N$8229),2,0),"")} -> Bathroom Countertop Soap Dispensers | P17: {=IFERROR(VLOOKUP(P$3&$A6&$A9,IF({1,0},业绩报告!$A$2:$A$8229&业绩报告!$B$2:$B$8229&业绩报告!$C$2:$C$8229,业绩报告!$N$2:$N$8229),2,0),"")} -> Bathroom Countertop Soap Dispensers | Q17: {=IFERROR(VLOOKUP(Q$3&$A6&$A9,IF({1,0},业绩报告!$A$2:$A$8229&业绩报告!$B$2:$B$8229&业绩报告!$C$2:$C$8229,业绩报告!$N$2:$N$8229),2,0),"")} -> Bathroom Countertop Soap Dispensers
B18: 小类排名 | C18: {=IFERROR(VLOOKUP(C$3&$A6&$A9,IF({1,0},业绩报告!$A$2:$A$8229&业绩报告!$B$2:$B$8229&业绩报告!$C$2:$C$8229,业绩报告!$O$2:$O$8229),2,0),"")} -> 67 | D18: {=IFERROR(VLOOKUP(D$3&$A6&$A9,IF({1,0},业绩报告!$A$2:$A$8229&业绩报告!$B$2:$B$8229&业绩报告!$C$2:$C$8229,业绩报告!$O$2:$O$8229),2,0),"")} -> 80 | E18: {=IFERROR(VLOOKUP(E$3&$A6&$A9,IF({1,0},业绩报告!$A$2:$A$8229&业绩报告!$B$2:$B$8229&业绩报告!$C$2:$C$8229,业绩报告!$O$2:$O$8229),2,0),"")} -> 98 | F18: {=IFERROR(VLOOKUP(F$3&$A6&$A9,IF({1,0},业绩报告!$A$2:$A$8229&业绩报告!$B$2:$B$8229&业绩报告!$C$2:$C$8229,业绩报告!$O$2:$O$8229),2,0),"")} -> 99 | G18: {=IFERROR(VLOOKUP(G$3&$A6&$A9,IF({1,0},业绩报告!$A$2:$A$8229&业绩报告!$B$2:$B$8229&业绩报告!$C$2:$C$8229,业绩报告!$O$2:$O$8229),2,0),"")} -> 76 | H18: {=IFERROR(VLOOKUP(H$3&$A6&$A9,IF({1,0},业绩报告!$A$2:$A$8229&业绩报告!$B$2:$B$8229&业绩报告!$C$2:$C$8229,业绩报告!$O$2:$O$8229),2,0),"")} -> 81 | I18: {=IFERROR(VLOOKUP(I$3&$A6&$A9,IF({1,0},业绩报告!$A$2:$A$8229&业绩报告!$B$2:$B$8229&业绩报告!$C$2:$C$8229,业绩报告!$O$2:$O$8229),2,0),"")} -> 76 | J18: =AVERAGE(C18:I18) -> 82.428571 | K18: {=IFERROR(VLOOKUP(K$3&$A6&$A9,IF({1,0},业绩报告!$A$2:$A$8229&业绩报告!$B$2:$B$8229&业绩报告!$C$2:$C$8229,业绩报告!$O$2:$O$8229),2,0),"")} -> 77 | L18: {=IFERROR(VLOOKUP(L$3&$A6&$A9,IF({1,0},业绩报告!$A$2:$A$8229&业绩报告!$B$2:$B$8229&业绩报告!$C$2:$C$8229,业绩报告!$O$2:$O$8229),2,0),"")} -> 82 | M18: {=IFERROR(VLOOKUP(M$3&$A6&$A9,IF({1,0},业绩报告!$A$2:$A$8229&业绩报告!$B$2:$B$8229&业绩报告!$C$2:$C$8229,业绩报告!$O$2:$O$8229),2,0),"")} -> 73 | N18: {=IFERROR(VLOOKUP(N$3&$A6&$A9,IF({1,0},业绩报告!$A$2:$A$8229&业绩报告!$B$2:$B$8229&业绩报告!$C$2:$C$8229,业绩报告!$O$2:$O$8229),2,0),"")} -> 83 | O18: {=IFERROR(VLOOKUP(O$3&$A6&$A9,IF({1,0},业绩报告!$A$2:$A$8229&业绩报告!$B$2:$B$8229&业绩报告!$C$2:$C$8229,业绩报告!$O$2:$O$8229),2,0),"")} -> 97 | P18: {=IFERROR(VLOOKUP(P$3&$A6&$A9,IF({1,0},业绩报告!$A$2:$A$8229&业绩报告!$B$2:$B$8229&业绩报告!$C$2:$C$8229,业绩报告!$O$2:$O$8229),2,0),"")} -> 102 | Q18: {=IFERROR(VLOOKUP(Q$3&$A6&$A9,IF({1,0},业绩报告!$A$2:$A$8229&业绩报告!$B$2:$B$8229&业绩报告!$C$2:$C$8229,业绩报告!$O$2:$O$8229),2,0),"")} -> 110
B19: 关键词1 | C19: {=IFERROR(VLOOKUP(C$3&$A6&$A9,IF({1,0},业绩报告!$A$2:$A$8229&业绩报告!$B$2:$B$8229&业绩报告!$C$2:$C$8229,业绩报告!$P$2:$P$8229),2,0),"")} -> 0 | D19: {=IFERROR(VLOOKUP(D$3&$A6&$A9,IF({1,0},业绩报告!$A$2:$A$8229&业绩报告!$B$2:$B$8229&业绩报告!$C$2:$C$8229,业绩报告!$P$2:$P$8229),2,0),"")} -> 0 | E19: {=IFERROR(VLOOKUP(E$3&$A6&$A9,IF({1,0},业绩报告!$A$2:$A$8229&业绩报告!$B$2:$B$8229&业绩报告!$C$2:$C$8229,业绩报告!$P$2:$P$8229),2,0),"")} -> 0 | F19: {=IFERROR(VLOOKUP(F$3&$A6&$A9,IF({1,0},业绩报告!$A$2:$A$8229&业绩报告!$B$2:$B$8229&业绩报告!$C$2:$C$8229,业绩报告!$P$2:$P$8229),2,0),"")} -> 0 | G19: {=IFERROR(VLOOKUP(G$3&$A6&$A9,IF({1,0},业绩报告!$A$2:$A$8229&业绩报告!$B$2:$B$8229&业绩报告!$C$2:$C$8229,业绩报告!$P$2:$P$8229),2,0),"")} -> 0 | H19: {=IFERROR(VLOOKUP(H$3&$A6&$A9,IF({1,0},业绩报告!$A$2:$A$8229&业绩报告!$B$2:$B$8229&业绩报告!$C$2:$C$8229,业绩报告!$P$2:$P$8229),2,0),"")} -> 0 | I19: {=IFERROR(VLOOKUP(I$3&$A6&$A9,IF({1,0},业绩报告!$A$2:$A$8229&业绩报告!$B$2:$B$8229&业绩报告!$C$2:$C$8229,业绩报告!$P$2:$P$8229),2,0),"")} -> 0 | K19: {=IFERROR(VLOOKUP(K$3&$A6&$A9,IF({1,0},业绩报告!$A$2:$A$8229&业绩报告!$B$2:$B$8229&业绩报告!$C$2:$C$8229,业绩报告!$P$2:$P$8229),2,0),"")} -> 0 | L19: {=IFERROR(VLOOKUP(L$3&$A6&$A9,IF({1,0},业绩报告!$A$2:$A$8229&业绩报告!$B$2:$B$8229&业绩报告!$C$2:$C$8229,业绩报告!$P$2:$P$8229),2,0),"")} -> 0 | M19: {=IFERROR(VLOOKUP(M$3&$A6&$A9,IF({1,0},业绩报告!$A$2:$A$8229&业绩报告!$B$2:$B$8229&业绩报告!$C$2:$C$8229,业绩报告!$P$2:$P$8229),2,0),"")} -> 0 | N19: {=IFERROR(VLOOKUP(N$3&$A6&$A9,IF({1,0},业绩报告!$A$2:$A$8229&业绩报告!$B$2:$B$8229&业绩报告!$C$2:$C$8229,业绩报告!$P$2:$P$8229),2,0),"")} -> 0 | O19: {=IFERROR(VLOOKUP(O$3&$A6&$A9,IF({1,0},业绩报告!$A$2:$A$8229&业绩报告!$B$2:$B$8229&业绩报告!$C$2:$C$8229,业绩报告!$P$2:$P$8229),2,0),"")} -> 0 | P19: {=IFERROR(VLOOKUP(P$3&$A6&$A9,IF({1,0},业绩报告!$A$2:$A$8229&业绩报告!$B$2:$B$8229&业绩报告!$C$2:$C$8229,业绩报告!$P$2:$P$8229),2,0),"")} -> 0 | Q19: {=IFERROR(VLOOKUP(Q$3&$A6&$A9,IF({1,0},业绩报告!$A$2:$A$8229&业绩报告!$B$2:$B$8229&业绩报告!$C$2:$C$8229,业绩报告!$P$2:$P$8229),2,0),"")} -> 0
B20: 自然位1 | C20: {=IFERROR(VLOOKUP(C$3&$A6&$A9,IF({1,0},业绩报告!$A$2:$A$8229&业绩报告!$B$2:$B$8229&业绩报告!$C$2:$C$8229,业绩报告!$Q$2:$Q$8229),2,0),"")} -> 0 | D20: {=IFERROR(VLOOKUP(D$3&$A6&$A9,IF({1,0},业绩报告!$A$2:$A$8229&业绩报告!$B$2:$B$8229&业绩报告!$C$2:$C$8229,业绩报告!$Q$2:$Q$8229),2,0),"")} -> 0 | E20: {=IFERROR(VLOOKUP(E$3&$A6&$A9,IF({1,0},业绩报告!$A$2:$A$8229&业绩报告!$B$2:$B$8229&业绩报告!$C$2:$C$8229,业绩报告!$Q$2:$Q$8229),2,0),"")} -> 0 | F20: {=IFERROR(VLOOKUP(F$3&$A6&$A9,IF({1,0},业绩报告!$A$2:$A$8229&业绩报告!$B$2:$B$8229&业绩报告!$C$2:$C$8229,业绩报告!$Q$2:$Q$8229),2,0),"")} -> 0 | G20: {=IFERROR(VLOOKUP(G$3&$A6&$A9,IF({1,0},业绩报告!$A$2:$A$8229&业绩报告!$B$2:$B$8229&业绩报告!$C$2:$C$8229,业绩报告!$Q$2:$Q$8229),2,0),"")} -> 0 | H20: {=IFERROR(VLOOKUP(H$3&$A6&$A9,IF({1,0},业绩报告!$A$2:$A$8229&业绩报告!$B$2:$B$8229&业绩报告!$C$2:$C$8229,业绩报告!$Q$2:$Q$8229),2,0),"")} -> 0 | I20: {=IFERROR(VLOOKUP(I$3&$A6&$A9,IF({1,0},业绩报告!$A$2:$A$8229&业绩报告!$B$2:$B$8229&业绩报告!$C$2:$C$8229,业绩报告!$Q$2:$Q$8229),2,0),"")} -> 0 | K20: {=IFERROR(VLOOKUP(K$3&$A6&$A9,IF({1,0},业绩报告!$A$2:$A$8229&业绩报告!$B$2:$B$8229&业绩报告!$C$2:$C$8229,业绩报告!$Q$2:$Q$8229),2,0),"")} -> 0 | L20: {=IFERROR(VLOOKUP(L$3&$A6&$A9,IF({1,0},业绩报告!$A$2:$A$8229&业绩报告!$B$2:$B$8229&业绩报告!$C$2:$C$8229,业绩报告!$Q$2:$Q$8229),2,0),"")} -> 0 | M20: {=IFERROR(VLOOKUP(M$3&$A6&$A9,IF({1,0},业绩报告!$A$2:$A$8229&业绩报告!$B$2:$B$8229&业绩报告!$C$2:$C$8229,业绩报告!$Q$2:$Q$8229),2,0),"")} -> 0 | N20: {=IFERROR(VLOOKUP(N$3&$A6&$A9,IF({1,0},业绩报告!$A$2:$A$8229&业绩报告!$B$2:$B$8229&业绩报告!$C$2:$C$8229,业绩报告!$Q$2:$Q$8229),2,0),"")} -> 0 | O20: {=IFERROR(VLOOKUP(O$3&$A6&$A9,IF({1,0},业绩报告!$A$2:$A$8229&业绩报告!$B$2:$B$8229&业绩报告!$C$2:$C$8229,业绩报告!$Q$2:$Q$8229),2,0),"")} -> 0 | P20: {=IFERROR(VLOOKUP(P$3&$A6&$A9,IF({1,0},业绩报告!$A$2:$A$8229&业绩报告!$B$2:$B$8229&业绩报告!$C$2:$C$8229,业绩报告!$Q$2:$Q$8229),2,0),"")} -> 0 | Q20: {=IFERROR(VLOOKUP(Q$3&$A6&$A9,IF({1,0},业绩报告!$A$2:$A$8229&业绩报告!$B$2:$B$8229&业绩报告!$C$2:$C$8229,业绩报告!$Q$2:$Q$8229),2,0),"")} -> 0
B21: 广告位1 | C21: {=IFERROR(VLOOKUP(C$3&$A6&$A9,IF({1,0},业绩报告!$A$2:$A$8229&业绩报告!$B$2:$B$8229&业绩报告!$C$2:$C$8229,业绩报告!$R$2:$R$8229),2,0),"")} -> 0 | D21: {=IFERROR(VLOOKUP(D$3&$A6&$A9,IF({1,0},业绩报告!$A$2:$A$8229&业绩报告!$B$2:$B$8229&业绩报告!$C$2:$C$8229,业绩报告!$R$2:$R$8229),2,0),"")} -> 0 | E21: {=IFERROR(VLOOKUP(E$3&$A6&$A9,IF({1,0},业绩报告!$A$2:$A$8229&业绩报告!$B$2:$B$8229&业绩报告!$C$2:$C$8229,业绩报告!$R$2:$R$8229),2,0),"")} -> 0 | F21: {=IFERROR(VLOOKUP(F$3&$A6&$A9,IF({1,0},业绩报告!$A$2:$A$8229&业绩报告!$B$2:$B$8229&业绩报告!$C$2:$C$8229,业绩报告!$R$2:$R$8229),2,0),"")} -> 0 | G21: {=IFERROR(VLOOKUP(G$3&$A6&$A9,IF({1,0},业绩报告!$A$2:$A$8229&业绩报告!$B$2:$B$8229&业绩报告!$C$2:$C$8229,业绩报告!$R$2:$R$8229),2,0),"")} -> 0 | H21: {=IFERROR(VLOOKUP(H$3&$A6&$A9,IF({1,0},业绩报告!$A$2:$A$8229&业绩报告!$B$2:$B$8229&业绩报告!$C$2:$C$8229,业绩报告!$R$2:$R$8229),2,0),"")} -> 0 | I21: {=IFERROR(VLOOKUP(I$3&$A6&$A9,IF({1,0},业绩报告!$A$2:$A$8229&业绩报告!$B$2:$B$8229&业绩报告!$C$2:$C$8229,业绩报告!$R$2:$R$8229),2,0),"")} -> 0 | K21: {=IFERROR(VLOOKUP(K$3&$A6&$A9,IF({1,0},业绩报告!$A$2:$A$8229&业绩报告!$B$2:$B$8229&业绩报告!$C$2:$C$8229,业绩报告!$R$2:$R$8229),2,0),"")} -> 0 | L21: {=IFERROR(VLOOKUP(L$3&$A6&$A9,IF({1,0},业绩报告!$A$2:$A$8229&业绩报告!$B$2:$B$8229&业绩报告!$C$2:$C$8229,业绩报告!$R$2:$R$8229),2,0),"")} -> 0 | M21: {=IFERROR(VLOOKUP(M$3&$A6&$A9,IF({1,0},业绩报告!$A$2:$A$8229&业绩报告!$B$2:$B$8229&业绩报告!$C$2:$C$8229,业绩报告!$R$2:$R$8229),2,0),"")} -> 0 | N21: {=IFERROR(VLOOKUP(N$3&$A6&$A9,IF({1,0},业绩报告!$A$2:$A$8229&业绩报告!$B$2:$B$8229&业绩报告!$C$2:$C$8229,业绩报告!$R$2:$R$8229),2,0),"")} -> 0 | O21: {=IFERROR(VLOOKUP(O$3&$A6&$A9,IF({1,0},业绩报告!$A$2:$A$8229&业绩报告!$B$2:$B$8229&业绩报告!$C$2:$C$8229,业绩报告!$R$2:$R$8229),2,0),"")} -> 0 | P21: {=IFERROR(VLOOKUP(P$3&$A6&$A9,IF({1,0},业绩报告!$A$2:$A$8229&业绩报告!$B$2:$B$8229&业绩报告!$C$2:$C$8229,业绩报告!$R$2:$R$8229),2,0),"")} -> 0 | Q21: {=IFERROR(VLOOKUP(Q$3&$A6&$A9,IF({1,0},业绩报告!$A$2:$A$8229&业绩报告!$B$2:$B$8229&业绩报告!$C$2:$C$8229,业绩报告!$R$2:$R$8229),2,0),"")} -> 0
B22: 关键词2 | C22: {=IFERROR(VLOOKUP(C$3&$A6&$A9,IF({1,0},业绩报告!$A$2:$A$8229&业绩报告!$B$2:$B$8229&业绩报告!$C$2:$C$8229,业绩报告!$S$2:$S$8229),2,0),"")} -> 0 | D22: {=IFERROR(VLOOKUP(D$3&$A6&$A9,IF({1,0},业绩报告!$A$2:$A$8229&业绩报告!$B$2:$B$8229&业绩报告!$C$2:$C$8229,业绩报告!$S$2:$S$8229),2,0),"")} -> 0 | E22: {=IFERROR(VLOOKUP(E$3&$A6&$A9,IF({1,0},业绩报告!$A$2:$A$8229&业绩报告!$B$2:$B$8229&业绩报告!$C$2:$C$8229,业绩报告!$S$2:$S$8229),2,0),"")} -> 0 | F22: {=IFERROR(VLOOKUP(F$3&$A6&$A9,IF({1,0},业绩报告!$A$2:$A$8229&业绩报告!$B$2:$B$8229&业绩报告!$C$2:$C$8229,业绩报告!$S$2:$S$8229),2,0),"")} -> 0 | G22: {=IFERROR(VLOOKUP(G$3&$A6&$A9,IF({1,0},业绩报告!$A$2:$A$8229&业绩报告!$B$2:$B$8229&业绩报告!$C$2:$C$8229,业绩报告!$S$2:$S$8229),2,0),"")} -> 0 | H22: {=IFERROR(VLOOKUP(H$3&$A6&$A9,IF({1,0},业绩报告!$A$2:$A$8229&业绩报告!$B$2:$B$8229&业绩报告!$C$2:$C$8229,业绩报告!$S$2:$S$8229),2,0),"")} -> 0 | I22: {=IFERROR(VLOOKUP(I$3&$A6&$A9,IF({1,0},业绩报告!$A$2:$A$8229&业绩报告!$B$2:$B$8229&业绩报告!$C$2:$C$8229,业绩报告!$S$2:$S$8229),2,0),"")} -> 0 | K22: {=IFERROR(VLOOKUP(K$3&$A6&$A9,IF({1,0},业绩报告!$A$2:$A$8229&业绩报告!$B$2:$B$8229&业绩报告!$C$2:$C$8229,业绩报告!$S$2:$S$8229),2,0),"")} -> 0 | L22: {=IFERROR(VLOOKUP(L$3&$A6&$A9,IF({1,0},业绩报告!$A$2:$A$8229&业绩报告!$B$2:$B$8229&业绩报告!$C$2:$C$8229,业绩报告!$S$2:$S$8229),2,0),"")} -> 0 | M22: {=IFERROR(VLOOKUP(M$3&$A6&$A9,IF({1,0},业绩报告!$A$2:$A$8229&业绩报告!$B$2:$B$8229&业绩报告!$C$2:$C$8229,业绩报告!$S$2:$S$8229),2,0),"")} -> 0 | N22: {=IFERROR(VLOOKUP(N$3&$A6&$A9,IF({1,0},业绩报告!$A$2:$A$8229&业绩报告!$B$2:$B$8229&业绩报告!$C$2:$C$8229,业绩报告!$S$2:$S$8229),2,0),"")} -> 0 | O22: {=IFERROR(VLOOKUP(O$3&$A6&$A9,IF({1,0},业绩报告!$A$2:$A$8229&业绩报告!$B$2:$B$8229&业绩报告!$C$2:$C$8229,业绩报告!$S$2:$S$8229),2,0),"")} -> 0 | P22: {=IFERROR(VLOOKUP(P$3&$A6&$A9,IF({1,0},业绩报告!$A$2:$A$8229&业绩报告!$B$2:$B$8229&业绩报告!$C$2:$C$8229,业绩报告!$S$2:$S$8229),2,0),"")} -> 0 | Q22: {=IFERROR(VLOOKUP(Q$3&$A6&$A9,IF({1,0},业绩报告!$A$2:$A$8229&业绩报告!$B$2:$B$8229&业绩报告!$C$2:$C$8229,业绩报告!$S$2:$S$8229),2,0),"")} -> 0
B23: 自然位2 | C23: {=IFERROR(VLOOKUP(C$3&$A6&$A9,IF({1,0},业绩报告!$A$2:$A$8229&业绩报告!$B$2:$B$8229&业绩报告!$C$2:$C$8229,业绩报告!$T$2:$T$8229),2,0),"")} -> 0 | D23: {=IFERROR(VLOOKUP(D$3&$A6&$A9,IF({1,0},业绩报告!$A$2:$A$8229&业绩报告!$B$2:$B$8229&业绩报告!$C$2:$C$8229,业绩报告!$T$2:$T$8229),2,0),"")} -> 0 | E23: {=IFERROR(VLOOKUP(E$3&$A6&$A9,IF({1,0},业绩报告!$A$2:$A$8229&业绩报告!$B$2:$B$8229&业绩报告!$C$2:$C$8229,业绩报告!$T$2:$T$8229),2,0),"")} -> 0 | F23: {=IFERROR(VLOOKUP(F$3&$A6&$A9,IF({1,0},业绩报告!$A$2:$A$8229&业绩报告!$B$2:$B$8229&业绩报告!$C$2:$C$8229,业绩报告!$T$2:$T$8229),2,0),"")} -> 0 | G23: {=IFERROR(VLOOKUP(G$3&$A6&$A9,IF({1,0},业绩报告!$A$2:$A$8229&业绩报告!$B$2:$B$8229&业绩报告!$C$2:$C$8229,业绩报告!$T$2:$T$8229),2,0),"")} -> 0 | H23: {=IFERROR(VLOOKUP(H$3&$A6&$A9,IF({1,0},业绩报告!$A$2:$A$8229&业绩报告!$B$2:$B$8229&业绩报告!$C$2:$C$8229,业绩报告!$T$2:$T$8229),2,0),"")} -> 0 | I23: {=IFERROR(VLOOKUP(I$3&$A6&$A9,IF({1,0},业绩报告!$A$2:$A$8229&业绩报告!$B$2:$B$8229&业绩报告!$C$2:$C$8229,业绩报告!$T$2:$T$8229),2,0),"")} -> 0 | K23: {=IFERROR(VLOOKUP(K$3&$A6&$A9,IF({1,0},业绩报告!$A$2:$A$8229&业绩报告!$B$2:$B$8229&业绩报告!$C$2:$C$8229,业绩报告!$T$2:$T$8229),2,0),"")} -> 0 | L23: {=IFERROR(VLOOKUP(L$3&$A6&$A9,IF({1,0},业绩报告!$A$2:$A$8229&业绩报告!$B$2:$B$8229&业绩报告!$C$2:$C$8229,业绩报告!$T$2:$T$8229),2,0),"")} -> 0 | M23: {=IFERROR(VLOOKUP(M$3&$A6&$A9,IF({1,0},业绩报告!$A$2:$A$8229&业绩报告!$B$2:$B$8229&业绩报告!$C$2:$C$8229,业绩报告!$T$2:$T$8229),2,0),"")} -> 0 | N23: {=IFERROR(VLOOKUP(N$3&$A6&$A9,IF({1,0},业绩报告!$A$2:$A$8229&业绩报告!$B$2:$B$8229&业绩报告!$C$2:$C$8229,业绩报告!$T$2:$T$8229),2,0),"")} -> 0 | O23: {=IFERROR(VLOOKUP(O$3&$A6&$A9,IF({1,0},业绩报告!$A$2:$A$8229&业绩报告!$B$2:$B$8229&业绩报告!$C$2:$C$8229,业绩报告!$T$2:$T$8229),2,0),"")} -> 0 | P23: {=IFERROR(VLOOKUP(P$3&$A6&$A9,IF({1,0},业绩报告!$A$2:$A$8229&业绩报告!$B$2:$B$8229&业绩报告!$C$2:$C$8229,业绩报告!$T$2:$T$8229),2,0),"")} -> 0 | Q23: {=IFERROR(VLOOKUP(Q$3&$A6&$A9,IF({1,0},业绩报告!$A$2:$A$8229&业绩报告!$B$2:$B$8229&业绩报告!$C$2:$C$8229,业绩报告!$T$2:$T$8229),2,0),"")} -> 0
B24: 广告位2 | C24: {=IFERROR(VLOOKUP(C$3&$A6&$A9,IF({1,0},业绩报告!$A$2:$A$8229&业绩报告!$B$2:$B$8229&业绩报告!$C$2:$C$8229,业绩报告!$U$2:$U$8229),2,0),"")} -> 0 | D24: {=IFERROR(VLOOKUP(D$3&$A6&$A9,IF({1,0},业绩报告!$A$2:$A$8229&业绩报告!$B$2:$B$8229&业绩报告!$C$2:$C$8229,业绩报告!$U$2:$U$8229),2,0),"")} -> 0 | E24: {=IFERROR(VLOOKUP(E$3&$A6&$A9,IF({1,0},业绩报告!$A$2:$A$8229&业绩报告!$B$2:$B$8229&业绩报告!$C$2:$C$8229,业绩报告!$U$2:$U$8229),2,0),"")} -> 0 | F24: {=IFERROR(VLOOKUP(F$3&$A6&$A9,IF({1,0},业绩报告!$A$2:$A$8229&业绩报告!$B$2:$B$8229&业绩报告!$C$2:$C$8229,业绩报告!$U$2:$U$8229),2,0),"")} -> 0 | G24: {=IFERROR(VLOOKUP(G$3&$A6&$A9,IF({1,0},业绩报告!$A$2:$A$8229&业绩报告!$B$2:$B$8229&业绩报告!$C$2:$C$8229,业绩报告!$U$2:$U$8229),2,0),"")} -> 0 | H24: {=IFERROR(VLOOKUP(H$3&$A6&$A9,IF({1,0},业绩报告!$A$2:$A$8229&业绩报告!$B$2:$B$8229&业绩报告!$C$2:$C$8229,业绩报告!$U$2:$U$8229),2,0),"")} -> 0 | I24: {=IFERROR(VLOOKUP(I$3&$A6&$A9,IF({1,0},业绩报告!$A$2:$A$8229&业绩报告!$B$2:$B$8229&业绩报告!$C$2:$C$8229,业绩报告!$U$2:$U$8229),2,0),"")} -> 0 | K24: {=IFERROR(VLOOKUP(K$3&$A6&$A9,IF({1,0},业绩报告!$A$2:$A$8229&业绩报告!$B$2:$B$8229&业绩报告!$C$2:$C$8229,业绩报告!$U$2:$U$8229),2,0),"")} -> 0 | L24: {=IFERROR(VLOOKUP(L$3&$A6&$A9,IF({1,0},业绩报告!$A$2:$A$8229&业绩报告!$B$2:$B$8229&业绩报告!$C$2:$C$8229,业绩报告!$U$2:$U$8229),2,0),"")} -> 0 | M24: {=IFERROR(VLOOKUP(M$3&$A6&$A9,IF({1,0},业绩报告!$A$2:$A$8229&业绩报告!$B$2:$B$8229&业绩报告!$C$2:$C$8229,业绩报告!$U$2:$U$8229),2,0),"")} -> 0 | N24: {=IFERROR(VLOOKUP(N$3&$A6&$A9,IF({1,0},业绩报告!$A$2:$A$8229&业绩报告!$B$2:$B$8229&业绩报告!$C$2:$C$8229,业绩报告!$U$2:$U$8229),2,0),"")} -> 0 | O24: {=IFERROR(VLOOKUP(O$3&$A6&$A9,IF({1,0},业绩报告!$A$2:$A$8229&业绩报告!$B$2:$B$8229&业绩报告!$C$2:$C$8229,业绩报告!$U$2:$U$8229),2,0),"")} -> 0 | P24: {=IFERROR(VLOOKUP(P$3&$A6&$A9,IF({1,0},业绩报告!$A$2:$A$8229&业绩报告!$B$2:$B$8229&业绩报告!$C$2:$C$8229,业绩报告!$U$2:$U$8229),2,0),"")} -> 0 | Q24: {=IFERROR(VLOOKUP(Q$3&$A6&$A9,IF({1,0},业绩报告!$A$2:$A$8229&业绩报告!$B$2:$B$8229&业绩报告!$C$2:$C$8229,业绩报告!$U$2:$U$8229),2,0),"")} -> 0
B25: 关键词3 | C25: {=IFERROR(VLOOKUP(C$3&$A6&$A9,IF({1,0},业绩报告!$A$2:$A$8229&业绩报告!$B$2:$B$8229&业绩报告!$C$2:$C$8229,业绩报告!$V$2:$V$8229),2,0),"")} -> 0 | D25: {=IFERROR(VLOOKUP(D$3&$A6&$A9,IF({1,0},业绩报告!$A$2:$A$8229&业绩报告!$B$2:$B$8229&业绩报告!$C$2:$C$8229,业绩报告!$V$2:$V$8229),2,0),"")} -> 0 | E25: {=IFERROR(VLOOKUP(E$3&$A6&$A9,IF({1,0},业绩报告!$A$2:$A$8229&业绩报告!$B$2:$B$8229&业绩报告!$C$2:$C$8229,业绩报告!$V$2:$V$8229),2,0),"")} -> 0 | F25: {=IFERROR(VLOOKUP(F$3&$A6&$A9,IF({1,0},业绩报告!$A$2:$A$8229&业绩报告!$B$2:$B$8229&业绩报告!$C$2:$C$8229,业绩报告!$V$2:$V$8229),2,0),"")} -> 0 | G25: {=IFERROR(VLOOKUP(G$3&$A6&$A9,IF({1,0},业绩报告!$A$2:$A$8229&业绩报告!$B$2:$B$8229&业绩报告!$C$2:$C$8229,业绩报告!$V$2:$V$8229),2,0),"")} -> 0 | H25: {=IFERROR(VLOOKUP(H$3&$A6&$A9,IF({1,0},业绩报告!$A$2:$A$8229&业绩报告!$B$2:$B$8229&业绩报告!$C$2:$C$8229,业绩报告!$V$2:$V$8229),2,0),"")} -> 0 | I25: {=IFERROR(VLOOKUP(I$3&$A6&$A9,IF({1,0},业绩报告!$A$2:$A$8229&业绩报告!$B$2:$B$8229&业绩报告!$C$2:$C$8229,业绩报告!$V$2:$V$8229),2,0),"")} -> 0 | K25: {=IFERROR(VLOOKUP(K$3&$A6&$A9,IF({1,0},业绩报告!$A$2:$A$8229&业绩报告!$B$2:$B$8229&业绩报告!$C$2:$C$8229,业绩报告!$V$2:$V$8229),2,0),"")} -> 0 | L25: {=IFERROR(VLOOKUP(L$3&$A6&$A9,IF({1,0},业绩报告!$A$2:$A$8229&业绩报告!$B$2:$B$8229&业绩报告!$C$2:$C$8229,业绩报告!$V$2:$V$8229),2,0),"")} -> 0 | M25: {=IFERROR(VLOOKUP(M$3&$A6&$A9,IF({1,0},业绩报告!$A$2:$A$8229&业绩报告!$B$2:$B$8229&业绩报告!$C$2:$C$8229,业绩报告!$V$2:$V$8229),2,0),"")} -> 0 | N25: {=IFERROR(VLOOKUP(N$3&$A6&$A9,IF({1,0},业绩报告!$A$2:$A$8229&业绩报告!$B$2:$B$8229&业绩报告!$C$2:$C$8229,业绩报告!$V$2:$V$8229),2,0),"")} -> 0 | O25: {=IFERROR(VLOOKUP(O$3&$A6&$A9,IF({1,0},业绩报告!$A$2:$A$8229&业绩报告!$B$2:$B$8229&业绩报告!$C$2:$C$8229,业绩报告!$V$2:$V$8229),2,0),"")} -> 0 | P25: {=IFERROR(VLOOKUP(P$3&$A6&$A9,IF({1,0},业绩报告!$A$2:$A$8229&业绩报告!$B$2:$B$8229&业绩报告!$C$2:$C$8229,业绩报告!$V$2:$V$8229),2,0),"")} -> 0 | Q25: {=IFERROR(VLOOKUP(Q$3&$A6&$A9,IF({1,0},业绩报告!$A$2:$A$8229&业绩报告!$B$2:$B$8229&业绩报告!$C$2:$C$8229,业绩报告!$V$2:$V$8229),2,0),"")} -> 0
B26: 自然位3 | C26: {=IFERROR(VLOOKUP(C$3&$A6&$A9,IF({1,0},业绩报告!$A$2:$A$8229&业绩报告!$B$2:$B$8229&业绩报告!$C$2:$C$8229,业绩报告!$W$2:$W$8229),2,0),"")} -> 0 | D26: {=IFERROR(VLOOKUP(D$3&$A6&$A9,IF({1,0},业绩报告!$A$2:$A$8229&业绩报告!$B$2:$B$8229&业绩报告!$C$2:$C$8229,业绩报告!$W$2:$W$8229),2,0),"")} -> 0 | E26: {=IFERROR(VLOOKUP(E$3&$A6&$A9,IF({1,0},业绩报告!$A$2:$A$8229&业绩报告!$B$2:$B$8229&业绩报告!$C$2:$C$8229,业绩报告!$W$2:$W$8229),2,0),"")} -> 0 | F26: {=IFERROR(VLOOKUP(F$3&$A6&$A9,IF({1,0},业绩报告!$A$2:$A$8229&业绩报告!$B$2:$B$8229&业绩报告!$C$2:$C$8229,业绩报告!$W$2:$W$8229),2,0),"")} -> 0 | G26: {=IFERROR(VLOOKUP(G$3&$A6&$A9,IF({1,0},业绩报告!$A$2:$A$8229&业绩报告!$B$2:$B$8229&业绩报告!$C$2:$C$8229,业绩报告!$W$2:$W$8229),2,0),"")} -> 0 | H26: {=IFERROR(VLOOKUP(H$3&$A6&$A9,IF({1,0},业绩报告!$A$2:$A$8229&业绩报告!$B$2:$B$8229&业绩报告!$C$2:$C$8229,业绩报告!$W$2:$W$8229),2,0),"")} -> 0 | I26: {=IFERROR(VLOOKUP(I$3&$A6&$A9,IF({1,0},业绩报告!$A$2:$A$8229&业绩报告!$B$2:$B$8229&业绩报告!$C$2:$C$8229,业绩报告!$W$2:$W$8229),2,0),"")} -> 0 | K26: {=IFERROR(VLOOKUP(K$3&$A6&$A9,IF({1,0},业绩报告!$A$2:$A$8229&业绩报告!$B$2:$B$8229&业绩报告!$C$2:$C$8229,业绩报告!$W$2:$W$8229),2,0),"")} -> 0 | L26: {=IFERROR(VLOOKUP(L$3&$A6&$A9,IF({1,0},业绩报告!$A$2:$A$8229&业绩报告!$B$2:$B$8229&业绩报告!$C$2:$C$8229,业绩报告!$W$2:$W$8229),2,0),"")} -> 0 | M26: {=IFERROR(VLOOKUP(M$3&$A6&$A9,IF({1,0},业绩报告!$A$2:$A$8229&业绩报告!$B$2:$B$8229&业绩报告!$C$2:$C$8229,业绩报告!$W$2:$W$8229),2,0),"")} -> 0 | N26: {=IFERROR(VLOOKUP(N$3&$A6&$A9,IF({1,0},业绩报告!$A$2:$A$8229&业绩报告!$B$2:$B$8229&业绩报告!$C$2:$C$8229,业绩报告!$W$2:$W$8229),2,0),"")} -> 0 | O26: {=IFERROR(VLOOKUP(O$3&$A6&$A9,IF({1,0},业绩报告!$A$2:$A$8229&业绩报告!$B$2:$B$8229&业绩报告!$C$2:$C$8229,业绩报告!$W$2:$W$8229),2,0),"")} -> 0 | P26: {=IFERROR(VLOOKUP(P$3&$A6&$A9,IF({1,0},业绩报告!$A$2:$A$8229&业绩报告!$B$2:$B$8229&业绩报告!$C$2:$C$8229,业绩报告!$W$2:$W$8229),2,0),"")} -> 0 | Q26: {=IFERROR(VLOOKUP(Q$3&$A6&$A9,IF({1,0},业绩报告!$A$2:$A$8229&业绩报告!$B$2:$B$8229&业绩报告!$C$2:$C$8229,业绩报告!$W$2:$W$8229),2,0),"")} -> 0
B27: 广告位3 | C27: {=IFERROR(VLOOKUP(C$3&$A6&$A9,IF({1,0},业绩报告!$A$2:$A$8229&业绩报告!$B$2:$B$8229&业绩报告!$C$2:$C$8229,业绩报告!$X$2:$X$8229),2,0),"")} -> 0 | D27: {=IFERROR(VLOOKUP(D$3&$A6&$A9,IF({1,0},业绩报告!$A$2:$A$8229&业绩报告!$B$2:$B$8229&业绩报告!$C$2:$C$8229,业绩报告!$X$2:$X$8229),2,0),"")} -> 0 | E27: {=IFERROR(VLOOKUP(E$3&$A6&$A9,IF({1,0},业绩报告!$A$2:$A$8229&业绩报告!$B$2:$B$8229&业绩报告!$C$2:$C$8229,业绩报告!$X$2:$X$8229),2,0),"")} -> 0 | F27: {=IFERROR(VLOOKUP(F$3&$A6&$A9,IF({1,0},业绩报告!$A$2:$A$8229&业绩报告!$B$2:$B$8229&业绩报告!$C$2:$C$8229,业绩报告!$X$2:$X$8229),2,0),"")} -> 0 | G27: {=IFERROR(VLOOKUP(G$3&$A6&$A9,IF({1,0},业绩报告!$A$2:$A$8229&业绩报告!$B$2:$B$8229&业绩报告!$C$2:$C$8229,业绩报告!$X$2:$X$8229),2,0),"")} -> 0 | H27: {=IFERROR(VLOOKUP(H$3&$A6&$A9,IF({1,0},业绩报告!$A$2:$A$8229&业绩报告!$B$2:$B$8229&业绩报告!$C$2:$C$8229,业绩报告!$X$2:$X$8229),2,0),"")} -> 0 | I27: {=IFERROR(VLOOKUP(I$3&$A6&$A9,IF({1,0},业绩报告!$A$2:$A$8229&业绩报告!$B$2:$B$8229&业绩报告!$C$2:$C$8229,业绩报告!$X$2:$X$8229),2,0),"")} -> 0 | K27: {=IFERROR(VLOOKUP(K$3&$A6&$A9,IF({1,0},业绩报告!$A$2:$A$8229&业绩报告!$B$2:$B$8229&业绩报告!$C$2:$C$8229,业绩报告!$X$2:$X$8229),2,0),"")} -> 0 | L27: {=IFERROR(VLOOKUP(L$3&$A6&$A9,IF({1,0},业绩报告!$A$2:$A$8229&业绩报告!$B$2:$B$8229&业绩报告!$C$2:$C$8229,业绩报告!$X$2:$X$8229),2,0),"")} -> 0 | M27: {=IFERROR(VLOOKUP(M$3&$A6&$A9,IF({1,0},业绩报告!$A$2:$A$8229&业绩报告!$B$2:$B$8229&业绩报告!$C$2:$C$8229,业绩报告!$X$2:$X$8229),2,0),"")} -> 0 | N27: {=IFERROR(VLOOKUP(N$3&$A6&$A9,IF({1,0},业绩报告!$A$2:$A$8229&业绩报告!$B$2:$B$8229&业绩报告!$C$2:$C$8229,业绩报告!$X$2:$X$8229),2,0),"")} -> 0 | O27: {=IFERROR(VLOOKUP(O$3&$A6&$A9,IF({1,0},业绩报告!$A$2:$A$8229&业绩报告!$B$2:$B$8229&业绩报告!$C$2:$C$8229,业绩报告!$X$2:$X$8229),2,0),"")} -> 0 | P27: {=IFERROR(VLOOKUP(P$3&$A6&$A9,IF({1,0},业绩报告!$A$2:$A$8229&业绩报告!$B$2:$B$8229&业绩报告!$C$2:$C$8229,业绩报告!$X$2:$X$8229),2,0),"")} -> 0 | Q27: {=IFERROR(VLOOKUP(Q$3&$A6&$A9,IF({1,0},业绩报告!$A$2:$A$8229&业绩报告!$B$2:$B$8229&业绩报告!$C$2:$C$8229,业绩报告!$X$2:$X$8229),2,0),"")} -> 0
B28: 关键词4 | C28: {=IFERROR(VLOOKUP(C$3&$A6&$A9,IF({1,0},业绩报告!$A$2:$A$8229&业绩报告!$B$2:$B$8229&业绩报告!$C$2:$C$8229,业绩报告!$Y$2:$Y$8229),2,0),"")} -> 0 | D28: {=IFERROR(VLOOKUP(D$3&$A6&$A9,IF({1,0},业绩报告!$A$2:$A$8229&业绩报告!$B$2:$B$8229&业绩报告!$C$2:$C$8229,业绩报告!$Y$2:$Y$8229),2,0),"")} -> 0 | E28: {=IFERROR(VLOOKUP(E$3&$A6&$A9,IF({1,0},业绩报告!$A$2:$A$8229&业绩报告!$B$2:$B$8229&业绩报告!$C$2:$C$8229,业绩报告!$Y$2:$Y$8229),2,0),"")} -> 0 | F28: {=IFERROR(VLOOKUP(F$3&$A6&$A9,IF({1,0},业绩报告!$A$2:$A$8229&业绩报告!$B$2:$B$8229&业绩报告!$C$2:$C$8229,业绩报告!$Y$2:$Y$8229),2,0),"")} -> 0 | G28: {=IFERROR(VLOOKUP(G$3&$A6&$A9,IF({1,0},业绩报告!$A$2:$A$8229&业绩报告!$B$2:$B$8229&业绩报告!$C$2:$C$8229,业绩报告!$Y$2:$Y$8229),2,0),"")} -> 0 | H28: {=IFERROR(VLOOKUP(H$3&$A6&$A9,IF({1,0},业绩报告!$A$2:$A$8229&业绩报告!$B$2:$B$8229&业绩报告!$C$2:$C$8229,业绩报告!$Y$2:$Y$8229),2,0),"")} -> 0 | I28: {=IFERROR(VLOOKUP(I$3&$A6&$A9,IF({1,0},业绩报告!$A$2:$A$8229&业绩报告!$B$2:$B$8229&业绩报告!$C$2:$C$8229,业绩报告!$Y$2:$Y$8229),2,0),"")} -> 0 | K28: {=IFERROR(VLOOKUP(K$3&$A6&$A9,IF({1,0},业绩报告!$A$2:$A$8229&业绩报告!$B$2:$B$8229&业绩报告!$C$2:$C$8229,业绩报告!$Y$2:$Y$8229),2,0),"")} -> 0 | L28: {=IFERROR(VLOOKUP(L$3&$A6&$A9,IF({1,0},业绩报告!$A$2:$A$8229&业绩报告!$B$2:$B$8229&业绩报告!$C$2:$C$8229,业绩报告!$Y$2:$Y$8229),2,0),"")} -> 0 | M28: {=IFERROR(VLOOKUP(M$3&$A6&$A9,IF({1,0},业绩报告!$A$2:$A$8229&业绩报告!$B$2:$B$8229&业绩报告!$C$2:$C$8229,业绩报告!$Y$2:$Y$8229),2,0),"")} -> 0 | N28: {=IFERROR(VLOOKUP(N$3&$A6&$A9,IF({1,0},业绩报告!$A$2:$A$8229&业绩报告!$B$2:$B$8229&业绩报告!$C$2:$C$8229,业绩报告!$Y$2:$Y$8229),2,0),"")} -> 0 | O28: {=IFERROR(VLOOKUP(O$3&$A6&$A9,IF({1,0},业绩报告!$A$2:$A$8229&业绩报告!$B$2:$B$8229&业绩报告!$C$2:$C$8229,业绩报告!$Y$2:$Y$8229),2,0),"")} -> 0 | P28: {=IFERROR(VLOOKUP(P$3&$A6&$A9,IF({1,0},业绩报告!$A$2:$A$8229&业绩报告!$B$2:$B$8229&业绩报告!$C$2:$C$8229,业绩报告!$Y$2:$Y$8229),2,0),"")} -> 0 | Q28: {=IFERROR(VLOOKUP(Q$3&$A6&$A9,IF({1,0},业绩报告!$A$2:$A$8229&业绩报告!$B$2:$B$8229&业绩报告!$C$2:$C$8229,业绩报告!$Y$2:$Y$8229),2,0),"")} -> 0
B29: 自然位4 | C29: {=IFERROR(VLOOKUP(C$3&$A6&$A9,IF({1,0},业绩报告!$A$2:$A$8229&业绩报告!$B$2:$B$8229&业绩报告!$C$2:$C$8229,业绩报告!$Z$2:$Z$8229),2,0),"")} -> 0 | D29: {=IFERROR(VLOOKUP(D$3&$A6&$A9,IF({1,0},业绩报告!$A$2:$A$8229&业绩报告!$B$2:$B$8229&业绩报告!$C$2:$C$8229,业绩报告!$Z$2:$Z$8229),2,0),"")} -> 0 | E29: {=IFERROR(VLOOKUP(E$3&$A6&$A9,IF({1,0},业绩报告!$A$2:$A$8229&业绩报告!$B$2:$B$8229&业绩报告!$C$2:$C$8229,业绩报告!$Z$2:$Z$8229),2,0),"")} -> 0 | F29: {=IFERROR(VLOOKUP(F$3&$A6&$A9,IF({1,0},业绩报告!$A$2:$A$8229&业绩报告!$B$2:$B$8229&业绩报告!$C$2:$C$8229,业绩报告!$Z$2:$Z$8229),2,0),"")} -> 0 | G29: {=IFERROR(VLOOKUP(G$3&$A6&$A9,IF({1,0},业绩报告!$A$2:$A$8229&业绩报告!$B$2:$B$8229&业绩报告!$C$2:$C$8229,业绩报告!$Z$2:$Z$8229),2,0),"")} -> 0 | H29: {=IFERROR(VLOOKUP(H$3&$A6&$A9,IF({1,0},业绩报告!$A$2:$A$8229&业绩报告!$B$2:$B$8229&业绩报告!$C$2:$C$8229,业绩报告!$Z$2:$Z$8229),2,0),"")} -> 0 | I29: {=IFERROR(VLOOKUP(I$3&$A6&$A9,IF({1,0},业绩报告!$A$2:$A$8229&业绩报告!$B$2:$B$8229&业绩报告!$C$2:$C$8229,业绩报告!$Z$2:$Z$8229),2,0),"")} -> 0 | K29: {=IFERROR(VLOOKUP(K$3&$A6&$A9,IF({1,0},业绩报告!$A$2:$A$8229&业绩报告!$B$2:$B$8229&业绩报告!$C$2:$C$8229,业绩报告!$Z$2:$Z$8229),2,0),"")} -> 0 | L29: {=IFERROR(VLOOKUP(L$3&$A6&$A9,IF({1,0},业绩报告!$A$2:$A$8229&业绩报告!$B$2:$B$8229&业绩报告!$C$2:$C$8229,业绩报告!$Z$2:$Z$8229),2,0),"")} -> 0 | M29: {=IFERROR(VLOOKUP(M$3&$A6&$A9,IF({1,0},业绩报告!$A$2:$A$8229&业绩报告!$B$2:$B$8229&业绩报告!$C$2:$C$8229,业绩报告!$Z$2:$Z$8229),2,0),"")} -> 0 | N29: {=IFERROR(VLOOKUP(N$3&$A6&$A9,IF({1,0},业绩报告!$A$2:$A$8229&业绩报告!$B$2:$B$8229&业绩报告!$C$2:$C$8229,业绩报告!$Z$2:$Z$8229),2,0),"")} -> 0 | O29: {=IFERROR(VLOOKUP(O$3&$A6&$A9,IF({1,0},业绩报告!$A$2:$A$8229&业绩报告!$B$2:$B$8229&业绩报告!$C$2:$C$8229,业绩报告!$Z$2:$Z$8229),2,0),"")} -> 0 | P29: {=IFERROR(VLOOKUP(P$3&$A6&$A9,IF({1,0},业绩报告!$A$2:$A$8229&业绩报告!$B$2:$B$8229&业绩报告!$C$2:$C$8229,业绩报告!$Z$2:$Z$8229),2,0),"")} -> 0 | Q29: {=IFERROR(VLOOKUP(Q$3&$A6&$A9,IF({1,0},业绩报告!$A$2:$A$8229&业绩报告!$B$2:$B$8229&业绩报告!$C$2:$C$8229,业绩报告!$Z$2:$Z$8229),2,0),"")} -> 0
B30: 广告位4 | C30: {=IFERROR(VLOOKUP(C$3&$A6&$A9,IF({1,0},业绩报告!$A$2:$A$8229&业绩报告!$B$2:$B$8229&业绩报告!$C$2:$C$8229,业绩报告!$AA$2:$AA$8229),2,0),"")} -> 0 | D30: {=IFERROR(VLOOKUP(D$3&$A6&$A9,IF({1,0},业绩报告!$A$2:$A$8229&业绩报告!$B$2:$B$8229&业绩报告!$C$2:$C$8229,业绩报告!$AA$2:$AA$8229),2,0),"")} -> 0 | E30: {=IFERROR(VLOOKUP(E$3&$A6&$A9,IF({1,0},业绩报告!$A$2:$A$8229&业绩报告!$B$2:$B$8229&业绩报告!$C$2:$C$8229,业绩报告!$AA$2:$AA$8229),2,0),"")} -> 0 | F30: {=IFERROR(VLOOKUP(F$3&$A6&$A9,IF({1,0},业绩报告!$A$2:$A$8229&业绩报告!$B$2:$B$8229&业绩报告!$C$2:$C$8229,业绩报告!$AA$2:$AA$8229),2,0),"")} -> 0 | G30: {=IFERROR(VLOOKUP(G$3&$A6&$A9,IF({1,0},业绩报告!$A$2:$A$8229&业绩报告!$B$2:$B$8229&业绩报告!$C$2:$C$8229,业绩报告!$AA$2:$AA$8229),2,0),"")} -> 0 | H30: {=IFERROR(VLOOKUP(H$3&$A6&$A9,IF({1,0},业绩报告!$A$2:$A$8229&业绩报告!$B$2:$B$8229&业绩报告!$C$2:$C$8229,业绩报告!$AA$2:$AA$8229),2,0),"")} -> 0 | I30: {=IFERROR(VLOOKUP(I$3&$A6&$A9,IF({1,0},业绩报告!$A$2:$A$8229&业绩报告!$B$2:$B$8229&业绩报告!$C$2:$C$8229,业绩报告!$AA$2:$AA$8229),2,0),"")} -> 0 | K30: {=IFERROR(VLOOKUP(K$3&$A6&$A9,IF({1,0},业绩报告!$A$2:$A$8229&业绩报告!$B$2:$B$8229&业绩报告!$C$2:$C$8229,业绩报告!$AA$2:$AA$8229),2,0),"")} -> 0 | L30: {=IFERROR(VLOOKUP(L$3&$A6&$A9,IF({1,0},业绩报告!$A$2:$A$8229&业绩报告!$B$2:$B$8229&业绩报告!$C$2:$C$8229,业绩报告!$AA$2:$AA$8229),2,0),"")} -> 0 | M30: {=IFERROR(VLOOKUP(M$3&$A6&$A9,IF({1,0},业绩报告!$A$2:$A$8229&业绩报告!$B$2:$B$8229&业绩报告!$C$2:$C$8229,业绩报告!$AA$2:$AA$8229),2,0),"")} -> 0 | N30: {=IFERROR(VLOOKUP(N$3&$A6&$A9,IF({1,0},业绩报告!$A$2:$A$8229&业绩报告!$B$2:$B$8229&业绩报告!$C$2:$C$8229,业绩报告!$AA$2:$AA$8229),2,0),"")} -> 0 | O30: {=IFERROR(VLOOKUP(O$3&$A6&$A9,IF({1,0},业绩报告!$A$2:$A$8229&业绩报告!$B$2:$B$8229&业绩报告!$C$2:$C$8229,业绩报告!$AA$2:$AA$8229),2,0),"")} -> 0 | P30: {=IFERROR(VLOOKUP(P$3&$A6&$A9,IF({1,0},业绩报告!$A$2:$A$8229&业绩报告!$B$2:$B$8229&业绩报告!$C$2:$C$8229,业绩报告!$AA$2:$AA$8229),2,0),"")} -> 0 | Q30: {=IFERROR(VLOOKUP(Q$3&$A6&$A9,IF({1,0},业绩报告!$A$2:$A$8229&业绩报告!$B$2:$B$8229&业绩报告!$C$2:$C$8229,业绩报告!$AA$2:$AA$8229),2,0),"")} -> 0
B31: 关键词5 | C31: {=IFERROR(VLOOKUP(C$3&$A6&$A9,IF({1,0},业绩报告!$A$2:$A$8229&业绩报告!$B$2:$B$8229&业绩报告!$C$2:$C$8229,业绩报告!$AB$2:$AB$8229),2,0),"")} -> 0 | D31: {=IFERROR(VLOOKUP(D$3&$A6&$A9,IF({1,0},业绩报告!$A$2:$A$8229&业绩报告!$B$2:$B$8229&业绩报告!$C$2:$C$8229,业绩报告!$AB$2:$AB$8229),2,0),"")} -> 0 | E31: {=IFERROR(VLOOKUP(E$3&$A6&$A9,IF({1,0},业绩报告!$A$2:$A$8229&业绩报告!$B$2:$B$8229&业绩报告!$C$2:$C$8229,业绩报告!$AB$2:$AB$8229),2,0),"")} -> 0 | F31: {=IFERROR(VLOOKUP(F$3&$A6&$A9,IF({1,0},业绩报告!$A$2:$A$8229&业绩报告!$B$2:$B$8229&业绩报告!$C$2:$C$8229,业绩报告!$AB$2:$AB$8229),2,0),"")} -> 0 | G31: {=IFERROR(VLOOKUP(G$3&$A6&$A9,IF({1,0},业绩报告!$A$2:$A$8229&业绩报告!$B$2:$B$8229&业绩报告!$C$2:$C$8229,业绩报告!$AB$2:$AB$8229),2,0),"")} -> 0 | H31: {=IFERROR(VLOOKUP(H$3&$A6&$A9,IF({1,0},业绩报告!$A$2:$A$8229&业绩报告!$B$2:$B$8229&业绩报告!$C$2:$C$8229,业绩报告!$AB$2:$AB$8229),2,0),"")} -> 0 | I31: {=IFERROR(VLOOKUP(I$3&$A6&$A9,IF({1,0},业绩报告!$A$2:$A$8229&业绩报告!$B$2:$B$8229&业绩报告!$C$2:$C$8229,业绩报告!$AB$2:$AB$8229),2,0),"")} -> 0 | K31: {=IFERROR(VLOOKUP(K$3&$A6&$A9,IF({1,0},业绩报告!$A$2:$A$8229&业绩报告!$B$2:$B$8229&业绩报告!$C$2:$C$8229,业绩报告!$AB$2:$AB$8229),2,0),"")} -> 0 | L31: {=IFERROR(VLOOKUP(L$3&$A6&$A9,IF({1,0},业绩报告!$A$2:$A$8229&业绩报告!$B$2:$B$8229&业绩报告!$C$2:$C$8229,业绩报告!$AB$2:$AB$8229),2,0),"")} -> 0 | M31: {=IFERROR(VLOOKUP(M$3&$A6&$A9,IF({1,0},业绩报告!$A$2:$A$8229&业绩报告!$B$2:$B$8229&业绩报告!$C$2:$C$8229,业绩报告!$AB$2:$AB$8229),2,0),"")} -> 0 | N31: {=IFERROR(VLOOKUP(N$3&$A6&$A9,IF({1,0},业绩报告!$A$2:$A$8229&业绩报告!$B$2:$B$8229&业绩报告!$C$2:$C$8229,业绩报告!$AB$2:$AB$8229),2,0),"")} -> 0 | O31: {=IFERROR(VLOOKUP(O$3&$A6&$A9,IF({1,0},业绩报告!$A$2:$A$8229&业绩报告!$B$2:$B$8229&业绩报告!$C$2:$C$8229,业绩报告!$AB$2:$AB$8229),2,0),"")} -> 0 | P31: {=IFERROR(VLOOKUP(P$3&$A6&$A9,IF({1,0},业绩报告!$A$2:$A$8229&业绩报告!$B$2:$B$8229&业绩报告!$C$2:$C$8229,业绩报告!$AB$2:$AB$8229),2,0),"")} -> 0 | Q31: {=IFERROR(VLOOKUP(Q$3&$A6&$A9,IF({1,0},业绩报告!$A$2:$A$8229&业绩报告!$B$2:$B$8229&业绩报告!$C$2:$C$8229,业绩报告!$AB$2:$AB$8229),2,0),"")} -> 0
B32: 自然位5 | C32: {=IFERROR(VLOOKUP(C$3&$A6&$A9,IF({1,0},业绩报告!$A$2:$A$8229&业绩报告!$B$2:$B$8229&业绩报告!$C$2:$C$8229,业绩报告!$AC$2:$AC$8229),2,0),"")} -> 0 | D32: {=IFERROR(VLOOKUP(D$3&$A6&$A9,IF({1,0},业绩报告!$A$2:$A$8229&业绩报告!$B$2:$B$8229&业绩报告!$C$2:$C$8229,业绩报告!$AC$2:$AC$8229),2,0),"")} -> 0 | E32: {=IFERROR(VLOOKUP(E$3&$A6&$A9,IF({1,0},业绩报告!$A$2:$A$8229&业绩报告!$B$2:$B$8229&业绩报告!$C$2:$C$8229,业绩报告!$AC$2:$AC$8229),2,0),"")} -> 0 | F32: {=IFERROR(VLOOKUP(F$3&$A6&$A9,IF({1,0},业绩报告!$A$2:$A$8229&业绩报告!$B$2:$B$8229&业绩报告!$C$2:$C$8229,业绩报告!$AC$2:$AC$8229),2,0),"")} -> 0 | G32: {=IFERROR(VLOOKUP(G$3&$A6&$A9,IF({1,0},业绩报告!$A$2:$A$8229&业绩报告!$B$2:$B$8229&业绩报告!$C$2:$C$8229,业绩报告!$AC$2:$AC$8229),2,0),"")} -> 0 | H32: {=IFERROR(VLOOKUP(H$3&$A6&$A9,IF({1,0},业绩报告!$A$2:$A$8229&业绩报告!$B$2:$B$8229&业绩报告!$C$2:$C$8229,业绩报告!$AC$2:$AC$8229),2,0),"")} -> 0 | I32: {=IFERROR(VLOOKUP(I$3&$A6&$A9,IF({1,0},业绩报告!$A$2:$A$8229&业绩报告!$B$2:$B$8229&业绩报告!$C$2:$C$8229,业绩报告!$AC$2:$AC$8229),2,0),"")} -> 0 | K32: {=IFERROR(VLOOKUP(K$3&$A6&$A9,IF({1,0},业绩报告!$A$2:$A$8229&业绩报告!$B$2:$B$8229&业绩报告!$C$2:$C$8229,业绩报告!$AC$2:$AC$8229),2,0),"")} -> 0 | L32: {=IFERROR(VLOOKUP(L$3&$A6&$A9,IF({1,0},业绩报告!$A$2:$A$8229&业绩报告!$B$2:$B$8229&业绩报告!$C$2:$C$8229,业绩报告!$AC$2:$AC$8229),2,0),"")} -> 0 | M32: {=IFERROR(VLOOKUP(M$3&$A6&$A9,IF({1,0},业绩报告!$A$2:$A$8229&业绩报告!$B$2:$B$8229&业绩报告!$C$2:$C$8229,业绩报告!$AC$2:$AC$8229),2,0),"")} -> 0 | N32: {=IFERROR(VLOOKUP(N$3&$A6&$A9,IF({1,0},业绩报告!$A$2:$A$8229&业绩报告!$B$2:$B$8229&业绩报告!$C$2:$C$8229,业绩报告!$AC$2:$AC$8229),2,0),"")} -> 0 | O32: {=IFERROR(VLOOKUP(O$3&$A6&$A9,IF({1,0},业绩报告!$A$2:$A$8229&业绩报告!$B$2:$B$8229&业绩报告!$C$2:$C$8229,业绩报告!$AC$2:$AC$8229),2,0),"")} -> 0 | P32: {=IFERROR(VLOOKUP(P$3&$A6&$A9,IF({1,0},业绩报告!$A$2:$A$8229&业绩报告!$B$2:$B$8229&业绩报告!$C$2:$C$8229,业绩报告!$AC$2:$AC$8229),2,0),"")} -> 0 | Q32: {=IFERROR(VLOOKUP(Q$3&$A6&$A9,IF({1,0},业绩报告!$A$2:$A$8229&业绩报告!$B$2:$B$8229&业绩报告!$C$2:$C$8229,业绩报告!$AC$2:$AC$8229),2,0),"")} -> 0
B33: 广告位5 | C33: {=IFERROR(VLOOKUP(C$3&$A6&$A9,IF({1,0},业绩报告!$A$2:$A$8229&业绩报告!$B$2:$B$8229&业绩报告!$C$2:$C$8229,业绩报告!$AD$2:$AD$8229),2,0),"")} -> 0 | D33: {=IFERROR(VLOOKUP(D$3&$A6&$A9,IF({1,0},业绩报告!$A$2:$A$8229&业绩报告!$B$2:$B$8229&业绩报告!$C$2:$C$8229,业绩报告!$AD$2:$AD$8229),2,0),"")} -> 0 | E33: {=IFERROR(VLOOKUP(E$3&$A6&$A9,IF({1,0},业绩报告!$A$2:$A$8229&业绩报告!$B$2:$B$8229&业绩报告!$C$2:$C$8229,业绩报告!$AD$2:$AD$8229),2,0),"")} -> 0 | F33: {=IFERROR(VLOOKUP(F$3&$A6&$A9,IF({1,0},业绩报告!$A$2:$A$8229&业绩报告!$B$2:$B$8229&业绩报告!$C$2:$C$8229,业绩报告!$AD$2:$AD$8229),2,0),"")} -> 0 | G33: {=IFERROR(VLOOKUP(G$3&$A6&$A9,IF({1,0},业绩报告!$A$2:$A$8229&业绩报告!$B$2:$B$8229&业绩报告!$C$2:$C$8229,业绩报告!$AD$2:$AD$8229),2,0),"")} -> 0 | H33: {=IFERROR(VLOOKUP(H$3&$A6&$A9,IF({1,0},业绩报告!$A$2:$A$8229&业绩报告!$B$2:$B$8229&业绩报告!$C$2:$C$8229,业绩报告!$AD$2:$AD$8229),2,0),"")} -> 0 | I33: {=IFERROR(VLOOKUP(I$3&$A6&$A9,IF({1,0},业绩报告!$A$2:$A$8229&业绩报告!$B$2:$B$8229&业绩报告!$C$2:$C$8229,业绩报告!$AD$2:$AD$8229),2,0),"")} -> 0 | K33: {=IFERROR(VLOOKUP(K$3&$A6&$A9,IF({1,0},业绩报告!$A$2:$A$8229&业绩报告!$B$2:$B$8229&业绩报告!$C$2:$C$8229,业绩报告!$AD$2:$AD$8229),2,0),"")} -> 0 | L33: {=IFERROR(VLOOKUP(L$3&$A6&$A9,IF({1,0},业绩报告!$A$2:$A$8229&业绩报告!$B$2:$B$8229&业绩报告!$C$2:$C$8229,业绩报告!$AD$2:$AD$8229),2,0),"")} -> 0 | M33: {=IFERROR(VLOOKUP(M$3&$A6&$A9,IF({1,0},业绩报告!$A$2:$A$8229&业绩报告!$B$2:$B$8229&业绩报告!$C$2:$C$8229,业绩报告!$AD$2:$AD$8229),2,0),"")} -> 0 | N33: {=IFERROR(VLOOKUP(N$3&$A6&$A9,IF({1,0},业绩报告!$A$2:$A$8229&业绩报告!$B$2:$B$8229&业绩报告!$C$2:$C$8229,业绩报告!$AD$2:$AD$8229),2,0),"")} -> 0 | O33: {=IFERROR(VLOOKUP(O$3&$A6&$A9,IF({1,0},业绩报告!$A$2:$A$8229&业绩报告!$B$2:$B$8229&业绩报告!$C$2:$C$8229,业绩报告!$AD$2:$AD$8229),2,0),"")} -> 0 | P33: {=IFERROR(VLOOKUP(P$3&$A6&$A9,IF({1,0},业绩报告!$A$2:$A$8229&业绩报告!$B$2:$B$8229&业绩报告!$C$2:$C$8229,业绩报告!$AD$2:$AD$8229),2,0),"")} -> 0 | Q33: {=IFERROR(VLOOKUP(Q$3&$A6&$A9,IF({1,0},业绩报告!$A$2:$A$8229&业绩报告!$B$2:$B$8229&业绩报告!$C$2:$C$8229,业绩报告!$AD$2:$AD$8229),2,0),"")} -> 0
B34: 关键词6 | C34: {=IFERROR(VLOOKUP(C$3&$A6&$A9,IF({1,0},业绩报告!$A$2:$A$8229&业绩报告!$B$2:$B$8229&业绩报告!$C$2:$C$8229,业绩报告!$AE$2:$AE$8229),2,0),"")} -> 0 | D34: {=IFERROR(VLOOKUP(D$3&$A6&$A9,IF({1,0},业绩报告!$A$2:$A$8229&业绩报告!$B$2:$B$8229&业绩报告!$C$2:$C$8229,业绩报告!$AE$2:$AE$8229),2,0),"")} -> 0 | E34: {=IFERROR(VLOOKUP(E$3&$A6&$A9,IF({1,0},业绩报告!$A$2:$A$8229&业绩报告!$B$2:$B$8229&业绩报告!$C$2:$C$8229,业绩报告!$AE$2:$AE$8229),2,0),"")} -> 0 | F34: {=IFERROR(VLOOKUP(F$3&$A6&$A9,IF({1,0},业绩报告!$A$2:$A$8229&业绩报告!$B$2:$B$8229&业绩报告!$C$2:$C$8229,业绩报告!$AE$2:$AE$8229),2,0),"")} -> 0 | G34: {=IFERROR(VLOOKUP(G$3&$A6&$A9,IF({1,0},业绩报告!$A$2:$A$8229&业绩报告!$B$2:$B$8229&业绩报告!$C$2:$C$8229,业绩报告!$AE$2:$AE$8229),2,0),"")} -> 0 | H34: {=IFERROR(VLOOKUP(H$3&$A6&$A9,IF({1,0},业绩报告!$A$2:$A$8229&业绩报告!$B$2:$B$8229&业绩报告!$C$2:$C$8229,业绩报告!$AE$2:$AE$8229),2,0),"")} -> 0 | I34: {=IFERROR(VLOOKUP(I$3&$A6&$A9,IF({1,0},业绩报告!$A$2:$A$8229&业绩报告!$B$2:$B$8229&业绩报告!$C$2:$C$8229,业绩报告!$AE$2:$AE$8229),2,0),"")} -> 0 | K34: {=IFERROR(VLOOKUP(K$3&$A6&$A9,IF({1,0},业绩报告!$A$2:$A$8229&业绩报告!$B$2:$B$8229&业绩报告!$C$2:$C$8229,业绩报告!$AE$2:$AE$8229),2,0),"")} -> 0 | L34: {=IFERROR(VLOOKUP(L$3&$A6&$A9,IF({1,0},业绩报告!$A$2:$A$8229&业绩报告!$B$2:$B$8229&业绩报告!$C$2:$C$8229,业绩报告!$AE$2:$AE$8229),2,0),"")} -> 0 | M34: {=IFERROR(VLOOKUP(M$3&$A6&$A9,IF({1,0},业绩报告!$A$2:$A$8229&业绩报告!$B$2:$B$8229&业绩报告!$C$2:$C$8229,业绩报告!$AE$2:$AE$8229),2,0),"")} -> 0 | N34: {=IFERROR(VLOOKUP(N$3&$A6&$A9,IF({1,0},业绩报告!$A$2:$A$8229&业绩报告!$B$2:$B$8229&业绩报告!$C$2:$C$8229,业绩报告!$AE$2:$AE$8229),2,0),"")} -> 0 | O34: {=IFERROR(VLOOKUP(O$3&$A6&$A9,IF({1,0},业绩报告!$A$2:$A$8229&业绩报告!$B$2:$B$8229&业绩报告!$C$2:$C$8229,业绩报告!$AE$2:$AE$8229),2,0),"")} -> 0 | P34: {=IFERROR(VLOOKUP(P$3&$A6&$A9,IF({1,0},业绩报告!$A$2:$A$8229&业绩报告!$B$2:$B$8229&业绩报告!$C$2:$C$8229,业绩报告!$AE$2:$AE$8229),2,0),"")} -> 0 | Q34: {=IFERROR(VLOOKUP(Q$3&$A6&$A9,IF({1,0},业绩报告!$A$2:$A$8229&业绩报告!$B$2:$B$8229&业绩报告!$C$2:$C$8229,业绩报告!$AE$2:$AE$8229),2,0),"")} -> 0
B35: 自然位6 | C35: {=IFERROR(VLOOKUP(C$3&$A6&$A9,IF({1,0},业绩报告!$A$2:$A$8229&业绩报告!$B$2:$B$8229&业绩报告!$C$2:$C$8229,业绩报告!$AF$2:$AF$8229),2,0),"")} -> 0 | D35: {=IFERROR(VLOOKUP(D$3&$A6&$A9,IF({1,0},业绩报告!$A$2:$A$8229&业绩报告!$B$2:$B$8229&业绩报告!$C$2:$C$8229,业绩报告!$AF$2:$AF$8229),2,0),"")} -> 0 | E35: {=IFERROR(VLOOKUP(E$3&$A6&$A9,IF({1,0},业绩报告!$A$2:$A$8229&业绩报告!$B$2:$B$8229&业绩报告!$C$2:$C$8229,业绩报告!$AF$2:$AF$8229),2,0),"")} -> 0 | F35: {=IFERROR(VLOOKUP(F$3&$A6&$A9,IF({1,0},业绩报告!$A$2:$A$8229&业绩报告!$B$2:$B$8229&业绩报告!$C$2:$C$8229,业绩报告!$AF$2:$AF$8229),2,0),"")} -> 0 | G35: {=IFERROR(VLOOKUP(G$3&$A6&$A9,IF({1,0},业绩报告!$A$2:$A$8229&业绩报告!$B$2:$B$8229&业绩报告!$C$2:$C$8229,业绩报告!$AF$2:$AF$8229),2,0),"")} -> 0 | H35: {=IFERROR(VLOOKUP(H$3&$A6&$A9,IF({1,0},业绩报告!$A$2:$A$8229&业绩报告!$B$2:$B$8229&业绩报告!$C$2:$C$8229,业绩报告!$AF$2:$AF$8229),2,0),"")} -> 0 | I35: {=IFERROR(VLOOKUP(I$3&$A6&$A9,IF({1,0},业绩报告!$A$2:$A$8229&业绩报告!$B$2:$B$8229&业绩报告!$C$2:$C$8229,业绩报告!$AF$2:$AF$8229),2,0),"")} -> 0 | K35: {=IFERROR(VLOOKUP(K$3&$A6&$A9,IF({1,0},业绩报告!$A$2:$A$8229&业绩报告!$B$2:$B$8229&业绩报告!$C$2:$C$8229,业绩报告!$AF$2:$AF$8229),2,0),"")} -> 0 | L35: {=IFERROR(VLOOKUP(L$3&$A6&$A9,IF({1,0},业绩报告!$A$2:$A$8229&业绩报告!$B$2:$B$8229&业绩报告!$C$2:$C$8229,业绩报告!$AF$2:$AF$8229),2,0),"")} -> 0 | M35: {=IFERROR(VLOOKUP(M$3&$A6&$A9,IF({1,0},业绩报告!$A$2:$A$8229&业绩报告!$B$2:$B$8229&业绩报告!$C$2:$C$8229,业绩报告!$AF$2:$AF$8229),2,0),"")} -> 0 | N35: {=IFERROR(VLOOKUP(N$3&$A6&$A9,IF({1,0},业绩报告!$A$2:$A$8229&业绩报告!$B$2:$B$8229&业绩报告!$C$2:$C$8229,业绩报告!$AF$2:$AF$8229),2,0),"")} -> 0 | O35: {=IFERROR(VLOOKUP(O$3&$A6&$A9,IF({1,0},业绩报告!$A$2:$A$8229&业绩报告!$B$2:$B$8229&业绩报告!$C$2:$C$8229,业绩报告!$AF$2:$AF$8229),2,0),"")} -> 0 | P35: {=IFERROR(VLOOKUP(P$3&$A6&$A9,IF({1,0},业绩报告!$A$2:$A$8229&业绩报告!$B$2:$B$8229&业绩报告!$C$2:$C$8229,业绩报告!$AF$2:$AF$8229),2,0),"")} -> 0 | Q35: {=IFERROR(VLOOKUP(Q$3&$A6&$A9,IF({1,0},业绩报告!$A$2:$A$8229&业绩报告!$B$2:$B$8229&业绩报告!$C$2:$C$8229,业绩报告!$AF$2:$AF$8229),2,0),"")} -> 0
B36: 广告位6 | C36: {=IFERROR(VLOOKUP(C$3&$A6&$A9,IF({1,0},业绩报告!$A$2:$A$8229&业绩报告!$B$2:$B$8229&业绩报告!$C$2:$C$8229,业绩报告!$AG$2:$AG$8229),2,0),"")} -> 0 | D36: {=IFERROR(VLOOKUP(D$3&$A6&$A9,IF({1,0},业绩报告!$A$2:$A$8229&业绩报告!$B$2:$B$8229&业绩报告!$C$2:$C$8229,业绩报告!$AG$2:$AG$8229),2,0),"")} -> 0 | E36: {=IFERROR(VLOOKUP(E$3&$A6&$A9,IF({1,0},业绩报告!$A$2:$A$8229&业绩报告!$B$2:$B$8229&业绩报告!$C$2:$C$8229,业绩报告!$AG$2:$AG$8229),2,0),"")} -> 0 | F36: {=IFERROR(VLOOKUP(F$3&$A6&$A9,IF({1,0},业绩报告!$A$2:$A$8229&业绩报告!$B$2:$B$8229&业绩报告!$C$2:$C$8229,业绩报告!$AG$2:$AG$8229),2,0),"")} -> 0 | G36: {=IFERROR(VLOOKUP(G$3&$A6&$A9,IF({1,0},业绩报告!$A$2:$A$8229&业绩报告!$B$2:$B$8229&业绩报告!$C$2:$C$8229,业绩报告!$AG$2:$AG$8229),2,0),"")} -> 0 | H36: {=IFERROR(VLOOKUP(H$3&$A6&$A9,IF({1,0},业绩报告!$A$2:$A$8229&业绩报告!$B$2:$B$8229&业绩报告!$C$2:$C$8229,业绩报告!$AG$2:$AG$8229),2,0),"")} -> 0 | I36: {=IFERROR(VLOOKUP(I$3&$A6&$A9,IF({1,0},业绩报告!$A$2:$A$8229&业绩报告!$B$2:$B$8229&业绩报告!$C$2:$C$8229,业绩报告!$AG$2:$AG$8229),2,0),"")} -> 0 | K36: {=IFERROR(VLOOKUP(K$3&$A6&$A9,IF({1,0},业绩报告!$A$2:$A$8229&业绩报告!$B$2:$B$8229&业绩报告!$C$2:$C$8229,业绩报告!$AG$2:$AG$8229),2,0),"")} -> 0 | L36: {=IFERROR(VLOOKUP(L$3&$A6&$A9,IF({1,0},业绩报告!$A$2:$A$8229&业绩报告!$B$2:$B$8229&业绩报告!$C$2:$C$8229,业绩报告!$AG$2:$AG$8229),2,0),"")} -> 0 | M36: {=IFERROR(VLOOKUP(M$3&$A6&$A9,IF({1,0},业绩报告!$A$2:$A$8229&业绩报告!$B$2:$B$8229&业绩报告!$C$2:$C$8229,业绩报告!$AG$2:$AG$8229),2,0),"")} -> 0 | N36: {=IFERROR(VLOOKUP(N$3&$A6&$A9,IF({1,0},业绩报告!$A$2:$A$8229&业绩报告!$B$2:$B$8229&业绩报告!$C$2:$C$8229,业绩报告!$AG$2:$AG$8229),2,0),"")} -> 0 | O36: {=IFERROR(VLOOKUP(O$3&$A6&$A9,IF({1,0},业绩报告!$A$2:$A$8229&业绩报告!$B$2:$B$8229&业绩报告!$C$2:$C$8229,业绩报告!$AG$2:$AG$8229),2,0),"")} -> 0 | P36: {=IFERROR(VLOOKUP(P$3&$A6&$A9,IF({1,0},业绩报告!$A$2:$A$8229&业绩报告!$B$2:$B$8229&业绩报告!$C$2:$C$8229,业绩报告!$AG$2:$AG$8229),2,0),"")} -> 0 | Q36: {=IFERROR(VLOOKUP(Q$3&$A6&$A9,IF({1,0},业绩报告!$A$2:$A$8229&业绩报告!$B$2:$B$8229&业绩报告!$C$2:$C$8229,业绩报告!$AG$2:$AG$8229),2,0),"")} -> 0
