Workbook

Sheet 表格说明
A1: 子表 | B1: 表格说明 | C1: 流程 | D1: 截图
A2: 年目标 | B2: 1. 2023年计划对比2022年实际完成的增长情况 2. 2023年计划完成销售额部分根据每月目标分解的每月销售额求和而来 3. 自己导入2022年的数据即可 其余部分均有公式 | C2: / | D2: /
A3: 2023年利润预测 | B3: 1. 旧品的FBA操作费 退款金额 平台费用等数据都是用2023年的目标销售额与2022年各个指标的比率相乘得来的预估数据 2. 广告花费部分则是根据船长2022年的CPC及转化率和预估的广告订单占比 得出的数据， 对于部分旧品可能存在2022年头程成本或者广告成本 促销成本较高的情况 可以根据产品当前的一个实际情况给予一个系数
A4: 市占率目标 | B4: 1. 表格包括对2023年整体的市场预估以及xxx的目标市占率 2. 整体的市场预估根据过去4年的市场容量复合增长情况得出 3. 表格无需任何预处理操作 直接有公式获取子表 - 市场概况里的数据 | C4: / | D4: /
A5: 单品目标年销量 | B5: 1. 旧品部分是根据xxx过去两年（2021-2022年)的销售数据得出的复合增长情况 作为2023年的销量目标增长，其中可能有部分新品是有出现暴增的情况 这种情况下 在销量目标占比那里除以一个系数即可 2. 新品规划部分批注上写了试产时间 各自按照站点情况 填写全年的目标销量 3. 其余系列部分均嵌入公式 除了第一点提到的情况 其余无需改动 | C5: /
A6: 每月目标分解 | B6: 1. 表格自动获取 子表 - 单品目标年销量里的年销售额 根据子表 - 2022年销售情况里每个月份占全年销售额的比例计算出每月的销售额 2. 对于部分新品 由于试产时间不一 有些上半年就可以卖 有些年中才试产 下半年销售 因此根据2022年的每月销售额占比计算会有缺失 因此均在11-12月份给出了一个增长系数(主要是销售额占比的增长系数) | C6: /
A7: 市场概况 | B7: 1. 表格包括了xxx自身总的及部分细分ASIN的销量及市占率走势 市场容量及市场份额的趋势 以及过去4年的市场容量复合增长和过去2年的市场份额复合增长情况 2. 其中有几个部分 需要手动改动 1）xxx主要ASIN销售情况(2022年) 这一部分需要修改自己ASIN所在类目市场容量及市场份额这部分的数据来源 2）各类目TOP5品牌集中度(近30天)这一部分也需要修改自己ASIN所在类目市场容量及市场份额这部分的数据来源 3. 过去四年市场销量复合增长情况这部分 需要通过sorftime插件获取2019年-2020年的销量数据 因为卖家精灵只能获取20年12月份到22年12月份的数据 | C7: /
A8: 2022年销售情况 | B8: 1. 内嵌公式 无需任何改动 2. 各站点可能有些ASIN是独立的 加入进去 下拉公式即可 | C8: / | D8: /
A9: 单品每月销售额占比 | B9: 1. 内嵌公式 无需任何改动 2. 各站点可能有些ASIN是独立的 加入进去 下拉公式即可 | C9: / | D9: /
A10: 船长每月数据(2021年) | B10: 1. 数据获取路径: 数据方舟 - 月度分析报表 - 筛选2021年的数据 | C10: /
A11: 船长每月数据(2022年) | B11: 1. 数据获取路径: 数据方舟 - 月度分析报表 - 筛选2022年的数据
A12: 每月市场趋势 | B12: 1. 数据下载路径: 卖家精灵 - 选市场 - 选择类目 - 筛选市场 - 下载市场分析报告为Excel格式 2. 文件下载下来后 复制 行业销售趋势的数据即可
A13: 类目品牌市占率 | B13: 1. 数据下载路径: 卖家精灵 - 选市场 - 选择类目 - 筛选市场 - 下载市场分析报告为Excel格式 2. 文件下载下来后 复制 品牌集中度的数据即可
A14: 2021&2022营销成本概况 | B14: 拉取2021年及2022年船长的数据得出的营销成本概况
A15: 2022年全年财务报表 | B15: 在全年的财务报表里做数据预处理 行一列只保留渠道SKU 然后复制过来即可

Sheet 年目标
A1: 2023年度目标计划 | H1: 各系列产品销量及销售额明细(年度)
A2: 月份 | B2: 2022年计划完成 | C2: 2022年实际完成 | D2: 2022年实际完成率 | E2: 2023年计划完成 | F2: 同比增长率 | H2: 大类 | I2: 系列 | J2: 2022年销量 | K2: 2022年销售额 | L2: 2023年计划销量 | M2: 2023年计划销售额 | N2: 销量同比 | O2: 销售额同比
A3: 1 | D3: =IFERROR(C3/B3,0) -> 0 | F3: =IFERROR((E3-C3)/C3,0) -> 0 | J3: =SUMIFS(单品目标年销量!I:I,单品目标年销量!B:B,I:I,单品目标年销量!A:A,H:H) -> 0 | K3: =SUMIFS(单品目标年销量!P:P,单品目标年销量!B:B,I:I,单品目标年销量!A:A,H:H) -> 0 | L3: =SUMIFS(单品目标年销量!U:U,单品目标年销量!B:B,I:I,单品目标年销量!A:A,H:H) -> 0 | M3: =SUMIFS(单品目标年销量!W:W,单品目标年销量!B:B,I:I,单品目标年销量!A:A,H:H) -> 0 | N3: =IFERROR((L3-J3)/J3,0) -> 0 | O3: =IFERROR((M3-K3)/K3,0) -> 0
A4: 2 | D4: =IFERROR(C4/B4,0) -> 0 | F4: =IFERROR((E4-C4)/C4,0) -> 0 | J4: =SUMIFS(单品目标年销量!I:I,单品目标年销量!B:B,I:I,单品目标年销量!A:A,H:H) -> 0 | K4: =SUMIFS(单品目标年销量!P:P,单品目标年销量!B:B,I:I,单品目标年销量!A:A,H:H) -> 0 | L4: =SUMIFS(单品目标年销量!U:U,单品目标年销量!B:B,I:I,单品目标年销量!A:A,H:H) -> 0 | M4: =SUMIFS(单品目标年销量!W:W,单品目标年销量!B:B,I:I,单品目标年销量!A:A,H:H) -> 0 | N4: =IFERROR((L4-J4)/J4,0) -> 0 | O4: =IFERROR((M4-K4)/K4,0) -> 0
A5: 3 | D5: =IFERROR(C5/B5,0) -> 0 | F5: =IFERROR((E5-C5)/C5,0) -> 0 | J5: =SUMIFS(单品目标年销量!I:I,单品目标年销量!B:B,I:I,单品目标年销量!A:A,H:H) -> 0 | K5: =SUMIFS(单品目标年销量!P:P,单品目标年销量!B:B,I:I,单品目标年销量!A:A,H:H) -> 0 | L5: =SUMIFS(单品目标年销量!U:U,单品目标年销量!B:B,I:I,单品目标年销量!A:A,H:H) -> 0 | M5: =SUMIFS(单品目标年销量!W:W,单品目标年销量!B:B,I:I,单品目标年销量!A:A,H:H) -> 0 | N5: =IFERROR((L5-J5)/J5,0) -> 0 | O5: =IFERROR((M5-K5)/K5,0) -> 0
A6: 4 | D6: =IFERROR(C6/B6,0) -> 0 | F6: =IFERROR((E6-C6)/C6,0) -> 0 | J6: =SUMIFS(单品目标年销量!I:I,单品目标年销量!B:B,I:I,单品目标年销量!A:A,H:H) -> 0 | K6: =SUMIFS(单品目标年销量!P:P,单品目标年销量!B:B,I:I,单品目标年销量!A:A,H:H) -> 0 | L6: =SUMIFS(单品目标年销量!U:U,单品目标年销量!B:B,I:I,单品目标年销量!A:A,H:H) -> 0 | M6: =SUMIFS(单品目标年销量!W:W,单品目标年销量!B:B,I:I,单品目标年销量!A:A,H:H) -> 0 | N6: =IFERROR((L6-J6)/J6,0) -> 0 | O6: =IFERROR((M6-K6)/K6,0) -> 0
A7: 5 | D7: =IFERROR(C7/B7,0) -> 0 | F7: =IFERROR((E7-C7)/C7,0) -> 0 | J7: =SUMIFS(单品目标年销量!I:I,单品目标年销量!B:B,I:I,单品目标年销量!A:A,H:H) -> 0 | K7: =SUMIFS(单品目标年销量!P:P,单品目标年销量!B:B,I:I,单品目标年销量!A:A,H:H) -> 0 | L7: =SUMIFS(单品目标年销量!U:U,单品目标年销量!B:B,I:I,单品目标年销量!A:A,H:H) -> 0 | M7: =SUMIFS(单品目标年销量!W:W,单品目标年销量!B:B,I:I,单品目标年销量!A:A,H:H) -> 0 | N7: =IFERROR((L7-J7)/J7,0) -> 0 | O7: =IFERROR((M7-K7)/K7,0) -> 0
A8: 6 | D8: =IFERROR(C8/B8,0) -> 0 | F8: =IFERROR((E8-C8)/C8,0) -> 0 | J8: =SUMIFS(单品目标年销量!I:I,单品目标年销量!B:B,I:I,单品目标年销量!A:A,H:H) -> 0 | K8: =SUMIFS(单品目标年销量!P:P,单品目标年销量!B:B,I:I,单品目标年销量!A:A,H:H) -> 0 | L8: =SUMIFS(单品目标年销量!U:U,单品目标年销量!B:B,I:I,单品目标年销量!A:A,H:H) -> 0 | M8: =SUMIFS(单品目标年销量!W:W,单品目标年销量!B:B,I:I,单品目标年销量!A:A,H:H) -> 0 | N8: =IFERROR((L8-J8)/J8,0) -> 0 | O8: =IFERROR((M8-K8)/K8,0) -> 0
A9: 7 | D9: =IFERROR(C9/B9,0) -> 0 | F9: =IFERROR((E9-C9)/C9,0) -> 0 | J9: =SUMIFS(单品目标年销量!I:I,单品目标年销量!B:B,I:I,单品目标年销量!A:A,H:H) -> 0 | K9: =SUMIFS(单品目标年销量!P:P,单品目标年销量!B:B,I:I,单品目标年销量!A:A,H:H) -> 0 | L9: =SUMIFS(单品目标年销量!U:U,单品目标年销量!B:B,I:I,单品目标年销量!A:A,H:H) -> 0 | M9: =SUMIFS(单品目标年销量!W:W,单品目标年销量!B:B,I:I,单品目标年销量!A:A,H:H) -> 0 | N9: =IFERROR((L9-J9)/J9,0) -> 0 | O9: =IFERROR((M9-K9)/K9,0) -> 0
A10: 8 | D10: =IFERROR(C10/B10,0) -> 0 | F10: =IFERROR((E10-C10)/C10,0) -> 0 | J10: =SUMIFS(单品目标年销量!I:I,单品目标年销量!B:B,I:I,单品目标年销量!A:A,H:H) -> 0 | K10: =SUMIFS(单品目标年销量!P:P,单品目标年销量!B:B,I:I,单品目标年销量!A:A,H:H) -> 0 | L10: =SUMIFS(单品目标年销量!U:U,单品目标年销量!B:B,I:I,单品目标年销量!A:A,H:H) -> 0 | M10: =SUMIFS(单品目标年销量!W:W,单品目标年销量!B:B,I:I,单品目标年销量!A:A,H:H) -> 0 | N10: =IFERROR((L10-J10)/J10,0) -> 0 | O10: =IFERROR((M10-K10)/K10,0) -> 0
A11: 9 | D11: =IFERROR(C11/B11,0) -> 0 | F11: =IFERROR((E11-C11)/C11,0) -> 0 | J11: =SUMIFS(单品目标年销量!I:I,单品目标年销量!B:B,I:I,单品目标年销量!A:A,H:H) -> 0 | K11: =SUMIFS(单品目标年销量!P:P,单品目标年销量!B:B,I:I,单品目标年销量!A:A,H:H) -> 0 | L11: =SUMIFS(单品目标年销量!U:U,单品目标年销量!B:B,I:I,单品目标年销量!A:A,H:H) -> 0 | M11: =SUMIFS(单品目标年销量!W:W,单品目标年销量!B:B,I:I,单品目标年销量!A:A,H:H) -> 0 | N11: =IFERROR((L11-J11)/J11,0) -> 0 | O11: =IFERROR((M11-K11)/K11,0) -> 0
A12: 10 | D12: =IFERROR(C12/B12,0) -> 0 | F12: =IFERROR((E12-C12)/C12,0) -> 0 | H12: 总计 | I12: / | J12: =SUM(J3:J11) -> 0 | K12: =SUM(K3:K11) -> 0 | L12: =SUM(L3:L11) -> 0 | M12: =SUM(M3:M11) -> 0 | N12: =IFERROR((L12-J12)/J12,0) -> 0 | O12: =IFERROR((M12-K12)/K12,0) -> 0
A13: 11 | D13: =IFERROR(C13/B13,0) -> 0 | F13: =IFERROR((E13-C13)/C13,0) -> 0
A14: 12 | D14: =IFERROR(C14/B14,0) -> 0 | F14: =IFERROR((E14-C14)/C14,0) -> 0
A15: 总计 | B15: =SUM(B3:B14) -> 0 | C15: =SUM(C3:C14) -> 0 | D15: =IFERROR(C15/B15,0) -> 0 | E15: =SUM(E3:E14) -> 0 | F15: =IFERROR((E15-C15)/C15,0) -> 0
A17: 币种 | B17: 汇率
A18: EUR | B18: 1.0682148
A19: GBP | B19: 1.2075472
A20: CNY | B20: 6.89
A21: SEK | B21: 0.0956459

Sheet 2023年利润预测
A1: 产品大类 | B1: 产品系列 | C1: 产品SKU | D1: 产品ASIN | E1: 型号系列 | F1: 产品中文名 | G1: 2023年利润预测
G2: 预估销售额 | H2: 预估销量 | I2: 预估广告订单量 | J2: 退款金额 | K2: FBA操作费 | L2: 平台费用 | M2: 头程费用 | N2: 产品成本 | O2: 税金 | P2: 预估广告花费 | Q2: 广告花费占比 | R2: 预估CPC | S2: 预估CPA | T2: 预估TCPA | U2: 预估促销花费 | V2: 促销花费占比 | W2: 预估转化率 | X2: 预估利润 | Y2: 预估利润率
G3: =SUMIF(每月目标分解!E:E,F:F,每月目标分解!R:R)*年目标!$B$18 -> 0 | H3: =IFERROR(SUMIF(F:F,每月目标分解!E:E,每月目标分解!R:R)/SUMIF(F:F,单品目标年销量!E:E,单品目标年销量!F:F),0) -> 0 | I3: =H3*0.4 -> 0 | J3: =IFERROR(G3*'2022年全年财务报表'!$E$154,0) -> 0 | K3: =G3*'2022年全年财务报表'!$G$154 -> 0 | L3: =G3*'2022年全年财务报表'!$I$154 -> 0 | M3: =G3*'2022年全年财务报表'!$O$154 -> 0 | N3: =G3*'2022年全年财务报表'!$Q$154 -> 0 | O3: =G3*'2022年全年财务报表'!$S$154 -> 0 | P3: =IFERROR(I3/W3*R3,0) -> 0 | Q3: =IFERROR(P3/G3,0) -> 0 | R3: =SUMIF('船长每月数据(2023年)'!C:C,"BBQ",'船长每月数据(2023年)'!AA:AA)/SUMIF('船长每月数据(2023年)'!C:C,"BBQ",'船长每月数据(2023年)'!AD:AD)*年目标!$B$18 -> #DIV/0! | S3: =IFERROR(P3/I3,0) -> 0 | T3: =IFERROR(P3/H3,0) -> 0 | U3: =G3*'2022年全年财务报表'!$K$154 -> 0 | V3: =IFERROR(U3/G3,0) -> 0 | W3: =SUMIF('船长每月数据(2023年)'!C:C,"BBQ",'船长每月数据(2023年)'!P:P)/SUMIF('船长每月数据(2023年)'!C:C,"BBQ",'船长每月数据(2023年)'!H:H) -> #DIV/0! | X3: =IFERROR(G3+J3+K3+L3+M3+N3+O3+P3+U3,0) -> 0 | Y3: =IFERROR(X3/G3,0) -> 0
G4: =SUMIF(每月目标分解!E:E,F:F,每月目标分解!R:R)*年目标!$B$18 -> 0 | H4: =IFERROR(SUMIF(F:F,每月目标分解!E:E,每月目标分解!R:R)/SUMIF(F:F,单品目标年销量!E:E,单品目标年销量!F:F),0) -> 0 | I4: =H4*0.4 -> 0 | J4: =IFERROR(G4*'2022年全年财务报表'!$E$154,0) -> 0 | K4: =G4*'2022年全年财务报表'!$G$154 -> 0 | L4: =G4*'2022年全年财务报表'!$I$154 -> 0 | M4: =G4*'2022年全年财务报表'!$O$154 -> 0 | N4: =G4*'2022年全年财务报表'!$Q$154 -> 0 | O4: =G4*'2022年全年财务报表'!$S$154 -> 0 | P4: =IFERROR(I4/W4*R4,0) -> 0 | Q4: =IFERROR(P4/G4,0) -> 0 | R4: =SUMIF('船长每月数据(2023年)'!C:C,"BBQ",'船长每月数据(2023年)'!AA:AA)/SUMIF('船长每月数据(2023年)'!C:C,"BBQ",'船长每月数据(2023年)'!AD:AD)*年目标!$B$18 -> #DIV/0! | S4: =IFERROR(P4/I4,0) -> 0 | T4: =IFERROR(P4/H4,0) -> 0 | U4: =G4*'2022年全年财务报表'!$K$154 -> 0 | V4: =IFERROR(U4/G4,0) -> 0 | W4: =SUMIF('船长每月数据(2023年)'!C:C,"BBQ",'船长每月数据(2023年)'!P:P)/SUMIF('船长每月数据(2023年)'!C:C,"BBQ",'船长每月数据(2023年)'!H:H) -> #DIV/0! | X4: =IFERROR(G4+J4+K4+L4+M4+N4+O4+P4+U4,0) -> 0 | Y4: =IFERROR(X4/G4,0) -> 0
G5: =SUMIF(每月目标分解!E:E,F:F,每月目标分解!R:R)*年目标!$B$18 -> 0 | H5: =IFERROR(SUMIF(F:F,每月目标分解!E:E,每月目标分解!R:R)/SUMIF(F:F,单品目标年销量!E:E,单品目标年销量!F:F),0) -> 0 | I5: =H5*0.4 -> 0 | J5: =IFERROR(G5*'2022年全年财务报表'!$E$154,0) -> 0 | K5: =G5*'2022年全年财务报表'!$G$154 -> 0 | L5: =G5*'2022年全年财务报表'!$I$154 -> 0 | M5: =G5*'2022年全年财务报表'!$O$154 -> 0 | N5: =G5*'2022年全年财务报表'!$Q$154 -> 0 | O5: =G5*'2022年全年财务报表'!$S$154 -> 0 | P5: =IFERROR(I5/W5*R5,0) -> 0 | Q5: =IFERROR(P5/G5,0) -> 0 | R5: =SUMIF('船长每月数据(2023年)'!C:C,"BBQ",'船长每月数据(2023年)'!AA:AA)/SUMIF('船长每月数据(2023年)'!C:C,"BBQ",'船长每月数据(2023年)'!AD:AD)*年目标!$B$18 -> #DIV/0! | S5: =IFERROR(P5/I5,0) -> 0 | T5: =IFERROR(P5/H5,0) -> 0 | U5: =G5*'2022年全年财务报表'!$K$154 -> 0 | V5: =IFERROR(U5/G5,0) -> 0 | W5: =SUMIF('船长每月数据(2023年)'!C:C,"BBQ",'船长每月数据(2023年)'!P:P)/SUMIF('船长每月数据(2023年)'!C:C,"BBQ",'船长每月数据(2023年)'!H:H) -> #DIV/0! | X5: =IFERROR(G5+J5+K5+L5+M5+N5+O5+P5+U5,0) -> 0 | Y5: =IFERROR(X5/G5,0) -> 0
G6: =SUMIF(每月目标分解!E:E,F:F,每月目标分解!R:R)*年目标!$B$18 -> 0 | H6: =IFERROR(SUMIF(F:F,每月目标分解!E:E,每月目标分解!R:R)/SUMIF(F:F,单品目标年销量!E:E,单品目标年销量!F:F),0) -> 0 | I6: =H6*0.4 -> 0 | J6: =IFERROR(G6*'2022年全年财务报表'!$E$154,0) -> 0 | K6: =G6*'2022年全年财务报表'!$G$154 -> 0 | L6: =G6*'2022年全年财务报表'!$I$154 -> 0 | M6: =G6*'2022年全年财务报表'!$O$154 -> 0 | N6: =G6*'2022年全年财务报表'!$Q$154 -> 0 | O6: =G6*'2022年全年财务报表'!$S$154 -> 0 | P6: =IFERROR(I6/W6*R6,0) -> 0 | Q6: =IFERROR(P6/G6,0) -> 0 | R6: =SUMIF('船长每月数据(2023年)'!C:C,"BBQ",'船长每月数据(2023年)'!AA:AA)/SUMIF('船长每月数据(2023年)'!C:C,"BBQ",'船长每月数据(2023年)'!AD:AD)*年目标!$B$18 -> #DIV/0! | S6: =IFERROR(P6/I6,0) -> 0 | T6: =IFERROR(P6/H6,0) -> 0 | U6: =G6*'2022年全年财务报表'!$K$154 -> 0 | V6: =IFERROR(U6/G6,0) -> 0 | W6: =SUMIF('船长每月数据(2023年)'!C:C,"BBQ",'船长每月数据(2023年)'!P:P)/SUMIF('船长每月数据(2023年)'!C:C,"BBQ",'船长每月数据(2023年)'!H:H) -> #DIV/0! | X6: =IFERROR(G6+J6+K6+L6+M6+N6+O6+P6+U6,0) -> 0 | Y6: =IFERROR(X6/G6,0) -> 0
G7: =SUMIF(每月目标分解!E:E,F:F,每月目标分解!R:R)*年目标!$B$18 -> 0 | H7: =IFERROR(SUMIF(F:F,每月目标分解!E:E,每月目标分解!R:R)/SUMIF(F:F,单品目标年销量!E:E,单品目标年销量!F:F),0) -> 0 | I7: =H7*0.4 -> 0 | J7: =IFERROR(G7*'2022年全年财务报表'!$E$154,0) -> 0 | K7: =G7*'2022年全年财务报表'!$G$154 -> 0 | L7: =G7*'2022年全年财务报表'!$I$154 -> 0 | M7: =G7*'2022年全年财务报表'!$O$154 -> 0 | N7: =G7*'2022年全年财务报表'!$Q$154 -> 0 | O7: =G7*'2022年全年财务报表'!$S$154 -> 0 | P7: =IFERROR(I7/W7*R7,0) -> 0 | Q7: =IFERROR(P7/G7,0) -> 0 | R7: =SUMIF('船长每月数据(2023年)'!C:C,"BBQ",'船长每月数据(2023年)'!AA:AA)/SUMIF('船长每月数据(2023年)'!C:C,"BBQ",'船长每月数据(2023年)'!AD:AD)*年目标!$B$18 -> #DIV/0! | S7: =IFERROR(P7/I7,0) -> 0 | T7: =IFERROR(P7/H7,0) -> 0 | U7: =G7*'2022年全年财务报表'!$K$154 -> 0 | V7: =IFERROR(U7/G7,0) -> 0 | W7: =SUMIF('船长每月数据(2023年)'!C:C,"BBQ",'船长每月数据(2023年)'!P:P)/SUMIF('船长每月数据(2023年)'!C:C,"BBQ",'船长每月数据(2023年)'!H:H) -> #DIV/0! | X7: =IFERROR(G7+J7+K7+L7+M7+N7+O7+P7+U7,0) -> 0 | Y7: =IFERROR(X7/G7,0) -> 0
G8: =SUMIF(每月目标分解!E:E,F:F,每月目标分解!R:R)*年目标!$B$18 -> 0 | H8: =IFERROR(SUMIF(F:F,每月目标分解!E:E,每月目标分解!R:R)/SUMIF(F:F,单品目标年销量!E:E,单品目标年销量!F:F),0) -> 0 | I8: =H8*0.4 -> 0 | J8: =IFERROR(G8*'2022年全年财务报表'!$E$154,0) -> 0 | K8: =G8*'2022年全年财务报表'!$G$154 -> 0 | L8: =G8*'2022年全年财务报表'!$I$154 -> 0 | M8: =G8*'2022年全年财务报表'!$O$154 -> 0 | N8: =G8*'2022年全年财务报表'!$Q$154 -> 0 | O8: =G8*'2022年全年财务报表'!$S$154 -> 0 | P8: =IFERROR(I8/W8*R8,0) -> 0 | Q8: =IFERROR(P8/G8,0) -> 0 | R8: =SUMIF('船长每月数据(2023年)'!C:C,"BBQ",'船长每月数据(2023年)'!AA:AA)/SUMIF('船长每月数据(2023年)'!C:C,"BBQ",'船长每月数据(2023年)'!AD:AD)*年目标!$B$18 -> #DIV/0! | S8: =IFERROR(P8/I8,0) -> 0 | T8: =IFERROR(P8/H8,0) -> 0 | U8: =G8*'2022年全年财务报表'!$K$154 -> 0 | V8: =IFERROR(U8/G8,0) -> 0 | W8: =SUMIF('船长每月数据(2023年)'!C:C,"BBQ",'船长每月数据(2023年)'!P:P)/SUMIF('船长每月数据(2023年)'!C:C,"BBQ",'船长每月数据(2023年)'!H:H) -> #DIV/0! | X8: =IFERROR(G8+J8+K8+L8+M8+N8+O8+P8+U8,0) -> 0 | Y8: =IFERROR(X8/G8,0) -> 0
G9: =SUMIF(每月目标分解!E:E,F:F,每月目标分解!R:R)*年目标!$B$18 -> 0 | H9: =IFERROR(SUMIF(F:F,每月目标分解!E:E,每月目标分解!R:R)/SUMIF(F:F,单品目标年销量!E:E,单品目标年销量!F:F),0) -> 0 | I9: =H9*0.4 -> 0 | J9: =IFERROR(G9*'2022年全年财务报表'!$E$154,0) -> 0 | K9: =G9*'2022年全年财务报表'!$G$154 -> 0 | L9: =G9*'2022年全年财务报表'!$I$154 -> 0 | M9: =G9*'2022年全年财务报表'!$O$154 -> 0 | N9: =G9*'2022年全年财务报表'!$Q$154 -> 0 | O9: =G9*'2022年全年财务报表'!$S$154 -> 0 | P9: =IFERROR(I9/W9*R9,0) -> 0 | Q9: =IFERROR(P9/G9,0) -> 0 | R9: =SUMIF('船长每月数据(2023年)'!C:C,"BBQ",'船长每月数据(2023年)'!AA:AA)/SUMIF('船长每月数据(2023年)'!C:C,"BBQ",'船长每月数据(2023年)'!AD:AD)*年目标!$B$18 -> #DIV/0! | S9: =IFERROR(P9/I9,0) -> 0 | T9: =IFERROR(P9/H9,0) -> 0 | U9: =G9*'2022年全年财务报表'!$K$154 -> 0 | V9: =IFERROR(U9/G9,0) -> 0 | W9: =SUMIF('船长每月数据(2023年)'!C:C,"BBQ",'船长每月数据(2023年)'!P:P)/SUMIF('船长每月数据(2023年)'!C:C,"BBQ",'船长每月数据(2023年)'!H:H) -> #DIV/0! | X9: =IFERROR(G9+J9+K9+L9+M9+N9+O9+P9+U9,0) -> 0 | Y9: =IFERROR(X9/G9,0) -> 0
G10: =SUMIF(每月目标分解!E:E,F:F,每月目标分解!R:R)*年目标!$B$18 -> 0 | H10: =IFERROR(SUMIF(F:F,每月目标分解!E:E,每月目标分解!R:R)/SUMIF(F:F,单品目标年销量!E:E,单品目标年销量!F:F),0) -> 0 | I10: =H10*0.4 -> 0 | J10: =IFERROR(G10*'2022年全年财务报表'!$E$154,0) -> 0 | K10: =G10*'2022年全年财务报表'!$G$154 -> 0 | L10: =G10*'2022年全年财务报表'!$I$154 -> 0 | M10: =G10*'2022年全年财务报表'!$O$154 -> 0 | N10: =G10*'2022年全年财务报表'!$Q$154 -> 0 | O10: =G10*'2022年全年财务报表'!$S$154 -> 0 | P10: =IFERROR(I10/W10*R10,0) -> 0 | Q10: =IFERROR(P10/G10,0) -> 0 | R10: =SUMIF('船长每月数据(2023年)'!C:C,"BBQ",'船长每月数据(2023年)'!AA:AA)/SUMIF('船长每月数据(2023年)'!C:C,"BBQ",'船长每月数据(2023年)'!AD:AD)*年目标!$B$18 -> #DIV/0! | S10: =IFERROR(P10/I10,0) -> 0 | T10: =IFERROR(P10/H10,0) -> 0 | U10: =G10*'2022年全年财务报表'!$K$154 -> 0 | V10: =IFERROR(U10/G10,0) -> 0 | W10: =SUMIF('船长每月数据(2023年)'!C:C,"BBQ",'船长每月数据(2023年)'!P:P)/SUMIF('船长每月数据(2023年)'!C:C,"BBQ",'船长每月数据(2023年)'!H:H) -> #DIV/0! | X10: =IFERROR(G10+J10+K10+L10+M10+N10+O10+P10+U10,0) -> 0 | Y10: =IFERROR(X10/G10,0) -> 0
G11: =SUMIF(每月目标分解!E:E,F:F,每月目标分解!R:R)*年目标!$B$18 -> 0 | H11: =IFERROR(SUMIF(F:F,每月目标分解!E:E,每月目标分解!R:R)/SUMIF(F:F,单品目标年销量!E:E,单品目标年销量!F:F),0) -> 0 | I11: =H11*0.4 -> 0 | J11: =IFERROR(G11*'2022年全年财务报表'!$E$154,0) -> 0 | K11: =G11*'2022年全年财务报表'!$G$154 -> 0 | L11: =G11*'2022年全年财务报表'!$I$154 -> 0 | M11: =G11*'2022年全年财务报表'!$O$154 -> 0 | N11: =G11*'2022年全年财务报表'!$Q$154 -> 0 | O11: =G11*'2022年全年财务报表'!$S$154 -> 0 | P11: =IFERROR(I11/W11*R11,0) -> 0 | Q11: =IFERROR(P11/G11,0) -> 0 | R11: =SUMIF('船长每月数据(2023年)'!C:C,"BBQ",'船长每月数据(2023年)'!AA:AA)/SUMIF('船长每月数据(2023年)'!C:C,"BBQ",'船长每月数据(2023年)'!AD:AD)*年目标!$B$18 -> #DIV/0! | S11: =IFERROR(P11/I11,0) -> 0 | T11: =IFERROR(P11/H11,0) -> 0 | U11: =G11*'2022年全年财务报表'!$K$154 -> 0 | V11: =IFERROR(U11/G11,0) -> 0 | W11: =SUMIF('船长每月数据(2023年)'!C:C,"BBQ",'船长每月数据(2023年)'!P:P)/SUMIF('船长每月数据(2023年)'!C:C,"BBQ",'船长每月数据(2023年)'!H:H) -> #DIV/0! | X11: =IFERROR(G11+J11+K11+L11+M11+N11+O11+P11+U11,0) -> 0 | Y11: =IFERROR(X11/G11,0) -> 0
G12: =SUMIF(每月目标分解!E:E,F:F,每月目标分解!R:R)*年目标!$B$18 -> 0 | H12: =IFERROR(SUMIF(F:F,每月目标分解!E:E,每月目标分解!R:R)/SUMIF(F:F,单品目标年销量!E:E,单品目标年销量!F:F),0) -> 0 | I12: =H12*0.4 -> 0 | J12: =IFERROR(G12*'2022年全年财务报表'!$E$154,0) -> 0 | K12: =G12*'2022年全年财务报表'!$G$154 -> 0 | L12: =G12*'2022年全年财务报表'!$I$154 -> 0 | M12: =G12*'2022年全年财务报表'!$O$154 -> 0 | N12: =G12*'2022年全年财务报表'!$Q$154 -> 0 | O12: =G12*'2022年全年财务报表'!$S$154 -> 0 | P12: =IFERROR(I12/W12*R12,0) -> 0 | Q12: =IFERROR(P12/G12,0) -> 0 | R12: =SUMIF('船长每月数据(2023年)'!C:C,"BBQ",'船长每月数据(2023年)'!AA:AA)/SUMIF('船长每月数据(2023年)'!C:C,"BBQ",'船长每月数据(2023年)'!AD:AD)*年目标!$B$18 -> #DIV/0! | S12: =IFERROR(P12/I12,0) -> 0 | T12: =IFERROR(P12/H12,0) -> 0 | U12: =G12*'2022年全年财务报表'!$K$154 -> 0 | V12: =IFERROR(U12/G12,0) -> 0 | W12: =SUMIF('船长每月数据(2023年)'!C:C,"BBQ",'船长每月数据(2023年)'!P:P)/SUMIF('船长每月数据(2023年)'!C:C,"BBQ",'船长每月数据(2023年)'!H:H) -> #DIV/0! | X12: =IFERROR(G12+J12+K12+L12+M12+N12+O12+P12+U12,0) -> 0 | Y12: =IFERROR(X12/G12,0) -> 0
G13: =SUMIF(每月目标分解!E:E,F:F,每月目标分解!R:R)*年目标!$B$18 -> 0 | H13: =IFERROR(SUMIF(F:F,每月目标分解!E:E,每月目标分解!R:R)/SUMIF(F:F,单品目标年销量!E:E,单品目标年销量!F:F),0) -> 0 | I13: =H13*0.4 -> 0 | J13: =IFERROR(G13*'2022年全年财务报表'!$E$154,0) -> 0 | K13: =G13*'2022年全年财务报表'!$G$154 -> 0 | L13: =G13*'2022年全年财务报表'!$I$154 -> 0 | M13: =G13*'2022年全年财务报表'!$O$154 -> 0 | N13: =G13*'2022年全年财务报表'!$Q$154 -> 0 | O13: =G13*'2022年全年财务报表'!$S$154 -> 0 | P13: =IFERROR(I13/W13*R13,0) -> 0 | Q13: =IFERROR(P13/G13,0) -> 0 | R13: =SUMIF('船长每月数据(2023年)'!C:C,"BBQ",'船长每月数据(2023年)'!AA:AA)/SUMIF('船长每月数据(2023年)'!C:C,"BBQ",'船长每月数据(2023年)'!AD:AD)*年目标!$B$18 -> #DIV/0! | S13: =IFERROR(P13/I13,0) -> 0 | T13: =IFERROR(P13/H13,0) -> 0 | U13: =G13*'2022年全年财务报表'!$K$154 -> 0 | V13: =IFERROR(U13/G13,0) -> 0 | W13: 0.1399 | X13: =IFERROR(G13+J13+K13+L13+M13+N13+O13+P13+U13,0) -> 0 | Y13: =IFERROR(X13/G13,0) -> 0
G14: =SUMIF(每月目标分解!E:E,F:F,每月目标分解!R:R)*年目标!$B$18 -> 0 | H14: =IFERROR(SUMIF(F:F,每月目标分解!E:E,每月目标分解!R:R)/SUMIF(F:F,单品目标年销量!E:E,单品目标年销量!F:F),0) -> 0 | I14: =IFERROR(SUMIF(D:D,D:D,H:H)*(SUMIF('船长每月数据(2023年)'!E:E,D:D,'船长每月数据(2023年)'!AI:AI)/SUMIF('船长每月数据(2023年)'!E:E,D:D,'船长每月数据(2023年)'!P:P)),0) -> 0 | J14: =SUMIF(D:D,D:D,G:G)*SUMIF('2022年全年财务报表'!A:A,C:C,'2022年全年财务报表'!E:E) -> 0 | K14: =SUMIF(D:D,D:D,G:G)*SUMIF('2022年全年财务报表'!A:A,C:C,'2022年全年财务报表'!G:G) -> 0 | L14: =SUMIF(D:D,D:D,G:G)*SUMIF('2022年全年财务报表'!A:A,C:C,'2022年全年财务报表'!I:I) -> 0 | M14: =SUMIF(D:D,D:D,G:G)*SUMIF('2022年全年财务报表'!A:A,C:C,'2022年全年财务报表'!O:O) -> 0 | N14: =SUMIF(D:D,D:D,G:G)*SUMIF('2022年全年财务报表'!A:A,C:C,'2022年全年财务报表'!Q:Q) -> 0 | O14: =SUMIF(D:D,D:D,G:G)*SUMIF('2022年全年财务报表'!A:A,C:C,'2022年全年财务报表'!S:S) -> 0 | P14: =IFERROR(I14/W14*R14,0)/1.5 -> 0 | Q14: =IFERROR(P14/G14,0) -> 0 | R14: =IFERROR(SUMIF('2021&2022营销成本概况'!C:C,D:D,'2021&2022营销成本概况'!S:S)+SUMIF('2021&2022营销成本概况'!C:C,D:D,'2021&2022营销成本概况'!S:S)*'2021&2022营销成本概况'!$T$37,0)*年目标!$B$18 -> 0 | S14: =IFERROR(P14/I14,0) -> 0 | T14: =IFERROR(P14/H14,0) -> 0 | U14: =SUMIF(D:D,D:D,G:G)*SUMIF('2022年全年财务报表'!A:A,C:C,'2022年全年财务报表'!K:K)/2 -> 0 | V14: =IFERROR(U14/G14,0) -> 0 | W14: =IFERROR(SUMIF('船长每月数据(2023年)'!E:E,D:D,'船长每月数据(2023年)'!P:P)/SUMIF('船长每月数据(2023年)'!E:E,D:D,'船长每月数据(2023年)'!H:H),0) -> 0 | X14: =IFERROR(G14+J14+K14+L14+M14+N14+O14+P14+U14,0) -> 0 | Y14: =IFERROR(X14/G14,0) -> 0
G15: =SUMIF(每月目标分解!E:E,F:F,每月目标分解!R:R)*年目标!$B$18 -> 0 | H15: =IFERROR(SUMIF(F:F,每月目标分解!E:E,每月目标分解!R:R)/SUMIF(F:F,单品目标年销量!E:E,单品目标年销量!F:F),0) -> 0 | I15: =IFERROR(SUMIF(D:D,D:D,H:H)*(SUMIF('船长每月数据(2023年)'!E:E,D:D,'船长每月数据(2023年)'!AI:AI)/SUMIF('船长每月数据(2023年)'!E:E,D:D,'船长每月数据(2023年)'!P:P)),0) -> 0 | J15: =SUMIF(D:D,D:D,G:G)*SUMIF('2022年全年财务报表'!A:A,C:C,'2022年全年财务报表'!E:E) -> 0 | K15: =SUMIF(D:D,D:D,G:G)*SUMIF('2022年全年财务报表'!A:A,C:C,'2022年全年财务报表'!G:G) -> 0 | L15: =SUMIF(D:D,D:D,G:G)*SUMIF('2022年全年财务报表'!A:A,C:C,'2022年全年财务报表'!I:I) -> 0 | M15: =SUMIF(D:D,D:D,G:G)*SUMIF('2022年全年财务报表'!A:A,C:C,'2022年全年财务报表'!O:O) -> 0 | N15: =SUMIF(D:D,D:D,G:G)*SUMIF('2022年全年财务报表'!A:A,C:C,'2022年全年财务报表'!Q:Q) -> 0 | O15: =SUMIF(D:D,D:D,G:G)*SUMIF('2022年全年财务报表'!A:A,C:C,'2022年全年财务报表'!S:S) -> 0 | P15: =IFERROR(I15/W15*R15,0) -> 0 | Q15: =IFERROR(P15/G15,0) -> 0 | R15: =IFERROR(SUMIF('2021&2022营销成本概况'!C:C,D:D,'2021&2022营销成本概况'!S:S)+SUMIF('2021&2022营销成本概况'!C:C,D:D,'2021&2022营销成本概况'!S:S)*'2021&2022营销成本概况'!$T$37,0)*年目标!$B$18 -> 0 | S15: =IFERROR(P15/I15,0) -> 0 | T15: =IFERROR(P15/H15,0) -> 0 | U15: =SUMIF(D:D,D:D,G:G)*SUMIF('2022年全年财务报表'!A:A,C:C,'2022年全年财务报表'!K:K) -> 0 | V15: =IFERROR(U15/G15,0) -> 0 | W15: =IFERROR(SUMIF('船长每月数据(2023年)'!E:E,D:D,'船长每月数据(2023年)'!P:P)/SUMIF('船长每月数据(2023年)'!E:E,D:D,'船长每月数据(2023年)'!H:H),0) -> 0 | X15: =IFERROR(G15+J15+K15+L15+M15+N15+O15+P15+U15,0) -> 0 | Y15: =IFERROR(X15/G15,0) -> 0
G16: =SUMIF(每月目标分解!E:E,F:F,每月目标分解!R:R)*年目标!$B$18 -> 0 | H16: =IFERROR(SUMIF(F:F,每月目标分解!E:E,每月目标分解!R:R)/SUMIF(F:F,单品目标年销量!E:E,单品目标年销量!F:F),0) -> 0 | I16: =IFERROR(SUMIF(D:D,D:D,H:H)*(SUMIF('船长每月数据(2023年)'!E:E,D:D,'船长每月数据(2023年)'!AI:AI)/SUMIF('船长每月数据(2023年)'!E:E,D:D,'船长每月数据(2023年)'!P:P)),0) -> 0 | J16: =SUMIF(D:D,D:D,G:G)*SUMIF('2022年全年财务报表'!A:A,C:C,'2022年全年财务报表'!E:E) -> 0 | K16: =SUMIF(D:D,D:D,G:G)*SUMIF('2022年全年财务报表'!A:A,C:C,'2022年全年财务报表'!G:G) -> 0 | L16: =SUMIF(D:D,D:D,G:G)*SUMIF('2022年全年财务报表'!A:A,C:C,'2022年全年财务报表'!I:I) -> 0 | M16: =SUMIF(D:D,D:D,G:G)*SUMIF('2022年全年财务报表'!A:A,C:C,'2022年全年财务报表'!O:O) -> 0 | N16: =SUMIF(D:D,D:D,G:G)*SUMIF('2022年全年财务报表'!A:A,C:C,'2022年全年财务报表'!Q:Q) -> 0 | O16: =SUMIF(D:D,D:D,G:G)*SUMIF('2022年全年财务报表'!A:A,C:C,'2022年全年财务报表'!S:S) -> 0 | P16: =IFERROR(I16/W16*R16,0)/1.2 -> 0 | Q16: =IFERROR(P16/G16,0) -> 0 | R16: =IFERROR(SUMIF('2021&2022营销成本概况'!C:C,D:D,'2021&2022营销成本概况'!S:S)+SUMIF('2021&2022营销成本概况'!C:C,D:D,'2021&2022营销成本概况'!S:S)*'2021&2022营销成本概况'!$T$37,0)*年目标!$B$18 -> 0 | S16: =IFERROR(P16/I16,0) -> 0 | T16: =IFERROR(P16/H16,0) -> 0 | U16: =SUMIF(D:D,D:D,G:G)*SUMIF('2022年全年财务报表'!A:A,C:C,'2022年全年财务报表'!K:K)/1.2 -> 0 | V16: =IFERROR(U16/G16,0) -> 0 | W16: =IFERROR(SUMIF('船长每月数据(2023年)'!E:E,D:D,'船长每月数据(2023年)'!P:P)/SUMIF('船长每月数据(2023年)'!E:E,D:D,'船长每月数据(2023年)'!H:H),0) -> 0 | X16: =IFERROR(G16+J16+K16+L16+M16+N16+O16+P16+U16,0) -> 0 | Y16: =IFERROR(X16/G16,0) -> 0
G17: =SUMIF(每月目标分解!E:E,F:F,每月目标分解!R:R)*年目标!$B$18 -> 0 | H17: =IFERROR(SUMIF(F:F,每月目标分解!E:E,每月目标分解!R:R)/SUMIF(F:F,单品目标年销量!E:E,单品目标年销量!F:F),0) -> 0 | I17: =IFERROR(SUMIF(D:D,D:D,H:H)*(SUMIF('船长每月数据(2023年)'!E:E,D:D,'船长每月数据(2023年)'!AI:AI)/SUMIF('船长每月数据(2023年)'!E:E,D:D,'船长每月数据(2023年)'!P:P)),0) -> 0 | J17: =SUMIF(D:D,D:D,G:G)*SUMIF('2022年全年财务报表'!A:A,C:C,'2022年全年财务报表'!E:E) -> 0 | K17: =SUMIF(D:D,D:D,G:G)*SUMIF('2022年全年财务报表'!A:A,C:C,'2022年全年财务报表'!G:G) -> 0 | L17: =SUMIF(D:D,D:D,G:G)*SUMIF('2022年全年财务报表'!A:A,C:C,'2022年全年财务报表'!I:I) -> 0 | M17: =SUMIF(D:D,D:D,G:G)*SUMIF('2022年全年财务报表'!A:A,C:C,'2022年全年财务报表'!O:O) -> 0 | N17: =SUMIF(D:D,D:D,G:G)*SUMIF('2022年全年财务报表'!A:A,C:C,'2022年全年财务报表'!Q:Q) -> 0 | O17: =SUMIF(D:D,D:D,G:G)*SUMIF('2022年全年财务报表'!A:A,C:C,'2022年全年财务报表'!S:S) -> 0 | P17: =IFERROR(I17/W17*R17,0) -> 0 | Q17: =IFERROR(P17/G17,0) -> 0 | R17: =IFERROR(SUMIF('2021&2022营销成本概况'!C:C,D:D,'2021&2022营销成本概况'!S:S)+SUMIF('2021&2022营销成本概况'!C:C,D:D,'2021&2022营销成本概况'!S:S)*'2021&2022营销成本概况'!$T$37,0)*年目标!$B$18 -> 0 | S17: =IFERROR(P17/I17,0) -> 0 | T17: =IFERROR(P17/H17,0) -> 0 | U17: =SUMIF(D:D,D:D,G:G)*SUMIF('2022年全年财务报表'!A:A,C:C,'2022年全年财务报表'!K:K) -> 0 | V17: =IFERROR(U17/G17,0) -> 0 | W17: =IFERROR(SUMIF('船长每月数据(2023年)'!E:E,D:D,'船长每月数据(2023年)'!P:P)/SUMIF('船长每月数据(2023年)'!E:E,D:D,'船长每月数据(2023年)'!H:H),0) -> 0 | X17: =IFERROR(G17+J17+K17+L17+M17+N17+O17+P17+U17,0) -> 0 | Y17: =IFERROR(X17/G17,0) -> 0
G18: =SUMIF(每月目标分解!E:E,F:F,每月目标分解!R:R)*年目标!$B$18 -> 0 | H18: =IFERROR(SUMIF(F:F,每月目标分解!E:E,每月目标分解!R:R)/SUMIF(F:F,单品目标年销量!E:E,单品目标年销量!F:F),0) -> 0 | I18: =IFERROR(SUMIF(D:D,D:D,H:H)*(SUMIF('船长每月数据(2023年)'!E:E,D:D,'船长每月数据(2023年)'!AI:AI)/SUMIF('船长每月数据(2023年)'!E:E,D:D,'船长每月数据(2023年)'!P:P)),0) -> 0 | J18: =SUMIF(D:D,D:D,G:G)*SUMIF('2022年全年财务报表'!A:A,C:C,'2022年全年财务报表'!E:E) -> 0 | K18: =SUMIF(D:D,D:D,G:G)*SUMIF('2022年全年财务报表'!A:A,C:C,'2022年全年财务报表'!G:G) -> 0 | L18: =SUMIF(D:D,D:D,G:G)*SUMIF('2022年全年财务报表'!A:A,C:C,'2022年全年财务报表'!I:I) -> 0 | M18: =SUMIF(D:D,D:D,G:G)*SUMIF('2022年全年财务报表'!A:A,C:C,'2022年全年财务报表'!O:O) -> 0 | N18: =SUMIF(D:D,D:D,G:G)*SUMIF('2022年全年财务报表'!A:A,C:C,'2022年全年财务报表'!Q:Q) -> 0 | O18: =SUMIF(D:D,D:D,G:G)*SUMIF('2022年全年财务报表'!A:A,C:C,'2022年全年财务报表'!S:S) -> 0 | P18: =IFERROR(I18/W18*R18,0) -> 0 | Q18: =IFERROR(P18/G18,0) -> 0 | R18: =IFERROR(SUMIF('2021&2022营销成本概况'!C:C,D:D,'2021&2022营销成本概况'!S:S)+SUMIF('2021&2022营销成本概况'!C:C,D:D,'2021&2022营销成本概况'!S:S)*'2021&2022营销成本概况'!$T$37,0)*年目标!$B$18 -> 0 | S18: =IFERROR(P18/I18,0) -> 0 | T18: =IFERROR(P18/H18,0) -> 0 | U18: =SUMIF(D:D,D:D,G:G)*SUMIF('2022年全年财务报表'!A:A,C:C,'2022年全年财务报表'!K:K) -> 0 | V18: =IFERROR(U18/G18,0) -> 0 | W18: =IFERROR(SUMIF('船长每月数据(2023年)'!E:E,D:D,'船长每月数据(2023年)'!P:P)/SUMIF('船长每月数据(2023年)'!E:E,D:D,'船长每月数据(2023年)'!H:H),0) -> 0 | X18: =IFERROR(G18+J18+K18+L18+M18+N18+O18+P18+U18,0) -> 0 | Y18: =IFERROR(X18/G18,0) -> 0
G19: =SUMIF(每月目标分解!E:E,F:F,每月目标分解!R:R)*年目标!$B$18 -> 0 | H19: =IFERROR(SUMIF(F:F,每月目标分解!E:E,每月目标分解!R:R)/SUMIF(F:F,单品目标年销量!E:E,单品目标年销量!F:F),0) -> 0 | I19: =IFERROR(SUMIF(D:D,D:D,H:H)*(SUMIF('船长每月数据(2023年)'!E:E,D:D,'船长每月数据(2023年)'!AI:AI)/SUMIF('船长每月数据(2023年)'!E:E,D:D,'船长每月数据(2023年)'!P:P)),0) -> 0 | J19: =SUMIF(D:D,D:D,G:G)*SUMIF('2022年全年财务报表'!A:A,C:C,'2022年全年财务报表'!E:E) -> 0 | K19: =SUMIF(D:D,D:D,G:G)*SUMIF('2022年全年财务报表'!A:A,C:C,'2022年全年财务报表'!G:G) -> 0 | L19: =SUMIF(D:D,D:D,G:G)*SUMIF('2022年全年财务报表'!A:A,C:C,'2022年全年财务报表'!I:I) -> 0 | M19: =SUMIF(D:D,D:D,G:G)*SUMIF('2022年全年财务报表'!A:A,C:C,'2022年全年财务报表'!O:O) -> 0 | N19: =SUMIF(D:D,D:D,G:G)*SUMIF('2022年全年财务报表'!A:A,C:C,'2022年全年财务报表'!Q:Q) -> 0 | O19: =SUMIF(D:D,D:D,G:G)*SUMIF('2022年全年财务报表'!A:A,C:C,'2022年全年财务报表'!S:S) -> 0 | P19: =IFERROR(I19/W19*R19,0)*0 -> 0 | Q19: =IFERROR(P19/G19,0) -> 0 | R19: =IFERROR(SUMIF('2021&2022营销成本概况'!C:C,D:D,'2021&2022营销成本概况'!S:S)+SUMIF('2021&2022营销成本概况'!C:C,D:D,'2021&2022营销成本概况'!S:S)*'2021&2022营销成本概况'!$T$37,0)*年目标!$B$18 -> 0 | S19: =IFERROR(P19/I19,0) -> 0 | T19: =IFERROR(P19/H19,0) -> 0 | U19: =SUMIF(D:D,D:D,G:G)*SUMIF('2022年全年财务报表'!A:A,C:C,'2022年全年财务报表'!K:K)/2 -> 0 | V19: =IFERROR(U19/G19,0) -> 0 | W19: =IFERROR(SUMIF('船长每月数据(2023年)'!E:E,D:D,'船长每月数据(2023年)'!P:P)/SUMIF('船长每月数据(2023年)'!E:E,D:D,'船长每月数据(2023年)'!H:H),0) -> 0 | X19: =IFERROR(G19+J19+K19+L19+M19+N19+O19+P19+U19,0) -> 0 | Y19: =IFERROR(X19/G19,0) -> 0
G20: =SUMIF(每月目标分解!E:E,F:F,每月目标分解!R:R)*年目标!$B$18 -> 0 | H20: =IFERROR(SUMIF(F:F,每月目标分解!E:E,每月目标分解!R:R)/SUMIF(F:F,单品目标年销量!E:E,单品目标年销量!F:F),0) -> 0 | I20: =IFERROR(SUMIF(D:D,D:D,H:H)*(SUMIF('船长每月数据(2023年)'!E:E,D:D,'船长每月数据(2023年)'!AI:AI)/SUMIF('船长每月数据(2023年)'!E:E,D:D,'船长每月数据(2023年)'!P:P)),0) -> 0 | J20: =SUMIF(D:D,D:D,G:G)*SUMIF('2022年全年财务报表'!A:A,C:C,'2022年全年财务报表'!E:E) -> 0 | K20: =SUMIF(D:D,D:D,G:G)*SUMIF('2022年全年财务报表'!A:A,C:C,'2022年全年财务报表'!G:G) -> 0 | L20: =SUMIF(D:D,D:D,G:G)*SUMIF('2022年全年财务报表'!A:A,C:C,'2022年全年财务报表'!I:I) -> 0 | M20: =SUMIF(D:D,D:D,G:G)*SUMIF('2022年全年财务报表'!A:A,C:C,'2022年全年财务报表'!O:O) -> 0 | N20: =SUMIF(D:D,D:D,G:G)*SUMIF('2022年全年财务报表'!A:A,C:C,'2022年全年财务报表'!Q:Q) -> 0 | O20: =SUMIF(D:D,D:D,G:G)*SUMIF('2022年全年财务报表'!A:A,C:C,'2022年全年财务报表'!S:S) -> 0 | P20: =IFERROR(I20/W20*R20,0) -> 0 | Q20: =IFERROR(P20/G20,0) -> 0 | R20: =IFERROR(SUMIF('2021&2022营销成本概况'!C:C,D:D,'2021&2022营销成本概况'!S:S)+SUMIF('2021&2022营销成本概况'!C:C,D:D,'2021&2022营销成本概况'!S:S)*'2021&2022营销成本概况'!$T$37,0)*年目标!$B$18 -> 0 | S20: =IFERROR(P20/I20,0) -> 0 | T20: =IFERROR(P20/H20,0) -> 0 | U20: =SUMIF(D:D,D:D,G:G)*SUMIF('2022年全年财务报表'!A:A,C:C,'2022年全年财务报表'!K:K) -> 0 | V20: =IFERROR(U20/G20,0) -> 0 | W20: =IFERROR(SUMIF('船长每月数据(2023年)'!E:E,D:D,'船长每月数据(2023年)'!P:P)/SUMIF('船长每月数据(2023年)'!E:E,D:D,'船长每月数据(2023年)'!H:H),0) -> 0 | X20: =IFERROR(G20+J20+K20+L20+M20+N20+O20+P20+U20,0) -> 0 | Y20: =IFERROR(X20/G20,0) -> 0
G21: =SUMIF(每月目标分解!E:E,F:F,每月目标分解!R:R)*年目标!$B$18 -> 0 | H21: =IFERROR(SUMIF(F:F,每月目标分解!E:E,每月目标分解!R:R)/SUMIF(F:F,单品目标年销量!E:E,单品目标年销量!F:F),0) -> 0 | I21: =IFERROR(SUMIF(D:D,D:D,H:H)*(SUMIF('船长每月数据(2023年)'!E:E,D:D,'船长每月数据(2023年)'!AI:AI)/SUMIF('船长每月数据(2023年)'!E:E,D:D,'船长每月数据(2023年)'!P:P)),0) -> 0 | J21: =SUMIF(D:D,D:D,G:G)*SUMIF('2022年全年财务报表'!A:A,C:C,'2022年全年财务报表'!E:E) -> 0 | K21: =SUMIF(D:D,D:D,G:G)*SUMIF('2022年全年财务报表'!A:A,C:C,'2022年全年财务报表'!G:G) -> 0 | L21: =SUMIF(D:D,D:D,G:G)*SUMIF('2022年全年财务报表'!A:A,C:C,'2022年全年财务报表'!I:I) -> 0 | M21: =SUMIF(D:D,D:D,G:G)*SUMIF('2022年全年财务报表'!A:A,C:C,'2022年全年财务报表'!O:O) -> 0 | N21: =SUMIF(D:D,D:D,G:G)*SUMIF('2022年全年财务报表'!A:A,C:C,'2022年全年财务报表'!Q:Q) -> 0 | O21: =SUMIF(D:D,D:D,G:G)*SUMIF('2022年全年财务报表'!A:A,C:C,'2022年全年财务报表'!S:S) -> 0 | P21: =IFERROR(I21/W21*R21,0) -> 0 | Q21: =IFERROR(P21/G21,0) -> 0 | R21: =IFERROR(SUMIF('2021&2022营销成本概况'!C:C,D:D,'2021&2022营销成本概况'!S:S)+SUMIF('2021&2022营销成本概况'!C:C,D:D,'2021&2022营销成本概况'!S:S)*'2021&2022营销成本概况'!$T$37,0)*年目标!$B$18 -> 0 | S21: =IFERROR(P21/I21,0) -> 0 | T21: =IFERROR(P21/H21,0) -> 0 | U21: =SUMIF(D:D,D:D,G:G)*SUMIF('2022年全年财务报表'!A:A,C:C,'2022年全年财务报表'!K:K) -> 0 | V21: =IFERROR(U21/G21,0) -> 0 | W21: =IFERROR(SUMIF('船长每月数据(2023年)'!E:E,D:D,'船长每月数据(2023年)'!P:P)/SUMIF('船长每月数据(2023年)'!E:E,D:D,'船长每月数据(2023年)'!H:H),0) -> 0 | X21: =IFERROR(G21+J21+K21+L21+M21+N21+O21+P21+U21,0) -> 0 | Y21: =IFERROR(X21/G21,0) -> 0
G22: =SUMIF(每月目标分解!E:E,F:F,每月目标分解!R:R)*年目标!$B$18 -> 0 | H22: =IFERROR(SUMIF(F:F,每月目标分解!E:E,每月目标分解!R:R)/SUMIF(F:F,单品目标年销量!E:E,单品目标年销量!F:F),0) -> 0 | I22: =IFERROR(SUMIF(D:D,D:D,H:H)*(SUMIF('船长每月数据(2023年)'!E:E,D:D,'船长每月数据(2023年)'!AI:AI)/SUMIF('船长每月数据(2023年)'!E:E,D:D,'船长每月数据(2023年)'!P:P)),0) -> 0 | J22: =SUMIF(D:D,D:D,G:G)*SUMIF('2022年全年财务报表'!A:A,C:C,'2022年全年财务报表'!E:E) -> 0 | K22: =SUMIF(D:D,D:D,G:G)*SUMIF('2022年全年财务报表'!A:A,C:C,'2022年全年财务报表'!G:G) -> 0 | L22: =SUMIF(D:D,D:D,G:G)*SUMIF('2022年全年财务报表'!A:A,C:C,'2022年全年财务报表'!I:I) -> 0 | M22: =SUMIF(D:D,D:D,G:G)*SUMIF('2022年全年财务报表'!A:A,C:C,'2022年全年财务报表'!O:O) -> 0 | N22: =SUMIF(D:D,D:D,G:G)*SUMIF('2022年全年财务报表'!A:A,C:C,'2022年全年财务报表'!Q:Q) -> 0 | O22: =SUMIF(D:D,D:D,G:G)*SUMIF('2022年全年财务报表'!A:A,C:C,'2022年全年财务报表'!S:S) -> 0 | P22: =IFERROR(I22/W22*R22,0)/2.5 -> 0 | Q22: =IFERROR(P22/G22,0) -> 0 | R22: =IFERROR(SUMIF('2021&2022营销成本概况'!C:C,D:D,'2021&2022营销成本概况'!S:S)+SUMIF('2021&2022营销成本概况'!C:C,D:D,'2021&2022营销成本概况'!S:S)*'2021&2022营销成本概况'!$T$37,0)*年目标!$B$18 -> 0 | S22: =IFERROR(P22/I22,0) -> 0 | T22: =IFERROR(P22/H22,0) -> 0 | U22: =SUMIF(D:D,D:D,G:G)*SUMIF('2022年全年财务报表'!A:A,C:C,'2022年全年财务报表'!K:K)/1.2 -> 0 | V22: =IFERROR(U22/G22,0) -> 0 | W22: =IFERROR(SUMIF('船长每月数据(2023年)'!E:E,D:D,'船长每月数据(2023年)'!P:P)/SUMIF('船长每月数据(2023年)'!E:E,D:D,'船长每月数据(2023年)'!H:H),0) -> 0 | X22: =IFERROR(G22+J22+K22+L22+M22+N22+O22+P22+U22,0) -> 0 | Y22: =IFERROR(X22/G22,0) -> 0
G23: =SUMIF(每月目标分解!E:E,F:F,每月目标分解!R:R)*年目标!$B$18 -> 0 | H23: =IFERROR(SUMIF(F:F,每月目标分解!E:E,每月目标分解!R:R)/SUMIF(F:F,单品目标年销量!E:E,单品目标年销量!F:F),0) -> 0 | I23: =IFERROR(SUMIF(D:D,D:D,H:H)*(SUMIF('船长每月数据(2023年)'!E:E,D:D,'船长每月数据(2023年)'!AI:AI)/SUMIF('船长每月数据(2023年)'!E:E,D:D,'船长每月数据(2023年)'!P:P)),0) -> 0 | J23: =SUMIF(D:D,D:D,G:G)*SUMIF('2022年全年财务报表'!A:A,C:C,'2022年全年财务报表'!E:E) -> 0 | K23: =SUMIF(D:D,D:D,G:G)*SUMIF('2022年全年财务报表'!A:A,C:C,'2022年全年财务报表'!G:G) -> 0 | L23: =SUMIF(D:D,D:D,G:G)*SUMIF('2022年全年财务报表'!A:A,C:C,'2022年全年财务报表'!I:I) -> 0 | M23: =SUMIF(D:D,D:D,G:G)*SUMIF('2022年全年财务报表'!A:A,C:C,'2022年全年财务报表'!O:O) -> 0 | N23: =SUMIF(D:D,D:D,G:G)*SUMIF('2022年全年财务报表'!A:A,C:C,'2022年全年财务报表'!Q:Q) -> 0 | O23: =SUMIF(D:D,D:D,G:G)*SUMIF('2022年全年财务报表'!A:A,C:C,'2022年全年财务报表'!S:S) -> 0 | P23: =IFERROR(I23/W23*R23,0)/2.5 -> 0 | Q23: =IFERROR(P23/G23,0) -> 0 | R23: =IFERROR(SUMIF('2021&2022营销成本概况'!C:C,D:D,'2021&2022营销成本概况'!S:S)+SUMIF('2021&2022营销成本概况'!C:C,D:D,'2021&2022营销成本概况'!S:S)*'2021&2022营销成本概况'!$T$37,0)*年目标!$B$18 -> 0 | S23: =IFERROR(P23/I23,0) -> 0 | T23: =IFERROR(P23/H23,0) -> 0 | U23: =SUMIF(D:D,D:D,G:G)*SUMIF('2022年全年财务报表'!A:A,C:C,'2022年全年财务报表'!K:K)/1.2 -> 0 | V23: =IFERROR(U23/G23,0) -> 0 | W23: =IFERROR(SUMIF('船长每月数据(2023年)'!E:E,D:D,'船长每月数据(2023年)'!P:P)/SUMIF('船长每月数据(2023年)'!E:E,D:D,'船长每月数据(2023年)'!H:H),0) -> 0 | X23: =IFERROR(G23+J23+K23+L23+M23+N23+O23+P23+U23,0) -> 0 | Y23: =IFERROR(X23/G23,0) -> 0
G24: =SUMIF(每月目标分解!E:E,F:F,每月目标分解!R:R)*年目标!$B$18 -> 0 | H24: =IFERROR(SUMIF(F:F,每月目标分解!E:E,每月目标分解!R:R)/SUMIF(F:F,单品目标年销量!E:E,单品目标年销量!F:F),0) -> 0 | I24: =IFERROR(SUMIF(D:D,D:D,H:H)*(SUMIF('船长每月数据(2023年)'!E:E,D:D,'船长每月数据(2023年)'!AI:AI)/SUMIF('船长每月数据(2023年)'!E:E,D:D,'船长每月数据(2023年)'!P:P)),0) -> 0 | J24: =SUMIF(D:D,D:D,G:G)*SUMIF('2022年全年财务报表'!A:A,C:C,'2022年全年财务报表'!E:E) -> 0 | K24: =SUMIF(D:D,D:D,G:G)*SUMIF('2022年全年财务报表'!A:A,C:C,'2022年全年财务报表'!G:G) -> 0 | L24: =SUMIF(D:D,D:D,G:G)*SUMIF('2022年全年财务报表'!A:A,C:C,'2022年全年财务报表'!I:I) -> 0 | M24: =SUMIF(D:D,D:D,G:G)*SUMIF('2022年全年财务报表'!A:A,C:C,'2022年全年财务报表'!O:O) -> 0 | N24: =SUMIF(D:D,D:D,G:G)*SUMIF('2022年全年财务报表'!A:A,C:C,'2022年全年财务报表'!Q:Q) -> 0 | O24: =SUMIF(D:D,D:D,G:G)*SUMIF('2022年全年财务报表'!A:A,C:C,'2022年全年财务报表'!S:S) -> 0 | P24: =IFERROR(I24/W24*R24,0)/1.2 -> 0 | Q24: =IFERROR(P24/G24,0) -> 0 | R24: =IFERROR(SUMIF('2021&2022营销成本概况'!C:C,D:D,'2021&2022营销成本概况'!S:S)+SUMIF('2021&2022营销成本概况'!C:C,D:D,'2021&2022营销成本概况'!S:S)*'2021&2022营销成本概况'!$T$37,0)*年目标!$B$18 -> 0 | S24: =IFERROR(P24/I24,0) -> 0 | T24: =IFERROR(P24/H24,0) -> 0 | U24: =SUMIF(D:D,D:D,G:G)*SUMIF('2022年全年财务报表'!A:A,C:C,'2022年全年财务报表'!K:K) -> 0 | V24: =IFERROR(U24/G24,0) -> 0 | W24: =IFERROR(SUMIF('船长每月数据(2023年)'!E:E,D:D,'船长每月数据(2023年)'!P:P)/SUMIF('船长每月数据(2023年)'!E:E,D:D,'船长每月数据(2023年)'!H:H),0) -> 0 | X24: =IFERROR(G24+J24+K24+L24+M24+N24+O24+P24+U24,0) -> 0 | Y24: =IFERROR(X24/G24,0) -> 0
G25: =SUMIF(每月目标分解!E:E,F:F,每月目标分解!R:R)*年目标!$B$18 -> 0 | H25: =IFERROR(SUMIF(F:F,每月目标分解!E:E,每月目标分解!R:R)/SUMIF(F:F,单品目标年销量!E:E,单品目标年销量!F:F),0) -> 0 | I25: =IFERROR(SUMIF(D:D,D:D,H:H)*(SUMIF('船长每月数据(2023年)'!E:E,D:D,'船长每月数据(2023年)'!AI:AI)/SUMIF('船长每月数据(2023年)'!E:E,D:D,'船长每月数据(2023年)'!P:P)),0) -> 0 | J25: =SUMIF(D:D,D:D,G:G)*SUMIF('2022年全年财务报表'!A:A,C:C,'2022年全年财务报表'!E:E) -> 0 | K25: =SUMIF(D:D,D:D,G:G)*SUMIF('2022年全年财务报表'!A:A,C:C,'2022年全年财务报表'!G:G) -> 0 | L25: =SUMIF(D:D,D:D,G:G)*SUMIF('2022年全年财务报表'!A:A,C:C,'2022年全年财务报表'!I:I) -> 0 | M25: =SUMIF(D:D,D:D,G:G)*SUMIF('2022年全年财务报表'!A:A,C:C,'2022年全年财务报表'!O:O) -> 0 | N25: =SUMIF(D:D,D:D,G:G)*SUMIF('2022年全年财务报表'!A:A,C:C,'2022年全年财务报表'!Q:Q) -> 0 | O25: =SUMIF(D:D,D:D,G:G)*SUMIF('2022年全年财务报表'!A:A,C:C,'2022年全年财务报表'!S:S) -> 0 | P25: =IFERROR(I25/W25*R25,0) -> 0 | Q25: =IFERROR(P25/G25,0) -> 0 | R25: =IFERROR(SUMIF('2021&2022营销成本概况'!C:C,D:D,'2021&2022营销成本概况'!S:S)+SUMIF('2021&2022营销成本概况'!C:C,D:D,'2021&2022营销成本概况'!S:S)*'2021&2022营销成本概况'!$T$37,0)*年目标!$B$18 -> 0 | S25: =IFERROR(P25/I25,0) -> 0 | T25: =IFERROR(P25/H25,0) -> 0 | U25: =SUMIF(D:D,D:D,G:G)*SUMIF('2022年全年财务报表'!A:A,C:C,'2022年全年财务报表'!K:K) -> 0 | V25: =IFERROR(U25/G25,0) -> 0 | W25: =IFERROR(SUMIF('船长每月数据(2023年)'!E:E,D:D,'船长每月数据(2023年)'!P:P)/SUMIF('船长每月数据(2023年)'!E:E,D:D,'船长每月数据(2023年)'!H:H),0) -> 0 | X25: =IFERROR(G25+J25+K25+L25+M25+N25+O25+P25+U25,0) -> 0 | Y25: =IFERROR(X25/G25,0) -> 0
G26: =SUMIF(每月目标分解!E:E,F:F,每月目标分解!R:R)*年目标!$B$18 -> 0 | H26: =IFERROR(SUMIF(F:F,每月目标分解!E:E,每月目标分解!R:R)/SUMIF(F:F,单品目标年销量!E:E,单品目标年销量!F:F),0) -> 0 | I26: =IFERROR(SUMIF(D:D,D:D,H:H)*(SUMIF('船长每月数据(2023年)'!E:E,D:D,'船长每月数据(2023年)'!AI:AI)/SUMIF('船长每月数据(2023年)'!E:E,D:D,'船长每月数据(2023年)'!P:P)),0) -> 0 | J26: =SUMIF(D:D,D:D,G:G)*SUMIF('2022年全年财务报表'!A:A,C:C,'2022年全年财务报表'!E:E) -> 0 | K26: =SUMIF(D:D,D:D,G:G)*SUMIF('2022年全年财务报表'!A:A,C:C,'2022年全年财务报表'!G:G) -> 0 | L26: =SUMIF(D:D,D:D,G:G)*SUMIF('2022年全年财务报表'!A:A,C:C,'2022年全年财务报表'!I:I) -> 0 | M26: =SUMIF(D:D,D:D,G:G)*SUMIF('2022年全年财务报表'!A:A,C:C,'2022年全年财务报表'!O:O) -> 0 | N26: =SUMIF(D:D,D:D,G:G)*SUMIF('2022年全年财务报表'!A:A,C:C,'2022年全年财务报表'!Q:Q) -> 0 | O26: =SUMIF(D:D,D:D,G:G)*SUMIF('2022年全年财务报表'!A:A,C:C,'2022年全年财务报表'!S:S) -> 0 | P26: =IFERROR(I26/W26*R26,0) -> 0 | Q26: =IFERROR(P26/G26,0) -> 0 | R26: =IFERROR(SUMIF('2021&2022营销成本概况'!C:C,D:D,'2021&2022营销成本概况'!S:S)+SUMIF('2021&2022营销成本概况'!C:C,D:D,'2021&2022营销成本概况'!S:S)*'2021&2022营销成本概况'!$T$37,0)*年目标!$B$18 -> 0 | S26: =IFERROR(P26/I26,0) -> 0 | T26: =IFERROR(P26/H26,0) -> 0 | U26: =SUMIF(D:D,D:D,G:G)*SUMIF('2022年全年财务报表'!A:A,C:C,'2022年全年财务报表'!K:K) -> 0 | V26: =IFERROR(U26/G26,0) -> 0 | W26: =IFERROR(SUMIF('船长每月数据(2023年)'!E:E,D:D,'船长每月数据(2023年)'!P:P)/SUMIF('船长每月数据(2023年)'!E:E,D:D,'船长每月数据(2023年)'!H:H),0) -> 0 | X26: =IFERROR(G26+J26+K26+L26+M26+N26+O26+P26+U26,0) -> 0 | Y26: =IFERROR(X26/G26,0) -> 0
G27: =SUMIF(每月目标分解!E:E,F:F,每月目标分解!R:R)*年目标!$B$18 -> 0 | H27: =IFERROR(SUMIF(F:F,每月目标分解!E:E,每月目标分解!R:R)/SUMIF(F:F,单品目标年销量!E:E,单品目标年销量!F:F),0) -> 0 | I27: =IFERROR(SUMIF(D:D,D:D,H:H)*(SUMIF('船长每月数据(2023年)'!E:E,D:D,'船长每月数据(2023年)'!AI:AI)/SUMIF('船长每月数据(2023年)'!E:E,D:D,'船长每月数据(2023年)'!P:P)),0) -> 0 | J27: =SUMIF(D:D,D:D,G:G)*SUMIF('2022年全年财务报表'!A:A,C:C,'2022年全年财务报表'!E:E) -> 0 | K27: =SUMIF(D:D,D:D,G:G)*SUMIF('2022年全年财务报表'!A:A,C:C,'2022年全年财务报表'!G:G) -> 0 | L27: =SUMIF(D:D,D:D,G:G)*SUMIF('2022年全年财务报表'!A:A,C:C,'2022年全年财务报表'!I:I) -> 0 | M27: =SUMIF(D:D,D:D,G:G)*SUMIF('2022年全年财务报表'!A:A,C:C,'2022年全年财务报表'!O:O) -> 0 | N27: =SUMIF(D:D,D:D,G:G)*SUMIF('2022年全年财务报表'!A:A,C:C,'2022年全年财务报表'!Q:Q) -> 0 | O27: =SUMIF(D:D,D:D,G:G)*SUMIF('2022年全年财务报表'!A:A,C:C,'2022年全年财务报表'!S:S) -> 0 | P27: =IFERROR(I27/W27*R27,0)/3.5 -> 0 | Q27: =IFERROR(P27/G27,0) -> 0 | R27: =IFERROR(SUMIF('2021&2022营销成本概况'!C:C,D:D,'2021&2022营销成本概况'!S:S)+SUMIF('2021&2022营销成本概况'!C:C,D:D,'2021&2022营销成本概况'!S:S)*'2021&2022营销成本概况'!$T$37,0)*年目标!$B$18 -> 0 | S27: =IFERROR(P27/I27,0) -> 0 | T27: =IFERROR(P27/H27,0) -> 0 | U27: =SUMIF(D:D,D:D,G:G)*SUMIF('2022年全年财务报表'!A:A,C:C,'2022年全年财务报表'!K:K)/4 -> 0 | V27: =IFERROR(U27/G27,0) -> 0 | W27: =IFERROR(SUMIF('船长每月数据(2023年)'!E:E,D:D,'船长每月数据(2023年)'!P:P)/SUMIF('船长每月数据(2023年)'!E:E,D:D,'船长每月数据(2023年)'!H:H),0) -> 0 | X27: =IFERROR(G27+J27+K27+L27+M27+N27+O27+P27+U27,0) -> 0 | Y27: =IFERROR(X27/G27,0) -> 0
G28: =SUMIF(每月目标分解!E:E,F:F,每月目标分解!R:R)*年目标!$B$18 -> 0 | H28: =IFERROR(SUMIF(F:F,每月目标分解!E:E,每月目标分解!R:R)/SUMIF(F:F,单品目标年销量!E:E,单品目标年销量!F:F),0) -> 0 | I28: =IFERROR(SUMIF(D:D,D:D,H:H)*(SUMIF('船长每月数据(2023年)'!E:E,D:D,'船长每月数据(2023年)'!AI:AI)/SUMIF('船长每月数据(2023年)'!E:E,D:D,'船长每月数据(2023年)'!P:P)),0) -> 0 | J28: =SUMIF(D:D,D:D,G:G)*SUMIF('2022年全年财务报表'!A:A,C:C,'2022年全年财务报表'!E:E) -> 0 | K28: =SUMIF(D:D,D:D,G:G)*SUMIF('2022年全年财务报表'!A:A,C:C,'2022年全年财务报表'!G:G) -> 0 | L28: =SUMIF(D:D,D:D,G:G)*SUMIF('2022年全年财务报表'!A:A,C:C,'2022年全年财务报表'!I:I) -> 0 | M28: =SUMIF(D:D,D:D,G:G)*SUMIF('2022年全年财务报表'!A:A,C:C,'2022年全年财务报表'!O:O) -> 0 | N28: =SUMIF(D:D,D:D,G:G)*SUMIF('2022年全年财务报表'!A:A,C:C,'2022年全年财务报表'!Q:Q) -> 0 | O28: =SUMIF(D:D,D:D,G:G)*SUMIF('2022年全年财务报表'!A:A,C:C,'2022年全年财务报表'!S:S) -> 0 | P28: =IFERROR(I28/W28*R28,0)/3 -> 0 | Q28: =IFERROR(P28/G28,0) -> 0 | R28: =IFERROR(SUMIF('2021&2022营销成本概况'!C:C,D:D,'2021&2022营销成本概况'!S:S)+SUMIF('2021&2022营销成本概况'!C:C,D:D,'2021&2022营销成本概况'!S:S)*'2021&2022营销成本概况'!$T$37,0)*年目标!$B$18 -> 0 | S28: =IFERROR(P28/I28,0) -> 0 | T28: =IFERROR(P28/H28,0) -> 0 | U28: =SUMIF(D:D,D:D,G:G)*SUMIF('2022年全年财务报表'!A:A,C:C,'2022年全年财务报表'!K:K)/3 -> 0 | V28: =IFERROR(U28/G28,0) -> 0 | W28: =IFERROR(SUMIF('船长每月数据(2023年)'!E:E,D:D,'船长每月数据(2023年)'!P:P)/SUMIF('船长每月数据(2023年)'!E:E,D:D,'船长每月数据(2023年)'!H:H),0) -> 0 | X28: =IFERROR(G28+J28+K28+L28+M28+N28+O28+P28+U28,0) -> 0 | Y28: =IFERROR(X28/G28,0) -> 0
G29: =SUMIF(每月目标分解!E:E,F:F,每月目标分解!R:R)*年目标!$B$18 -> 0 | H29: =IFERROR(SUMIF(F:F,每月目标分解!E:E,每月目标分解!R:R)/SUMIF(F:F,单品目标年销量!E:E,单品目标年销量!F:F),0) -> 0 | I29: =IFERROR(SUMIF(D:D,D:D,H:H)*(SUMIF('船长每月数据(2023年)'!E:E,D:D,'船长每月数据(2023年)'!AI:AI)/SUMIF('船长每月数据(2023年)'!E:E,D:D,'船长每月数据(2023年)'!P:P)),0) -> 0 | J29: =SUMIF(D:D,D:D,G:G)*SUMIF('2022年全年财务报表'!A:A,C:C,'2022年全年财务报表'!E:E) -> 0 | K29: =SUMIF(D:D,D:D,G:G)*SUMIF('2022年全年财务报表'!A:A,C:C,'2022年全年财务报表'!G:G) -> 0 | L29: =SUMIF(D:D,D:D,G:G)*SUMIF('2022年全年财务报表'!A:A,C:C,'2022年全年财务报表'!I:I) -> 0 | M29: =SUMIF(D:D,D:D,G:G)*SUMIF('2022年全年财务报表'!A:A,C:C,'2022年全年财务报表'!O:O) -> 0 | N29: =SUMIF(D:D,D:D,G:G)*SUMIF('2022年全年财务报表'!A:A,C:C,'2022年全年财务报表'!Q:Q) -> 0 | O29: =SUMIF(D:D,D:D,G:G)*SUMIF('2022年全年财务报表'!A:A,C:C,'2022年全年财务报表'!S:S) -> 0 | P29: =IFERROR(I29/W29*R29,0)/2 -> 0 | Q29: =IFERROR(P29/G29,0) -> 0 | R29: =IFERROR(SUMIF('2021&2022营销成本概况'!C:C,D:D,'2021&2022营销成本概况'!S:S)+SUMIF('2021&2022营销成本概况'!C:C,D:D,'2021&2022营销成本概况'!S:S)*'2021&2022营销成本概况'!$T$37,0)*年目标!$B$18 -> 0 | S29: =IFERROR(P29/I29,0) -> 0 | T29: =IFERROR(P29/H29,0) -> 0 | U29: =SUMIF(D:D,D:D,G:G)*SUMIF('2022年全年财务报表'!A:A,C:C,'2022年全年财务报表'!K:K)/2 -> 0 | V29: =IFERROR(U29/G29,0) -> 0 | W29: =IFERROR(SUMIF('船长每月数据(2023年)'!E:E,D:D,'船长每月数据(2023年)'!P:P)/SUMIF('船长每月数据(2023年)'!E:E,D:D,'船长每月数据(2023年)'!H:H),0) -> 0 | X29: =IFERROR(G29+J29+K29+L29+M29+N29+O29+P29+U29,0) -> 0 | Y29: =IFERROR(X29/G29,0) -> 0
G30: =SUMIF(每月目标分解!E:E,F:F,每月目标分解!R:R)*年目标!$B$18 -> 0 | H30: =IFERROR(SUMIF(F:F,每月目标分解!E:E,每月目标分解!R:R)/SUMIF(F:F,单品目标年销量!E:E,单品目标年销量!F:F),0) -> 0 | I30: =IFERROR(SUMIF(D:D,D:D,H:H)*(SUMIF('船长每月数据(2023年)'!E:E,D:D,'船长每月数据(2023年)'!AI:AI)/SUMIF('船长每月数据(2023年)'!E:E,D:D,'船长每月数据(2023年)'!P:P)),0) -> 0 | J30: =SUMIF(D:D,D:D,G:G)*SUMIF('2022年全年财务报表'!A:A,C:C,'2022年全年财务报表'!E:E) -> 0 | K30: =SUMIF(D:D,D:D,G:G)*SUMIF('2022年全年财务报表'!A:A,C:C,'2022年全年财务报表'!G:G) -> 0 | L30: =SUMIF(D:D,D:D,G:G)*SUMIF('2022年全年财务报表'!A:A,C:C,'2022年全年财务报表'!I:I) -> 0 | M30: =SUMIF(D:D,D:D,G:G)*SUMIF('2022年全年财务报表'!A:A,C:C,'2022年全年财务报表'!O:O) -> 0 | N30: =SUMIF(D:D,D:D,G:G)*SUMIF('2022年全年财务报表'!A:A,C:C,'2022年全年财务报表'!Q:Q) -> 0 | O30: =SUMIF(D:D,D:D,G:G)*SUMIF('2022年全年财务报表'!A:A,C:C,'2022年全年财务报表'!S:S) -> 0 | P30: =IFERROR(I30/W30*R30,0)/5 -> 0 | Q30: =IFERROR(P30/G30,0) -> 0 | R30: =IFERROR(SUMIF('2021&2022营销成本概况'!C:C,D:D,'2021&2022营销成本概况'!S:S)+SUMIF('2021&2022营销成本概况'!C:C,D:D,'2021&2022营销成本概况'!S:S)*'2021&2022营销成本概况'!$T$37,0)*年目标!$B$18 -> 0 | S30: =IFERROR(P30/I30,0) -> 0 | T30: =IFERROR(P30/H30,0) -> 0 | U30: =SUMIF(D:D,D:D,G:G)*SUMIF('2022年全年财务报表'!A:A,C:C,'2022年全年财务报表'!K:K) -> 0 | V30: =IFERROR(U30/G30,0) -> 0 | W30: =IFERROR(SUMIF('船长每月数据(2023年)'!E:E,D:D,'船长每月数据(2023年)'!P:P)/SUMIF('船长每月数据(2023年)'!E:E,D:D,'船长每月数据(2023年)'!H:H),0) -> 0 | X30: =IFERROR(G30+J30+K30+L30+M30+N30+O30+P30+U30,0) -> 0 | Y30: =IFERROR(X30/G30,0) -> 0
G31: =SUMIF(每月目标分解!E:E,F:F,每月目标分解!R:R)*年目标!$B$18 -> 0 | H31: =IFERROR(SUMIF(F:F,每月目标分解!E:E,每月目标分解!R:R)/SUMIF(F:F,单品目标年销量!E:E,单品目标年销量!F:F),0) -> 0 | I31: =IFERROR(SUMIF(D:D,D:D,H:H)*(SUMIF('船长每月数据(2023年)'!E:E,D:D,'船长每月数据(2023年)'!AI:AI)/SUMIF('船长每月数据(2023年)'!E:E,D:D,'船长每月数据(2023年)'!P:P)),0) -> 0 | J31: =SUMIF(D:D,D:D,G:G)*SUMIF('2022年全年财务报表'!A:A,C:C,'2022年全年财务报表'!E:E) -> 0 | K31: =SUMIF(D:D,D:D,G:G)*SUMIF('2022年全年财务报表'!A:A,C:C,'2022年全年财务报表'!G:G) -> 0 | L31: =SUMIF(D:D,D:D,G:G)*SUMIF('2022年全年财务报表'!A:A,C:C,'2022年全年财务报表'!I:I) -> 0 | M31: =SUMIF(D:D,D:D,G:G)*SUMIF('2022年全年财务报表'!A:A,C:C,'2022年全年财务报表'!O:O)/3 -> 0 | N31: =SUMIF(D:D,D:D,G:G)*SUMIF('2022年全年财务报表'!A:A,C:C,'2022年全年财务报表'!Q:Q) -> 0 | O31: =SUMIF(D:D,D:D,G:G)*SUMIF('2022年全年财务报表'!A:A,C:C,'2022年全年财务报表'!S:S) -> 0 | P31: =IFERROR(I31/W31*R31,0)/2 -> 0 | Q31: =IFERROR(P31/G31,0) -> 0 | R31: =IFERROR(SUMIF('2021&2022营销成本概况'!C:C,D:D,'2021&2022营销成本概况'!S:S)+SUMIF('2021&2022营销成本概况'!C:C,D:D,'2021&2022营销成本概况'!S:S)*'2021&2022营销成本概况'!$T$37,0)*年目标!$B$18 -> 0 | S31: =IFERROR(P31/I31,0) -> 0 | T31: =IFERROR(P31/H31,0) -> 0 | U31: =SUMIF(D:D,D:D,G:G)*SUMIF('2022年全年财务报表'!A:A,C:C,'2022年全年财务报表'!K:K) -> 0 | V31: =IFERROR(U31/G31,0) -> 0 | W31: =IFERROR(SUMIF('船长每月数据(2023年)'!E:E,D:D,'船长每月数据(2023年)'!P:P)/SUMIF('船长每月数据(2023年)'!E:E,D:D,'船长每月数据(2023年)'!H:H),0) -> 0 | X31: =IFERROR(G31+J31+K31+L31+M31+N31+O31+P31+U31,0) -> 0 | Y31: =IFERROR(X31/G31,0) -> 0
G32: =SUMIF(每月目标分解!E:E,F:F,每月目标分解!R:R)*年目标!$B$18 -> 0 | H32: =IFERROR(SUMIF(F:F,每月目标分解!E:E,每月目标分解!R:R)/SUMIF(F:F,单品目标年销量!E:E,单品目标年销量!F:F),0) -> 0 | I32: =IFERROR(SUMIF(D:D,D:D,H:H)*(SUMIF('船长每月数据(2023年)'!E:E,D:D,'船长每月数据(2023年)'!AI:AI)/SUMIF('船长每月数据(2023年)'!E:E,D:D,'船长每月数据(2023年)'!P:P)),0) -> 0 | J32: =SUMIF(D:D,D:D,G:G)*SUMIF('2022年全年财务报表'!A:A,C:C,'2022年全年财务报表'!E:E) -> 0 | K32: =SUMIF(D:D,D:D,G:G)*SUMIF('2022年全年财务报表'!A:A,C:C,'2022年全年财务报表'!G:G) -> 0 | L32: =SUMIF(D:D,D:D,G:G)*SUMIF('2022年全年财务报表'!A:A,C:C,'2022年全年财务报表'!I:I) -> 0 | M32: =SUMIF(D:D,D:D,G:G)*SUMIF('2022年全年财务报表'!A:A,C:C,'2022年全年财务报表'!O:O) -> 0 | N32: =SUMIF(D:D,D:D,G:G)*SUMIF('2022年全年财务报表'!A:A,C:C,'2022年全年财务报表'!Q:Q) -> 0 | O32: =SUMIF(D:D,D:D,G:G)*SUMIF('2022年全年财务报表'!A:A,C:C,'2022年全年财务报表'!S:S) -> 0 | P32: =IFERROR(I32/W32*R32,0)/3 -> 0 | Q32: =IFERROR(P32/G32,0) -> 0 | R32: =IFERROR(SUMIF('2021&2022营销成本概况'!C:C,D:D,'2021&2022营销成本概况'!S:S)+SUMIF('2021&2022营销成本概况'!C:C,D:D,'2021&2022营销成本概况'!S:S)*'2021&2022营销成本概况'!$T$37,0)*年目标!$B$18 -> 0 | S32: =IFERROR(P32/I32,0) -> 0 | T32: =IFERROR(P32/H32,0) -> 0 | U32: =SUMIF(D:D,D:D,G:G)*SUMIF('2022年全年财务报表'!A:A,C:C,'2022年全年财务报表'!K:K) -> 0 | V32: =IFERROR(U32/G32,0) -> 0 | W32: =IFERROR(SUMIF('船长每月数据(2023年)'!E:E,D:D,'船长每月数据(2023年)'!P:P)/SUMIF('船长每月数据(2023年)'!E:E,D:D,'船长每月数据(2023年)'!H:H),0) -> 0 | X32: =IFERROR(G32+J32+K32+L32+M32+N32+O32+P32+U32,0) -> 0 | Y32: =IFERROR(X32/G32,0) -> 0
G33: =SUMIF(每月目标分解!E:E,F:F,每月目标分解!R:R)*年目标!$B$18 -> 0 | H33: =IFERROR(SUMIF(F:F,每月目标分解!E:E,每月目标分解!R:R)/SUMIF(F:F,单品目标年销量!E:E,单品目标年销量!F:F),0) -> 0 | I33: =IFERROR(SUMIF(D:D,D:D,H:H)*(SUMIF('船长每月数据(2023年)'!E:E,D:D,'船长每月数据(2023年)'!AI:AI)/SUMIF('船长每月数据(2023年)'!E:E,D:D,'船长每月数据(2023年)'!P:P)),0) -> 0 | J33: =SUMIF(D:D,D:D,G:G)*SUMIF('2022年全年财务报表'!A:A,C:C,'2022年全年财务报表'!E:E) -> 0 | K33: =SUMIF(D:D,D:D,G:G)*SUMIF('2022年全年财务报表'!A:A,C:C,'2022年全年财务报表'!G:G) -> 0 | L33: =SUMIF(D:D,D:D,G:G)*SUMIF('2022年全年财务报表'!A:A,C:C,'2022年全年财务报表'!I:I) -> 0 | M33: =SUMIF(D:D,D:D,G:G)*SUMIF('2022年全年财务报表'!A:A,C:C,'2022年全年财务报表'!O:O) -> 0 | N33: =SUMIF(D:D,D:D,G:G)*SUMIF('2022年全年财务报表'!A:A,C:C,'2022年全年财务报表'!Q:Q) -> 0 | O33: =SUMIF(D:D,D:D,G:G)*SUMIF('2022年全年财务报表'!A:A,C:C,'2022年全年财务报表'!S:S) -> 0 | P33: =IFERROR(I33/W33*R33,0)/4 -> 0 | Q33: =IFERROR(P33/G33,0) -> 0 | R33: =IFERROR(SUMIF('2021&2022营销成本概况'!C:C,D:D,'2021&2022营销成本概况'!S:S)+SUMIF('2021&2022营销成本概况'!C:C,D:D,'2021&2022营销成本概况'!S:S)*'2021&2022营销成本概况'!$T$37,0)*年目标!$B$18 -> 0 | S33: =IFERROR(P33/I33,0) -> 0 | T33: =IFERROR(P33/H33,0) -> 0 | U33: =SUMIF(D:D,D:D,G:G)*SUMIF('2022年全年财务报表'!A:A,C:C,'2022年全年财务报表'!K:K) -> 0 | V33: =IFERROR(U33/G33,0) -> 0 | W33: =IFERROR(SUMIF('船长每月数据(2023年)'!E:E,D:D,'船长每月数据(2023年)'!P:P)/SUMIF('船长每月数据(2023年)'!E:E,D:D,'船长每月数据(2023年)'!H:H),0) -> 0 | X33: =IFERROR(G33+J33+K33+L33+M33+N33+O33+P33+U33,0) -> 0 | Y33: =IFERROR(X33/G33,0) -> 0
G34: =SUMIF(每月目标分解!E:E,F:F,每月目标分解!R:R)*年目标!$B$18 -> 0 | H34: =IFERROR(SUMIF(F:F,每月目标分解!E:E,每月目标分解!R:R)/SUMIF(F:F,单品目标年销量!E:E,单品目标年销量!F:F),0) -> 0 | I34: =IFERROR(SUMIF(D:D,D:D,H:H)*(SUMIF('船长每月数据(2023年)'!E:E,D:D,'船长每月数据(2023年)'!AI:AI)/SUMIF('船长每月数据(2023年)'!E:E,D:D,'船长每月数据(2023年)'!P:P)),0) -> 0 | J34: =SUMIF(D:D,D:D,G:G)*SUMIF('2022年全年财务报表'!A:A,C:C,'2022年全年财务报表'!E:E) -> 0 | K34: =SUMIF(D:D,D:D,G:G)*SUMIF('2022年全年财务报表'!A:A,C:C,'2022年全年财务报表'!G:G) -> 0 | L34: =SUMIF(D:D,D:D,G:G)*SUMIF('2022年全年财务报表'!A:A,C:C,'2022年全年财务报表'!I:I) -> 0 | M34: =SUMIF(D:D,D:D,G:G)*SUMIF('2022年全年财务报表'!A:A,C:C,'2022年全年财务报表'!O:O) -> 0 | N34: =SUMIF(D:D,D:D,G:G)*SUMIF('2022年全年财务报表'!A:A,C:C,'2022年全年财务报表'!Q:Q) -> 0 | O34: =SUMIF(D:D,D:D,G:G)*SUMIF('2022年全年财务报表'!A:A,C:C,'2022年全年财务报表'!S:S) -> 0 | P34: =IFERROR(I34/W34*R34,0)/3 -> 0 | Q34: =IFERROR(P34/G34,0) -> 0 | R34: =IFERROR(SUMIF('2021&2022营销成本概况'!C:C,D:D,'2021&2022营销成本概况'!S:S)+SUMIF('2021&2022营销成本概况'!C:C,D:D,'2021&2022营销成本概况'!S:S)*'2021&2022营销成本概况'!$T$37,0)*年目标!$B$18 -> 0 | S34: =IFERROR(P34/I34,0) -> 0 | T34: =IFERROR(P34/H34,0) -> 0 | U34: =SUMIF(D:D,D:D,G:G)*SUMIF('2022年全年财务报表'!A:A,C:C,'2022年全年财务报表'!K:K) -> 0 | V34: =IFERROR(U34/G34,0) -> 0 | W34: =IFERROR(SUMIF('船长每月数据(2023年)'!E:E,D:D,'船长每月数据(2023年)'!P:P)/SUMIF('船长每月数据(2023年)'!E:E,D:D,'船长每月数据(2023年)'!H:H),0) -> 0 | X34: =IFERROR(G34+J34+K34+L34+M34+N34+O34+P34+U34,0) -> 0 | Y34: =IFERROR(X34/G34,0) -> 0
G35: =SUMIF(每月目标分解!E:E,F:F,每月目标分解!R:R)*年目标!$B$18 -> 0 | H35: =IFERROR(SUMIF(F:F,每月目标分解!E:E,每月目标分解!R:R)/SUMIF(F:F,单品目标年销量!E:E,单品目标年销量!F:F),0) -> 0 | I35: =IFERROR(SUMIF(D:D,D:D,H:H)*(SUMIF('船长每月数据(2023年)'!E:E,D:D,'船长每月数据(2023年)'!AI:AI)/SUMIF('船长每月数据(2023年)'!E:E,D:D,'船长每月数据(2023年)'!P:P)),0) -> 0 | J35: =SUMIF(D:D,D:D,G:G)*SUMIF('2022年全年财务报表'!A:A,C:C,'2022年全年财务报表'!E:E)/1.2 -> 0 | K35: =SUMIF(D:D,D:D,G:G)*SUMIF('2022年全年财务报表'!A:A,C:C,'2022年全年财务报表'!G:G) -> 0 | L35: =SUMIF(D:D,D:D,G:G)*SUMIF('2022年全年财务报表'!A:A,C:C,'2022年全年财务报表'!I:I) -> 0 | M35: =SUMIF(D:D,D:D,G:G)*SUMIF('2022年全年财务报表'!A:A,C:C,'2022年全年财务报表'!O:O)/2 -> 0 | N35: =SUMIF(D:D,D:D,G:G)*SUMIF('2022年全年财务报表'!A:A,C:C,'2022年全年财务报表'!Q:Q) -> 0 | O35: =SUMIF(D:D,D:D,G:G)*SUMIF('2022年全年财务报表'!A:A,C:C,'2022年全年财务报表'!S:S) -> 0 | P35: =IFERROR(I35/W35*R35,0)/5 -> 0 | Q35: =IFERROR(P35/G35,0) -> 0 | R35: =IFERROR(SUMIF('2021&2022营销成本概况'!C:C,D:D,'2021&2022营销成本概况'!S:S)+SUMIF('2021&2022营销成本概况'!C:C,D:D,'2021&2022营销成本概况'!S:S)*'2021&2022营销成本概况'!$T$37,0)*年目标!$B$18 -> 0 | S35: =IFERROR(P35/I35,0) -> 0 | T35: =IFERROR(P35/H35,0) -> 0 | U35: =SUMIF(D:D,D:D,G:G)*SUMIF('2022年全年财务报表'!A:A,C:C,'2022年全年财务报表'!K:K)/5 -> 0 | V35: =IFERROR(U35/G35,0) -> 0 | W35: =IFERROR(SUMIF('船长每月数据(2023年)'!E:E,D:D,'船长每月数据(2023年)'!P:P)/SUMIF('船长每月数据(2023年)'!E:E,D:D,'船长每月数据(2023年)'!H:H),0) -> 0 | X35: =IFERROR(G35+J35+K35+L35+M35+N35+O35+P35+U35,0) -> 0 | Y35: =IFERROR(X35/G35,0) -> 0
G36: =SUMIF(每月目标分解!E:E,F:F,每月目标分解!R:R)*年目标!$B$18 -> 0 | H36: =IFERROR(SUMIF(F:F,每月目标分解!E:E,每月目标分解!R:R)/SUMIF(F:F,单品目标年销量!E:E,单品目标年销量!F:F),0) -> 0 | I36: =IFERROR(SUMIF(D:D,D:D,H:H)*(SUMIF('船长每月数据(2023年)'!E:E,D:D,'船长每月数据(2023年)'!AI:AI)/SUMIF('船长每月数据(2023年)'!E:E,D:D,'船长每月数据(2023年)'!P:P)),0) -> 0 | J36: =SUMIF(D:D,D:D,G:G)*SUMIF('2022年全年财务报表'!A:A,C:C,'2022年全年财务报表'!E:E) -> 0 | K36: =SUMIF(D:D,D:D,G:G)*SUMIF('2022年全年财务报表'!A:A,C:C,'2022年全年财务报表'!G:G) -> 0 | L36: =SUMIF(D:D,D:D,G:G)*SUMIF('2022年全年财务报表'!A:A,C:C,'2022年全年财务报表'!I:I) -> 0 | M36: =SUMIF(D:D,D:D,G:G)*SUMIF('2022年全年财务报表'!A:A,C:C,'2022年全年财务报表'!O:O)/2 -> 0 | N36: =SUMIF(D:D,D:D,G:G)*SUMIF('2022年全年财务报表'!A:A,C:C,'2022年全年财务报表'!Q:Q) -> 0 | O36: =SUMIF(D:D,D:D,G:G)*SUMIF('2022年全年财务报表'!A:A,C:C,'2022年全年财务报表'!S:S) -> 0 | P36: =IFERROR(I36/W36*R36,0)/8 -> 0 | Q36: =IFERROR(P36/G36,0) -> 0 | R36: =IFERROR(SUMIF('2021&2022营销成本概况'!C:C,D:D,'2021&2022营销成本概况'!S:S)+SUMIF('2021&2022营销成本概况'!C:C,D:D,'2021&2022营销成本概况'!S:S)*'2021&2022营销成本概况'!$T$37,0)*年目标!$B$18 -> 0 | S36: =IFERROR(P36/I36,0) -> 0 | T36: =IFERROR(P36/H36,0) -> 0 | U36: =SUMIF(D:D,D:D,G:G)*SUMIF('2022年全年财务报表'!A:A,C:C,'2022年全年财务报表'!K:K)/5 -> 0 | V36: =IFERROR(U36/G36,0) -> 0 | W36: =IFERROR(SUMIF('船长每月数据(2023年)'!E:E,D:D,'船长每月数据(2023年)'!P:P)/SUMIF('船长每月数据(2023年)'!E:E,D:D,'船长每月数据(2023年)'!H:H),0) -> 0 | X36: =IFERROR(G36+J36+K36+L36+M36+N36+O36+P36+U36,0) -> 0 | Y36: =IFERROR(X36/G36,0) -> 0
A37: 总计 | G37: =SUM(G3:G36) -> 0 | H37: =SUM(H3:H36) -> 0 | I37: =SUM(I3:I36) -> 0 | J37: =SUM(J3:J36) -> 0 | K37: =SUM(K3:K36) -> 0 | L37: =SUM(L3:L36) -> 0 | M37: =SUM(M3:M36) -> 0 | N37: =SUM(N3:N36) -> 0 | ... P37: =SUM(P3:P36) -> 0 | Q37: =IFERROR(P37/G37,0) -> 0 | R37: =IFERROR(SUMIF('2021&2022营销成本概况'!C:C,D:D,'2021&2022营销成本概况'!S:S)+SUMIF('2021&2022营销成本概况'!C:C,D:D,'2021&2022营销成本概况'!S:S)*'2021&2022营销成本概况'!$T$37,0) -> 0 | S37: =IFERROR(P37/I37,0) -> 0 | T37: =IFERROR(P37/H37,0) -> 0 | U37: =SUM(U3:U36) -> 0 | V37: =IFERROR(U37/G37,0) -> 0 | W37: =AVERAGE(W3:W36) -> #DIV/0! | X37: =SUM(X3:X36) -> 0 | Y37: =IFERROR(X37/G37,0) -> 0

Sheet 市场概况
A1: 本品牌市场概况(2021-2022)
A2: 年份 | B2: 品类 | C2: 市场容量 | D2: 市场容量同比 | E2: xxx销量 | F2: xxx市占率 | G2: 市占率同比 | H2: 市场份额 | I2: 市场份额同比 | J2: xxx销售额 | K2: xxx市场份额占比 | L2: 市场份额同比
A3: 2021年 | C3: =SUM(C9:C20) -> 0 | D3: / | E3: =SUM(C36:C47) -> 0 | F3: =IFERROR(E3/C3,0) -> 0 | G3: / | H3: =SUM(F8:F20) -> 0 | I3: / | J3: =SUM(G36:G47) -> 0 | K3: =IFERROR(J3/H3,0) -> 0 | L3: /
A4: 2022年 | C4: =SUM(C21:C32) -> 0 | D4: =IFERROR((C4-C3)/C3,0) -> 0 | E4: =SUM(C48:C59) -> 0 | F4: =IFERROR(E4/C4,0) -> 0 | G4: =IFERROR((F4-F3)/F3,0) -> 0 | H4: =SUM(F21:F32) -> 0 | I4: =IFERROR((H4-H3)/H3,0) -> 0 | J4: =SUM(G48:G59) -> 0 | K4: =IFERROR(J4/H4,0) -> 0 | L4: =IFERROR((K4-K3)/K3,0) -> 0
A6: 每月市场趋势变化(2021-2022)
A7: 年份 | B7: 月份 | C7: 市场容量 | D7: 环比 | E7: 同比 | F7: 市场份额 | G7: 环比 | H7: 同比 | I7: 平均客单价 | J7: 环比 | K7: 同比
A8: 2020 | B8: 12 | C8: =每月市场趋势!B26+每月市场趋势!G26+每月市场趋势!L26+每月市场趋势!Q26 -> 0 | D8: / | E8: / | F8: =每月市场趋势!C26+每月市场趋势!H26+每月市场趋势!M26+每月市场趋势!R26 -> 0 | G8: / | H8: / | I8: =IFERROR(F8/C8,0) -> 0 | J8: / | K8: /
A9: 2021 | B9: 1 | C9: =每月市场趋势!B27+每月市场趋势!G27+每月市场趋势!L27+每月市场趋势!Q27 -> 0 | D9: =IFERROR((C9-C8)/C8,0) -> 0 | E9: / | F9: =每月市场趋势!C27+每月市场趋势!H27+每月市场趋势!M27+每月市场趋势!R27 -> 0 | G9: =IFERROR((F9-F8)/F8,0) -> 0 | H9: / | I9: =IFERROR(F9/C9,0) -> 0 | J9: =IFERROR((I9-I8)/I8,0) -> 0 | K9: /
A10: 2021 | B10: 2 | C10: =每月市场趋势!B28+每月市场趋势!G28+每月市场趋势!L28+每月市场趋势!Q28 -> 0 | D10: =IFERROR((C10-C9)/C9,0) -> 0 | E10: / | F10: =每月市场趋势!C28+每月市场趋势!H28+每月市场趋势!M28+每月市场趋势!R28 -> 0 | G10: =IFERROR((F10-F9)/F9,0) -> 0 | H10: / | I10: =IFERROR(F10/C10,0) -> 0 | J10: =IFERROR((I10-I9)/I9,0) -> 0 | K10: /
A11: 2021 | B11: 3 | C11: =每月市场趋势!B29+每月市场趋势!G29+每月市场趋势!L29+每月市场趋势!Q29 -> 0 | D11: =IFERROR((C11-C10)/C10,0) -> 0 | E11: / | F11: =每月市场趋势!C29+每月市场趋势!H29+每月市场趋势!M29+每月市场趋势!R29 -> 0 | G11: =IFERROR((F11-F10)/F10,0) -> 0 | H11: / | I11: =IFERROR(F11/C11,0) -> 0 | J11: =IFERROR((I11-I10)/I10,0) -> 0 | K11: /
A12: 2021 | B12: 4 | C12: =每月市场趋势!B30+每月市场趋势!G30+每月市场趋势!L30+每月市场趋势!Q30 -> 0 | D12: =IFERROR((C12-C11)/C11,0) -> 0 | E12: / | F12: =每月市场趋势!C30+每月市场趋势!H30+每月市场趋势!M30+每月市场趋势!R30 -> 0 | G12: =IFERROR((F12-F11)/F11,0) -> 0 | H12: / | I12: =IFERROR(F12/C12,0) -> 0 | J12: =IFERROR((I12-I11)/I11,0) -> 0 | K12: /
A13: 2021 | B13: 5 | C13: =每月市场趋势!B31+每月市场趋势!G31+每月市场趋势!L31+每月市场趋势!Q31 -> 0 | D13: =IFERROR((C13-C12)/C12,0) -> 0 | E13: / | F13: =每月市场趋势!C31+每月市场趋势!H31+每月市场趋势!M31+每月市场趋势!R31 -> 0 | G13: =IFERROR((F13-F12)/F12,0) -> 0 | H13: / | I13: =IFERROR(F13/C13,0) -> 0 | J13: =IFERROR((I13-I12)/I12,0) -> 0 | K13: /
A14: 2021 | B14: 6 | C14: =每月市场趋势!B32+每月市场趋势!G32+每月市场趋势!L32+每月市场趋势!Q32 -> 0 | D14: =IFERROR((C14-C13)/C13,0) -> 0 | E14: / | F14: =每月市场趋势!C32+每月市场趋势!H32+每月市场趋势!M32+每月市场趋势!R32 -> 0 | G14: =IFERROR((F14-F13)/F13,0) -> 0 | H14: / | I14: =IFERROR(F14/C14,0) -> 0 | J14: =IFERROR((I14-I13)/I13,0) -> 0 | K14: /
A15: 2021 | B15: 7 | C15: =每月市场趋势!B33+每月市场趋势!G33+每月市场趋势!L33+每月市场趋势!Q33 -> 0 | D15: =IFERROR((C15-C14)/C14,0) -> 0 | E15: / | F15: =每月市场趋势!C33+每月市场趋势!H33+每月市场趋势!M33+每月市场趋势!R33 -> 0 | G15: =IFERROR((F15-F14)/F14,0) -> 0 | H15: / | I15: =IFERROR(F15/C15,0) -> 0 | J15: =IFERROR((I15-I14)/I14,0) -> 0 | K15: /
A16: 2021 | B16: 8 | C16: =每月市场趋势!B34+每月市场趋势!G34+每月市场趋势!L34+每月市场趋势!Q34 -> 0 | D16: =IFERROR((C16-C15)/C15,0) -> 0 | E16: / | F16: =每月市场趋势!C34+每月市场趋势!H34+每月市场趋势!M34+每月市场趋势!R34 -> 0 | G16: =IFERROR((F16-F15)/F15,0) -> 0 | H16: / | I16: =IFERROR(F16/C16,0) -> 0 | J16: =IFERROR((I16-I15)/I15,0) -> 0 | K16: /
A17: 2021 | B17: 9 | C17: =每月市场趋势!B35+每月市场趋势!G35+每月市场趋势!L35+每月市场趋势!Q35 -> 0 | D17: =IFERROR((C17-C16)/C16,0) -> 0 | E17: / | F17: =每月市场趋势!C35+每月市场趋势!H35+每月市场趋势!M35+每月市场趋势!R35 -> 0 | G17: =IFERROR((F17-F16)/F16,0) -> 0 | H17: / | I17: =IFERROR(F17/C17,0) -> 0 | J17: =IFERROR((I17-I16)/I16,0) -> 0 | K17: /
A18: 2021 | B18: 10 | C18: =每月市场趋势!B36+每月市场趋势!G36+每月市场趋势!L36+每月市场趋势!Q36 -> 0 | D18: =IFERROR((C18-C17)/C17,0) -> 0 | E18: / | F18: =每月市场趋势!C36+每月市场趋势!H36+每月市场趋势!M36+每月市场趋势!R36 -> 0 | G18: =IFERROR((F18-F17)/F17,0) -> 0 | H18: / | I18: =IFERROR(F18/C18,0) -> 0 | J18: =IFERROR((I18-I17)/I17,0) -> 0 | K18: /
A19: 2021 | B19: 11 | C19: =每月市场趋势!B37+每月市场趋势!G37+每月市场趋势!L37+每月市场趋势!Q37 -> 0 | D19: =IFERROR((C19-C18)/C18,0) -> 0 | E19: / | F19: =每月市场趋势!C37+每月市场趋势!H37+每月市场趋势!M37+每月市场趋势!R37 -> 0 | G19: =IFERROR((F19-F18)/F18,0) -> 0 | H19: / | I19: =IFERROR(F19/C19,0) -> 0 | J19: =IFERROR((I19-I18)/I18,0) -> 0 | K19: /
A20: 2021 | B20: 12 | C20: =每月市场趋势!B38+每月市场趋势!G38+每月市场趋势!L38+每月市场趋势!Q38 -> 0 | D20: =IFERROR((C20-C19)/C19,0) -> 0 | E20: / | F20: =每月市场趋势!C38+每月市场趋势!H38+每月市场趋势!M38+每月市场趋势!R38 -> 0 | G20: =IFERROR((F20-F19)/F19,0) -> 0 | H20: / | I20: =IFERROR(F20/C20,0) -> 0 | J20: =IFERROR((I20-I19)/I19,0) -> 0 | K20: /
A21: 2022 | B21: 1 | C21: =每月市场趋势!B39+每月市场趋势!G39+每月市场趋势!L39+每月市场趋势!Q39 -> 0 | D21: =IFERROR((C21-C20)/C20,0) -> 0 | E21: =IFERROR((C21-C9)/C9,0) -> 0 | F21: =每月市场趋势!C39+每月市场趋势!H39+每月市场趋势!M39+每月市场趋势!R39 -> 0 | G21: =IFERROR((F21-F20)/F20,0) -> 0 | H21: =IFERROR((F21-F9)/F9,0) -> 0 | I21: =IFERROR(F21/C21,0) -> 0 | J21: =IFERROR((I21-I20)/I20,0) -> 0 | K21: =IFERROR((I21-I8)/I8,0) -> 0
A22: 2022 | B22: 2 | C22: =每月市场趋势!B40+每月市场趋势!G40+每月市场趋势!L40+每月市场趋势!Q40 -> 0 | D22: =IFERROR((C22-C21)/C21,0) -> 0 | E22: =IFERROR((C22-C10)/C10,0) -> 0 | F22: =每月市场趋势!C40+每月市场趋势!H40+每月市场趋势!M40+每月市场趋势!R40 -> 0 | G22: =IFERROR((F22-F21)/F21,0) -> 0 | H22: =IFERROR((F22-F10)/F10,0) -> 0 | I22: =IFERROR(F22/C22,0) -> 0 | J22: =IFERROR((I22-I21)/I21,0) -> 0 | K22: =IFERROR((I22-I9)/I9,0) -> 0
A23: 2022 | B23: 3 | C23: =每月市场趋势!B41+每月市场趋势!G41+每月市场趋势!L41+每月市场趋势!Q41 -> 0 | D23: =IFERROR((C23-C22)/C22,0) -> 0 | E23: =IFERROR((C23-C11)/C11,0) -> 0 | F23: =每月市场趋势!C41+每月市场趋势!H41+每月市场趋势!M41+每月市场趋势!R41 -> 0 | G23: =IFERROR((F23-F22)/F22,0) -> 0 | H23: =IFERROR((F23-F11)/F11,0) -> 0 | I23: =IFERROR(F23/C23,0) -> 0 | J23: =IFERROR((I23-I22)/I22,0) -> 0 | K23: =IFERROR((I23-I10)/I10,0) -> 0
A24: 2022 | B24: 4 | C24: =每月市场趋势!B42+每月市场趋势!G42+每月市场趋势!L42+每月市场趋势!Q42 -> 0 | D24: =IFERROR((C24-C23)/C23,0) -> 0 | E24: =IFERROR((C24-C12)/C12,0) -> 0 | F24: =每月市场趋势!C42+每月市场趋势!H42+每月市场趋势!M42+每月市场趋势!R42 -> 0 | G24: =IFERROR((F24-F23)/F23,0) -> 0 | H24: =IFERROR((F24-F12)/F12,0) -> 0 | I24: =IFERROR(F24/C24,0) -> 0 | J24: =IFERROR((I24-I23)/I23,0) -> 0 | K24: =IFERROR((I24-I11)/I11,0) -> 0
A25: 2022 | B25: 5 | C25: =每月市场趋势!B43+每月市场趋势!G43+每月市场趋势!L43+每月市场趋势!Q43 -> 0 | D25: =IFERROR((C25-C24)/C24,0) -> 0 | E25: =IFERROR((C25-C13)/C13,0) -> 0 | F25: =每月市场趋势!C43+每月市场趋势!H43+每月市场趋势!M43+每月市场趋势!R43 -> 0 | G25: =IFERROR((F25-F24)/F24,0) -> 0 | H25: =IFERROR((F25-F13)/F13,0) -> 0 | I25: =IFERROR(F25/C25,0) -> 0 | J25: =IFERROR((I25-I24)/I24,0) -> 0 | K25: =IFERROR((I25-I12)/I12,0) -> 0
A26: 2022 | B26: 6 | C26: =每月市场趋势!B44+每月市场趋势!G44+每月市场趋势!L44+每月市场趋势!Q44 -> 0 | D26: =IFERROR((C26-C25)/C25,0) -> 0 | E26: =IFERROR((C26-C14)/C14,0) -> 0 | F26: =每月市场趋势!C44+每月市场趋势!H44+每月市场趋势!M44+每月市场趋势!R44 -> 0 | G26: =IFERROR((F26-F25)/F25,0) -> 0 | H26: =IFERROR((F26-F14)/F14,0) -> 0 | I26: =IFERROR(F26/C26,0) -> 0 | J26: =IFERROR((I26-I25)/I25,0) -> 0 | K26: =IFERROR((I26-I13)/I13,0) -> 0
A27: 2022 | B27: 7 | C27: =每月市场趋势!B45+每月市场趋势!G45+每月市场趋势!L45+每月市场趋势!Q45 -> 0 | D27: =IFERROR((C27-C26)/C26,0) -> 0 | E27: =IFERROR((C27-C15)/C15,0) -> 0 | F27: =每月市场趋势!C45+每月市场趋势!H45+每月市场趋势!M45+每月市场趋势!R45 -> 0 | G27: =IFERROR((F27-F26)/F26,0) -> 0 | H27: =IFERROR((F27-F15)/F15,0) -> 0 | I27: =IFERROR(F27/C27,0) -> 0 | J27: =IFERROR((I27-I26)/I26,0) -> 0 | K27: =IFERROR((I27-I14)/I14,0) -> 0
A28: 2022 | B28: 8 | C28: =每月市场趋势!B46+每月市场趋势!G46+每月市场趋势!L46+每月市场趋势!Q46 -> 0 | D28: =IFERROR((C28-C27)/C27,0) -> 0 | E28: =IFERROR((C28-C16)/C16,0) -> 0 | F28: =每月市场趋势!C46+每月市场趋势!H46+每月市场趋势!M46+每月市场趋势!R46 -> 0 | G28: =IFERROR((F28-F27)/F27,0) -> 0 | H28: =IFERROR((F28-F16)/F16,0) -> 0 | I28: =IFERROR(F28/C28,0) -> 0 | J28: =IFERROR((I28-I27)/I27,0) -> 0 | K28: =IFERROR((I28-I15)/I15,0) -> 0
A29: 2022 | B29: 9 | C29: =每月市场趋势!B47+每月市场趋势!G47+每月市场趋势!L47+每月市场趋势!Q47 -> 0 | D29: =IFERROR((C29-C28)/C28,0) -> 0 | E29: =IFERROR((C29-C17)/C17,0) -> 0 | F29: =每月市场趋势!C47+每月市场趋势!H47+每月市场趋势!M47+每月市场趋势!R47 -> 0 | G29: =IFERROR((F29-F28)/F28,0) -> 0 | H29: =IFERROR((F29-F17)/F17,0) -> 0 | I29: =IFERROR(F29/C29,0) -> 0 | J29: =IFERROR((I29-I28)/I28,0) -> 0 | K29: =IFERROR((I29-I16)/I16,0) -> 0
A30: 2022 | B30: 10 | C30: =每月市场趋势!B48+每月市场趋势!G48+每月市场趋势!L48+每月市场趋势!Q48 -> 0 | D30: =IFERROR((C30-C29)/C29,0) -> 0 | E30: =IFERROR((C30-C18)/C18,0) -> 0 | F30: =每月市场趋势!C48+每月市场趋势!H48+每月市场趋势!M48+每月市场趋势!R48 -> 0 | G30: =IFERROR((F30-F29)/F29,0) -> 0 | H30: =IFERROR((F30-F18)/F18,0) -> 0 | I30: =IFERROR(F30/C30,0) -> 0 | J30: =IFERROR((I30-I29)/I29,0) -> 0 | K30: =IFERROR((I30-I17)/I17,0) -> 0
A31: 2022 | B31: 11 | C31: =每月市场趋势!B49+每月市场趋势!G49+每月市场趋势!L49+每月市场趋势!Q49 -> 0 | D31: =IFERROR((C31-C30)/C30,0) -> 0 | E31: =IFERROR((C31-C19)/C19,0) -> 0 | F31: =每月市场趋势!C49+每月市场趋势!H49+每月市场趋势!M49+每月市场趋势!R49 -> 0 | G31: =IFERROR((F31-F30)/F30,0) -> 0 | H31: =IFERROR((F31-F19)/F19,0) -> 0 | I31: =IFERROR(F31/C31,0) -> 0 | J31: =IFERROR((I31-I30)/I30,0) -> 0 | K31: =IFERROR((I31-I18)/I18,0) -> 0
A32: 2022 | B32: 12 | C32: =每月市场趋势!B50+每月市场趋势!G50+每月市场趋势!L50+每月市场趋势!Q50 -> 0 | D32: =IFERROR((C32-C31)/C31,0) -> 0 | E32: =IFERROR((C32-C20)/C20,0) -> 0 | F32: =每月市场趋势!C50+每月市场趋势!H50+每月市场趋势!M50+每月市场趋势!R50 -> 0 | G32: =IFERROR((F32-F31)/F31,0) -> 0 | H32: =IFERROR((F32-F20)/F20,0) -> 0 | I32: =IFERROR(F32/C32,0) -> 0 | J32: =IFERROR((I32-I31)/I31,0) -> 0 | K32: =IFERROR((I32-I19)/I19,0) -> 0
A34: xxx每月市占率趋势(2022年)
A35: 年份 | B35: 月份 | C35: 销量 | D35: 市占率 | E35: 市占率环比 | F35: 市占率同比 | G35: 销售额 | H35: 市场份额占比 | I35: 市场份额环比 | J35: 市场份额同比
A36: 2021 | B36: 44197 | C36: =SUMIFS('船长每月数据(2022年)'!P:P,'船长每月数据(2022年)'!C:C,"BBQ",'船长每月数据(2022年)'!F:F,B36) -> 0 | D36: =IFERROR(C36/C9,0) -> 0 | E36: / | F36: / | G36: =SUMIFS('船长每月数据(2022年)'!R:R,'船长每月数据(2022年)'!C:C,"BBQ",'船长每月数据(2022年)'!F:F,B36) -> 0 | H36: =IFERROR(G36/F8,0) -> 0 | I36: / | J36: /
A37: 2021 | B37: 44228 | C37: =SUMIFS('船长每月数据(2022年)'!P:P,'船长每月数据(2022年)'!C:C,"BBQ",'船长每月数据(2022年)'!F:F,B37) -> 0 | D37: =IFERROR(C37/C10,0) -> 0 | E37: =IFERROR((D37-D36)/D36,0) -> 0 | F37: / | G37: =SUMIFS('船长每月数据(2022年)'!R:R,'船长每月数据(2022年)'!C:C,"BBQ",'船长每月数据(2022年)'!F:F,B37) -> 0 | H37: =IFERROR(G37/F9,0) -> 0 | I37: =IFERROR((H37-H36)/H36,0) -> 0 | J37: /
